File: P2_Plasticity/A_comp.csv
True Plastic Strain (-)	 True Stress (MPa)
0.0	249.0625
0.002	254.83051398648300
0.004	260.4132074473030
0.006	265.81653454576800
0.008	271.0462581438670
0.01	276.1079559485920
0.012	281.0070264607830
0.014	285.74869473284400
0.016	290.3380179414650
0.018000000000000000	294.7798907813010
0.02	299.07905068536300
0.022	303.24008287766800
0.024	307.26742526357200
0.026000000000000000	311.1653731629630
0.028	314.9380838913940
0.03	318.58958119402600
0.032	322.12375953710500
0.034	325.5443882615700
0.036000000000000000	328.8551156032020
0.038	332.05947258361100
0.04	335.1608767762140
0.042	338.1626359512050
0.044	341.0679516034300
0.046	343.87992236690300
0.048	346.60154731962500
0.05	349.23572918221700
0.052000000000000000	351.78527741378500
0.054	354.2529112083250
0.056	356.6412623948440
0.058	358.9528782443150
0.06	361.190224186439
0.062	363.3556864391240
0.064	365.45157455348100
0.066	367.4801238770540
0.068	369.4434979379000
0.07	371.3437907520840
0.07200000000000000	373.1830290570280
0.074	374.96317447310400
0.076	376.6861255957830
0.078	378.3537200205600
0.08	379.9677363028220
0.082	381.5298958547510
0.084	383.04186478127400
0.08600000000000000	384.50525565703200
0.088	385.92162924625400
0.09	387.29249616737500
0.092	388.6193185041660
0.094	389.9035113651120
0.096	391.14644439267400
0.098	392.3494432240680
0.1	393.51379090511400
0.10200000000000000	394.6407292586490
0.10400000000000000	395.7314602089850
0.106	396.7871470638060
0.108	397.8089157548830
0.11	398.7978560389250
0.112	399.7550226598450
0.114	400.68143647368900
0.116	401.5780855374190
0.11800000000000000	402.44592616271400
0.12	403.2858839359130
0.122	404.0988547051920
0.124	404.88570553602000
0.126	405.64727563591900
0.128	406.38437724951200
0.13	407.0977965248130
0.132	407.78829435168800
0.134	408.4566071733690
0.136	409.10344777190500
0.138	409.7295060283700
0.14	410.3354496586470
0.14200000000000000	410.921924925576
0.14400000000000000	411.48955732821800
0.146	412.0389522689730
0.148	412.57069569926700
0.15	413.08535474449400
0.152	413.58347830887500
0.154	414.06559766088400
0.156	414.53222699987500
0.158	414.98386400448500
0.16	415.4209903634390
0.162	415.8440722892810
0.164	416.2535610156120
0.166	416.649893278351
0.168	417.0334917815250
0.17	417.4047656481060
0.17200000000000000	417.7641108563510
0.17400000000000000	418.11191066213200
0.176	418.4485360076960
0.178	418.7743459172810
0.18	419.08968788003800
0.182	419.39489822064000
0.184	419.69030245798200
0.186	419.9762156523620
0.188	420.25294274150700
0.19	420.5207788657990
0.192	420.7800096830550
0.194	421.0309116731900
0.196	421.27375243309700
0.198	421.50879096204900
0.2	421.73627793792900
0.202	421.95645598459200
0.20400000000000000	422.1695599306300
0.20600000000000000	422.37581705982700
0.20800000000000000	422.57544735356700
0.21	422.76866372545100
0.212	422.95567224837800
0.214	423.1366723743340
0.216	423.3118571471080
0.218	423.4814134081870
0.22	423.6455219960280
0.222	423.80435793892800
0.224	423.9580906417
0.226	424.1068840663510
0.228	424.25089690695000
0.23	424.39028275888700
0.232	424.52519028268300
0.234	424.6557633625460
0.23600000000000000	424.78214125983
0.23800000000000000	424.90445876155800
0.24	425.0228463241820
0.242	425.1374302127180
0.244	425.24833263541400
0.246	425.35567187408900
0.248	425.45956241028400
0.25	425.560115047365
0.252	425.6574370286940
0.254	425.75163215201300
0.256	425.8428008801450
0.258	425.9310404481420
0.26	426.01644496699400
0.262	426.0991055239960
0.264	426.1791102799010
0.266	426.25654456294400
0.268	426.3314909598490
0.27	426.4040294039120
0.272	426.47423726025200
0.274	426.54218940832300
0.276	426.607958321779
0.278	426.67161414576500
0.28	426.7332247717350
0.28200000000000000	426.79285590985700
0.28400000000000000	426.8505711590990
0.28600000000000000	426.9064320750540
0.28800000000000000	426.9604982355990
0.29	427.01282730443200
0.292	427.0634750925730
0.294	427.1124956178920
0.296	427.1599411627160
0.298	427.20586232959500
0.3	427.2503080952690
0.302	427.293325862905
0.304	427.3349615126530
0.306	427.37525945057800
0.308	427.4142626560270
0.31	427.45201272745800
0.312	427.488549926816
0.314	427.5239132224690
0.316	427.5581403307690
0.318	427.5912677562820
0.32	427.62333083071500
0.322	427.6543637506070
0.324	427.6843996137920
0.326	427.7134704547060
0.328	427.7416072785510
0.33	427.7688400943620
0.332	427.7951979470130
0.334	427.8207089481970
0.336	427.8454003064050
0.338	427.86929835594600
0.34	427.89242858503600
0.342	427.91481566297900
0.34400000000000000	427.93648346647700
0.34600000000000000	427.9574551051010
0.34800000000000000	427.97775294593200
0.35000000000000000	427.99739863742000
0.352	428.0164131324710
0.354	428.03481671079700
0.356	428.0526290005410
0.358	428.06986899921400
0.36	428.0865550939580
0.362	428.1027050811510
0.364	428.1183361853930
0.366	428.13346507787500
0.368	428.14810789416000
0.37	428.1622802513900
0.372	428.17599726494300
0.374	428.18927356455800
0.376	428.20212330993200
0.378	428.2145602058280
0.38	428.22659751668700
0.382	428.2382480807760
0.384	428.24952432388200
0.386	428.26043827256500
0.388	428.27100156698400
0.39	428.28122547330700
0.392	428.2911208957370
0.394	428.30069838813300
0.396	428.3099681652680
0.398	428.31894011372600
0.4	428.3276238024460
0.402	428.3360284929250
0.404	428.34416314909700
0.406	428.3520364468940
0.40800000000000000	428.3596567835010
0.41000000000000000	428.3670322863080
0.41200000000000000	428.3741708215790
0.41400000000000000	428.3810800028450
0.41600000000000000	428.3877671990210
0.418	428.3942395422670
0.42	428.40050393559100
0.422	428.40656706021700
0.424	428.4124353827080
0.426	428.41811516186100
0.428	428.42361245538600
0.43	428.4289331263630
0.432	428.43408284949800
0.434	428.43906711717500
0.436	428.4438912453110
0.438	428.4485603790320
0.44	428.453079498151
0.442	428.4574534224890
0.444	428.4616868170090
0.446	428.46578419679200
0.448	428.4697499318580
0.45	428.47358825181900
0.452	428.47730325039500
0.454	428.4808988897790
0.456	428.48437900486300
0.458	428.4877473073260
0.46	428.49100738959800
0.462	428.49416272868300
0.464	428.49721668987700
0.466	428.50017253034900
0.468	428.5030334026200
0.47000000000000000	428.50580235792400
0.47200000000000000	428.5084823494610
0.47400000000000000	428.51107623554800
0.47600000000000000	428.5135867826670
0.47800000000000000	428.5160166684160
0.48	428.51836848436300
0.482	428.5206447388150
0.484	428.5228478594850
0.486	428.52498019609000
0.488	428.5270440228500
0.49	428.529041540919
0.492	428.53097488072800
0.494	428.5328461042620
0.496	428.5346572072520
0.498	428.5364101213140
0.5	428.5381067159980
0.502	428.5397488007910
0.504	428.5413381270400
0.506	428.5428763898240
0.508	428.5443652297630
0.51	428.5458062347620
0.512	428.54720094171000
0.514	428.54855083811800
0.516	428.54985736370300
0.518	428.55112191192700
0.52	428.55234583148000
0.522	428.5535304277200
0.524	428.55467696406700
0.526	428.5557866633470
0.528	428.55686070909800
0.53	428.5579002468320
0.532	428.5589063852580
0.534	428.5598801974610
0.536	428.56082272205100
0.538	428.5617349642690
0.54	428.5626178970550
0.542	428.56347246209300
0.544	428.5642995708100
0.546	428.5651001053510
0.548	428.56587491951700
0.55	428.5666248396780
0.552	428.5673506656530
0.554	428.5680531715650
0.556	428.5687331066650
0.558	428.5693911961290
0.56	428.5700281418360
0.562	428.57064462311400
0.5640000000000000	428.5712412974640
0.5660000000000000	428.57181880126400
0.5680000000000000	428.57237775044400
0.5700000000000000	428.57291874114500
0.5720000000000000	428.5734423503560
0.5740000000000000	428.5739491365260
0.5760000000000000	428.5744396401620
0.578	428.5749143844070
0.58	428.5753738755940
0.582	428.57581860378800
0.584	428.57624904331000
0.586	428.5766656532400
0.588	428.57706887790900
0.59	428.5774591473720
0.592	428.57783687786800
0.594	428.57820247226000
0.596	428.57855632047000
0.598	428.57889879989
0.6	428.5792302757890
0.602	428.57955110169800
0.604	428.57986161979200
0.606	428.58016216124900
0.608	428.58045304661000
0.61	428.5807345861140
0.612	428.58100708003600
0.614	428.58127081900100
0.616	428.58152608429600
0.618	428.58177314817200
0.62	428.5820122741320
0.622	428.5822437172150
0.624	428.5824677242620
0.626	428.58268453418700
0.628	428.582894378226
0.63	428.5830974801850
0.632	428.5832940566820
0.634	428.5834843173720
0.636	428.58366846517600
0.638	428.58384669649500
0.64	428.58401920142000
0.642	428.5841861639340
0.644	428.5843477621100
0.646	428.58450416829700
0.648	428.58465554931000
0.65	428.5848020666030
0.652	428.5849438764410
0.654	428.58508113007100
0.656	428.5852139738780
0.658	428.58534254954700
0.66	428.5854669942090
0.662	428.58558744058700
0.664	428.58570401714400
0.666	428.5858168482130
0.668	428.5859260541320
0.67	428.5860317513740
0.672	428.5861340526690
0.674	428.58623306712600
0.676	428.5863289003470
0.678	428.58642165454300
0.68	428.5865114286390
0.682	428.5865983183830
0.684	428.58668241644600
0.686	428.5867638125230
0.6880000000000000	428.58684259342500
0.6900000000000000	428.586918843175
0.6920000000000000	428.5869926430970
0.6940000000000000	428.5870640719010
0.6960000000000000	428.58713320577000
0.6980000000000000	428.5872001184360
0.7000000000000000	428.5872648812650
0.7020000000000000	428.5873275633290
0.704	428.58738823148100
0.706	428.5874469504260
0.708	428.58750378278900
0.71	428.58755878918600
0.712	428.5876120282820
0.714	428.58766355686000
0.716	428.5877134298750
0.718	428.5877617005210
0.72	428.5878084202780
0.722	428.5878536389770
0.724	428.5878974048440
0.726	428.58793976455800
0.728	428.58798076329600
0.73	428.58802044478600
0.732	428.5880588513490
0.734	428.5880960239470
0.736	428.58813200222700
0.738	428.5881668245610
0.74	428.5882005280890
0.742	428.5882331487550
0.744	428.5882647213520
0.746	428.5882952795530
0.748	428.5883248559500
0.75	428.58835348208700
0.752	428.58838118849400
0.754	428.5884080047220
0.756	428.58843395937200
0.758	428.5884590801250
0.76	428.58848339377300
0.762	428.5885069262470
0.764	428.5885297026470
0.766	428.5885517472640
0.768	428.5885730836100
0.77	428.58859373443900
0.772	428.58861372177900
0.774	428.5886330669450
0.776	428.5886517905700
0.778	428.58866991262400
0.78	428.5886874524350
0.782	428.58870442870800
0.784	428.5887208595520
0.786	428.5887367624880
0.788	428.58875215447900
0.79	428.5887670519410
0.792	428.5887814707620
0.794	428.5887954263210
0.796	428.5888089335020
0.798	428.58882200671100
0.8	428.58883465989000
0.802	428.58884690653600
0.804	428.5888587597080
0.806	428.5888702320510
0.808	428.5888813357980
0.81	428.58889208279300
0.812	428.58890248449800
0.8140000000000000	428.5889125520070
0.8160000000000000	428.58892229605600
0.8180000000000000	428.58893172703900
0.8200000000000000	428.5889408550140
0.8220000000000000	428.5889496897160
0.8240000000000000	428.58895824056800
0.8260000000000000	428.5889665166900
0.8280000000000000	428.5889745269080
0.8300000000000000	428.5889822797660
0.8320000000000000	428.5889897835330
0.834	428.5889970462100
0.836	428.5890040755460
0.838	428.5890108790350
0.84	428.58901746393600
0.842	428.5890238372700
0.844	428.5890300058350
0.846	428.5890359762100
0.848	428.58904175476400
0.85	428.5890473476580
0.852	428.58905276085800
0.854	428.58905800013700
0.856	428.5890630710830
0.858	428.5890679791050
0.86	428.5890727294380
0.862	428.58907732714600
0.864	428.5890817771350
0.866	428.5890860841510
0.868	428.58909025278600
0.87	428.5890942874870
0.872	428.5890981925570
0.874	428.5891019721610
0.876	428.5891056303300
0.878	428.58910917096600
0.88	428.5891125978450
0.882	428.58911591462200
0.884	428.5891191248340
0.886	428.58912223190500
0.888	428.58912523914900
0.89	428.5891281497730
0.892	428.5891309668820
0.894	428.5891336934790
0.896	428.5891363324750
0.898	428.5891388866810
0.9	428.5891413588240
0.902	428.5891437515390
0.904	428.5891460673790
0.906	428.5891483088130
0.908	428.5891504782320
0.91	428.5891525779490
0.912	428.589154610205
0.914	428.58915657716700
0.916	428.58915848093200
0.918	428.58916032353000
0.92	428.58916210692900
0.922	428.5891638330280
0.924	428.5891655036690
0.926	428.58916712063500
0.928	428.58916868564900
0.93	428.58917020038000
0.932	428.5891716664450
0.934	428.5891730854060
0.936	428.5891744587780
0.9380000000000000	428.5891757880250
0.9400000000000000	428.5891770745640
0.9420000000000000	428.5891783197680
0.9440000000000000	428.5891795249650
0.9460000000000000	428.5891806914400
0.9480000000000000	428.58918182043800
0.9500000000000000	428.5891829131620
0.9520000000000000	428.5891839707780
0.9540000000000000	428.58918499441300
0.9560000000000000	428.5891859851610
0.9580000000000000	428.589186944076
0.96	428.58918787218300
0.962	428.58918877047000
0.964	428.5891896398960
0.966	428.5891904813890
0.968	428.589191295845
0.97	428.5891920841340
0.972	428.5891928470950
0.974	428.5891935855440
0.976	428.5891943002670
0.978	428.58919499202600
0.98	428.5891956615600
0.982	428.58919630958200
0.984	428.5891969367850
0.986	428.5891975438350
0.988	428.58919813138200
0.99	428.58919870005200
0.992	428.58919925045100
0.994	428.58919978316600
0.996	428.5892002987650
0.998	428.5892007977990
1.0	428.5892012807990
1.002	428.589201748281
1.004	428.5892022007430
1.006	428.5892026386680
1.008	428.5892030625230
1.01	428.58920347276000
1.012	428.5892038698170
1.014	428.5892042541160
1.016	428.5892046260680
1.018	428.5892049860700
1.02	428.58920533450500
1.022	428.58920567174600
1.024	428.5892059981510
1.026	428.5892063140690
1.028	428.5892066198370
1.03	428.58920691578100
1.032	428.5892072022170
1.034	428.58920747945000
1.036	428.58920774777500
1.038	428.58920800748000
1.04	428.58920825884
1.042	428.5892085021250
1.044	428.58920873759200
1.046	428.5892089654950
1.048	428.58920918607500
1.05	428.58920939956900
1.052	428.58920960620300
1.054	428.5892098061980
1.056	428.58920999976700
1.058	428.5892101871180
1.06	428.58921036844800
1.062	428.5892105439530
1.064	428.5892107138190
1.066	428.58921087822800
1.068	428.58921103735400
1.07	428.58921119136700
1.072	428.58921134043300
1.074	428.5892114847090
1.076	428.5892116243490
1.078	428.5892117595030
1.08	428.58921189031500
1.082	428.58921201692400
1.084	428.58921213946500
1.086	428.58921225806900
1.088	428.5892123728620
1.09	428.589212483967
1.092	428.58921259150200
1.094	428.5892126955830
1.096	428.5892127963190
1.098	428.58921289381900
1.1	428.5892129881860
1.102	428.5892130795210
1.104	428.58921316792200
1.106	428.5892132534830
1.108	428.5892133362940
1.11	428.5892134164450
1.112	428.5892134940210
1.114	428.58921356910400
1.116	428.58921364177500
1.118	428.58921371211200
1.12	428.58921378018800
1.122	428.589213846077
1.124	428.58921390984900
1.1260000000000000	428.58921397157200
1.1280000000000000	428.5892140313120
1.1300000000000000	428.58921408913300
1.1320000000000000	428.5892141450960
1.1340000000000000	428.589214199261
1.1360000000000000	428.5892142516860
1.1380000000000000	428.58921430242600
1.1400000000000000	428.58921435153600
1.1420000000000000	428.58921439906800
1.1440000000000000	428.5892144450730
1.1460000000000000	428.5892144896000
1.1480000000000000	428.58921453269700
1.1500000000000000	428.5892145744090
1.1520000000000000	428.5892146147800
1.154	428.5892146538550
1.156	428.5892146916740
1.158	428.5892147282780
1.16	428.58921476370500
1.162	428.5892147979950
1.164	428.5892148311830
1.166	428.58921486330500
1.168	428.58921489439400
1.17	428.5892149244850
1.172	428.58921495360900
1.174	428.5892149817970
1.176	428.58921500908000
1.178	428.58921503548600
1.18	428.5892150610440
1.182	428.58921508578
1.184	428.58921510972200
1.186	428.5892151328940
1.188	428.5892151553220
1.19	428.5892151770300
1.192	428.5892151980400
1.194	428.5892152183740
1.196	428.589215238056
1.198	428.58921525710500
1.2	428.5892152755420
1.202	428.58921529338700
1.204	428.5892153106590
1.206	428.58921532737500
1.208	428.5892153435550
1.21	428.58921535921500
1.212	428.58921537437100
1.214	428.58921538904100
1.216	428.5892154032390
1.218	428.589215416981
1.22	428.58921543028200
1.222	428.5892154431550
1.224	428.5892154556140
1.226	428.5892154676740
1.228	428.5892154793460
1.23	428.5892154906420
1.232	428.5892155015760
1.234	428.58921551215900
1.236	428.58921552240100
1.238	428.58921553231500
1.24	428.58921554191
1.242	428.5892155511970
1.244	428.58921556018500
1.246	428.5892155688850
1.248	428.5892155773050
1.25	428.5892155854540
1.252	428.5892155933420
1.254	428.5892156009760
1.256	428.58921560836500
1.258	428.58921561551700
1.26	428.5892156224390
1.262	428.58921562913800
1.264	428.58921563562200
1.266	428.5892156418980
1.268	428.5892156479720
1.27	428.5892156538510
1.272	428.58921565954100
1.274	428.58921566504900
1.276	428.58921567037900
1.278	428.5892156755380
1.28	428.58921568053200
1.282	428.5892156853650
1.284	428.5892156900420
1.286	428.5892156945700
1.288	428.5892156989510
1.29	428.5892157031930
1.292	428.5892157072970
1.294	428.5892157112700
1.296	428.58921571511600
1.298	428.5892157188380
1.3	428.5892157224400
1.302	428.5892157259260
1.304	428.5892157293010
1.306	428.5892157325670
1.308	428.5892157357280
1.31	428.58921573878700
1.312	428.5892157417490
1.314	428.58921574461500
1.316	428.58921574738900
1.318	428.58921575007400
1.32	428.5892157526720
1.322	428.58921575518700
1.324	428.5892157576220
1.326	428.5892157599780
1.328	428.58921576225800
1.33	428.58921576446500
1.332	428.58921576660200
1.334	428.5892157686690
1.336	428.5892157706700
1.338	428.5892157726070
1.34	428.58921577448200
1.342	428.58921577629600
1.344	428.5892157780520
1.346	428.58921577975200
1.348	428.5892157813970
1.35	428.5892157829890
1.352	428.58921578453000
1.354	428.589215786022
1.356	428.58921578746600
1.358	428.58921578886300
1.36	428.5892157902150
1.362	428.5892157915240
1.364	428.58921579279100
1.366	428.5892157940170
1.368	428.589215795204
1.37	428.5892157963530
1.372	428.58921579746400
1.374	428.5892157985400
1.3760000000000000	428.5892157995820
1.3780000000000000	428.5892158005900
1.3800000000000000	428.58921580156500
1.3820000000000000	428.58921580251000
1.3840000000000000	428.5892158034240
1.3860000000000000	428.589215804308
1.3880000000000000	428.58921580516400
1.3900000000000000	428.5892158059930
1.3920000000000000	428.58921580679500
1.3940000000000000	428.589215807571
1.3960000000000000	428.5892158083220
1.3980000000000000	428.58921580904900
1.4000000000000000	428.5892158097530
1.4020000000000000	428.58921581043400
1.4040000000000000	428.5892158110940
1.4060000000000000	428.58921581173200
1.408	428.5892158123490
1.41	428.58921581294700
1.412	428.58921581352600
1.414	428.5892158140860
1.416	428.5892158146280
1.418	428.5892158151520
1.42	428.58921581566000
1.422	428.5892158161510
1.424	428.58921581662700
1.426	428.58921581708700
1.428	428.5892158175330
1.43	428.5892158179640
1.432	428.5892158183820
1.434	428.5892158187850
1.436	428.5892158191760
1.438	428.58921581955500
1.44	428.5892158199210
1.442	428.5892158202760
1.444	428.5892158206190
1.446	428.58921582095100
1.448	428.5892158212720
1.45	428.58921582158300
1.452	428.58921582188400
1.454	428.5892158221760
1.456	428.58921582245800
1.458	428.5892158227310
1.46	428.589215822995
1.462	428.5892158232510
1.464	428.5892158234980
1.466	428.58921582373800
1.468	428.58921582397000
1.47	428.5892158241940
1.472	428.5892158244110
1.474	428.58921582462200
1.476	428.58921582482500
1.478	428.58921582502200
1.48	428.5892158252130
1.482	428.58921582539700
1.484	428.5892158255760
1.486	428.58921582574800
1.488	428.58921582591600
1.49	428.58921582607800
1.492	428.5892158262340
1.494	428.58921582638600
1.496	428.5892158265330
1.498	428.58921582667500
1.5	428.5892158268120
1.502	428.5892158269450
1.504	428.5892158270740
1.506	428.5892158271990
1.508	428.58921582732000
1.51	428.58921582743600
1.512	428.58921582754900
1.514	428.5892158276590
1.516	428.5892158277650
1.518	428.5892158278670
1.52	428.58921582796600
1.522	428.5892158280620
1.524	428.58921582815500
1.526	428.5892158282450
1.528	428.58921582833200
1.53	428.5892158284170
1.532	428.5892158284980
1.534	428.58921582857700
1.536	428.5892158286530
1.538	428.58921582872700
1.54	428.58921582879900
1.542	428.58921582886800
1.544	428.58921582893500
1.546	428.58921582900000
1.548	428.5892158290630
1.55	428.58921582912400
1.552	428.5892158291830
1.554	428.5892158292390
1.556	428.5892158292950
1.558	428.58921582934800
1.56	428.58921582939900
1.562	428.5892158294490
1.564	428.5892158294980
1.566	428.58921582954500
1.568	428.5892158295900
1.57	428.58921582963400
1.572	428.58921582967600
1.574	428.5892158297170
1.576	428.589215829757
1.578	428.5892158297960
1.58	428.5892158298330
1.582	428.58921582986900
1.584	428.58921582990400
1.586	428.5892158299370
1.588	428.5892158299700
1.59	428.58921583000200
1.592	428.58921583003200
1.594	428.58921583006200
1.596	428.58921583009100
1.598	428.5892158301180
1.6	428.58921583014500
1.602	428.58921583017100
1.604	428.58921583019600
1.606	428.58921583022100
1.608	428.58921583024400
1.61	428.5892158302670
1.612	428.5892158302890
1.614	428.58921583031100
1.616	428.58921583033100
1.618	428.58921583035100
1.62	428.58921583037100
1.622	428.5892158303900
1.624	428.5892158304080
1.6260000000000000	428.58921583042500
1.6280000000000000	428.58921583044200
1.6300000000000000	428.58921583045900
1.6320000000000000	428.5892158304750
1.6340000000000000	428.58921583049000
1.6360000000000000	428.58921583050500
1.6380000000000000	428.5892158305190
1.6400000000000000	428.58921583053300
1.6420000000000000	428.5892158305470
1.6440000000000000	428.58921583056
1.6460000000000000	428.5892158305730
1.6480000000000000	428.589215830585
1.6500000000000000	428.5892158305970
1.6520000000000000	428.58921583060800
1.6540000000000000	428.5892158306190
1.6560000000000000	428.5892158306300
1.6580000000000000	428.5892158306410
1.6600000000000000	428.58921583065100
1.6620000000000000	428.58921583066000
1.6640000000000000	428.58921583067000
1.666	428.5892158306790
1.668	428.589215830688
1.67	428.5892158306970
1.672	428.5892158307050
1.674	428.5892158307130
1.676	428.5892158307210
1.678	428.5892158307280
1.68	428.5892158307350
1.682	428.58921583074200
1.684	428.58921583074900
1.686	428.58921583075600
1.688	428.5892158307620
1.69	428.5892158307680
1.692	428.5892158307740
1.694	428.5892158307800
1.696	428.58921583078600
1.698	428.5892158307910
1.7	428.58921583079600
1.702	428.58921583080200
1.704	428.58921583080600
1.706	428.5892158308110
1.708	428.5892158308160
1.71	428.5892158308200
1.712	428.58921583082500
1.714	428.5892158308290
1.716	428.5892158308330
1.718	428.5892158308370
1.72	428.58921583084100
1.722	428.5892158308440
1.724	428.5892158308480
1.726	428.5892158308510
1.728	428.58921583085400
1.73	428.5892158308580
1.732	428.5892158308610
1.734	428.58921583086400
1.736	428.5892158308670
1.738	428.58921583087000
1.74	428.58921583087200
1.742	428.58921583087500
1.744	428.5892158308780
1.746	428.58921583088
1.748	428.5892158308820
1.75	428.58921583088500
1.752	428.5892158308870
1.754	428.5892158308890
1.756	428.58921583089100
1.758	428.58921583089300
1.76	428.5892158308950
1.762	428.5892158308970
1.764	428.589215830899
1.766	428.5892158309010
1.768	428.5892158309030
1.77	428.58921583090400
1.772	428.5892158309060
1.774	428.58921583090700
1.776	428.58921583090900
1.778	428.58921583091000
1.78	428.5892158309120
1.782	428.5892158309130
1.784	428.58921583091400
1.786	428.58921583091600
1.788	428.589215830917
1.79	428.5892158309180
1.792	428.5892158309190
1.794	428.5892158309210
1.796	428.5892158309220
1.798	428.5892158309230
1.8	428.58921583092400
1.802	428.5892158309250
1.804	428.58921583092600
1.806	428.5892158309270
1.808	428.58921583092700
1.81	428.5892158309280
1.812	428.5892158309290
1.814	428.58921583093
1.816	428.5892158309310
1.818	428.58921583093200
1.82	428.5892158309320
1.822	428.589215830933
1.824	428.5892158309340
1.826	428.58921583093400
1.828	428.589215830935
1.83	428.58921583093600
1.832	428.58921583093600
1.834	428.58921583093700
1.836	428.5892158309370
1.838	428.589215830938
1.84	428.5892158309390
1.842	428.589215830939
1.844	428.5892158309400
1.846	428.58921583094
1.848	428.5892158309410
1.85	428.58921583094100
1.852	428.5892158309410
1.854	428.5892158309420
1.856	428.5892158309420
1.858	428.58921583094300
1.86	428.589215830943
1.862	428.5892158309430
1.864	428.5892158309440
1.866	428.58921583094400
1.868	428.5892158309440
1.87	428.58921583094500
1.872	428.589215830945
1.874	428.58921583094500
1.8760000000000000	428.58921583094600
1.8780000000000000	428.58921583094600
1.8800000000000000	428.58921583094600
1.8820000000000000	428.5892158309470
1.8840000000000000	428.5892158309470
1.8860000000000000	428.58921583094700
1.8880000000000000	428.58921583094700
1.8900000000000000	428.58921583094700
1.8920000000000000	428.5892158309480
1.8940000000000000	428.5892158309480
1.8960000000000000	428.5892158309480
1.8980000000000000	428.5892158309480
1.9000000000000000	428.58921583094900
1.9020000000000000	428.5892158309490
1.9040000000000000	428.5892158309490
1.9060000000000000	428.5892158309490
1.9080000000000000	428.58921583094900
1.9100000000000000	428.58921583094900
1.9120000000000000	428.58921583095000
1.9140000000000000	428.5892158309500
1.9160000000000000	428.5892158309500
1.9180000000000000	428.5892158309500
1.92	428.58921583095000
1.922	428.58921583095000
1.924	428.5892158309510
1.926	428.5892158309510
1.928	428.5892158309510
1.93	428.5892158309510
1.932	428.589215830951
1.934	428.5892158309510
1.936	428.5892158309510
1.938	428.58921583095100
1.94	428.5892158309510
1.942	428.5892158309520
1.944	428.5892158309520
1.946	428.58921583095200
1.948	428.58921583095200
1.95	428.5892158309520
1.952	428.58921583095200
1.954	428.58921583095200
1.956	428.5892158309520
1.958	428.58921583095200
1.96	428.5892158309520
1.962	428.5892158309520
1.964	428.5892158309520
1.966	428.5892158309530
1.968	428.5892158309530
1.97	428.58921583095300
1.972	428.58921583095300
1.974	428.58921583095300
1.976	428.5892158309530
1.978	428.58921583095300
1.98	428.5892158309530
1.982	428.589215830953
1.984	428.58921583095300
1.986	428.5892158309530
1.988	428.58921583095300
1.99	428.5892158309530
1.992	428.5892158309530
1.994	428.58921583095300
1.996	428.5892158309530
1.998	428.5892158309530
2.0	428.58921583095300