File: P2_Plasticity/Aluminium.csv
Tensile strain (Strain 1) : Primary source		Strain 1

Results Table 1
	Tensile strain (Strain 1) gauge length	Strain 1 gauge length	Time at removal
	(mm)	(mm)	(s)
1	50.00	50.00	54.05
2	50.00	50.00	54.05
3	50.00	50.00	54.03

Results Table 2


1	Time	Displacement	Force	Tensile strain (Strain 1)	Tensile displacement	Strain 1
	(s)	(mm)	(kN)	(%)	(mm)	(%)
	0.0000	0.0000	0.0129	-0.2071	-0.1036	-0.2071
	0.1000	0.0047	0.0319	-0.2060	-0.1030	-0.2060
	0.2000	0.0126	0.0816	-0.2037	-0.1018	-0.2037
	0.3000	0.0212	0.1373	-0.2009	-0.1005	-0.2009
	0.4000	0.0295	0.1978	-0.1979	-0.0990	-0.1979
	0.5000	0.0380	0.2646	-0.1944	-0.0972	-0.1944
	0.6000	0.0460	0.3319	-0.1907	-0.0954	-0.1907
	0.7000	0.0545	0.4042	-0.1868	-0.0934	-0.1868
	0.8000	0.0630	0.4751	-0.1829	-0.0914	-0.1829
	0.9000	0.0712	0.5464	-0.1789	-0.0895	-0.1789
	1.0000	0.0797	0.6210	-0.1747	-0.0874	-0.1747
	1.1000	0.0877	0.6903	-0.1709	-0.0854	-0.1709
	1.2000	0.0961	0.7619	-0.1668	-0.0834	-0.1668
	1.3000	0.1046	0.8331	-0.1628	-0.0814	-0.1628
	1.4000	0.1127	0.9043	-0.1588	-0.0794	-0.1588
	1.5000	0.1212	0.9768	-0.1546	-0.0773	-0.1546
	1.6000	0.1295	1.0459	-0.1507	-0.0753	-0.1507
	1.7000	0.1378	1.1168	-0.1467	-0.0733	-0.1467
	1.8000	0.1463	1.1869	-0.1426	-0.0713	-0.1426
	1.9000	0.1546	1.2576	-0.1386	-0.0693	-0.1386
	2.0000	0.1631	1.3281	-0.1346	-0.0673	-0.1346
	2.1000	0.1710	1.3948	-0.1307	-0.0654	-0.1307
	2.2000	0.1794	1.4641	-0.1268	-0.0634	-0.1268
	2.3000	0.1879	1.5320	-0.1229	-0.0614	-0.1229
	2.4000	0.1961	1.5995	-0.1190	-0.0595	-0.1190
	2.5000	0.2045	1.6683	-0.1151	-0.0575	-0.1151
	2.6000	0.2126	1.7345	-0.1113	-0.0556	-0.1113
	2.7000	0.2211	1.8024	-0.1074	-0.0537	-0.1074
	2.8000	0.2296	1.8669	-0.1037	-0.0518	-0.1037
	2.9000	0.2378	1.9335	-0.0998	-0.0499	-0.0998
	3.0000	0.2463	2.0012	-0.0960	-0.0480	-0.0960
	3.1000	0.2545	2.0643	-0.0923	-0.0462	-0.0923
	3.2000	0.2628	2.1281	-0.0887	-0.0443	-0.0887
	3.3000	0.2711	2.1921	-0.0850	-0.0425	-0.0850
	3.4000	0.2794	2.2578	-0.0811	-0.0406	-0.0811
	3.5000	0.2879	2.3216	-0.0775	-0.0387	-0.0775
	3.6000	0.2960	2.3843	-0.0738	-0.0369	-0.0738
	3.7000	0.3044	2.4493	-0.0701	-0.0350	-0.0701
	3.8000	0.3127	2.5114	-0.0665	-0.0333	-0.0665
	3.9000	0.3212	2.5754	-0.0628	-0.0314	-0.0628
	4.0000	0.3298	2.6381	-0.0592	-0.0296	-0.0592
	4.1000	0.3377	2.6994	-0.0556	-0.0278	-0.0556
	4.2000	0.3461	2.7614	-0.0520	-0.0260	-0.0520
	4.3000	0.3544	2.8213	-0.0485	-0.0243	-0.0485
	4.4000	0.3627	2.8822	-0.0450	-0.0225	-0.0450
	4.5000	0.3712	2.9416	-0.0415	-0.0208	-0.0415
	4.6000	0.3795	3.0013	-0.0380	-0.0190	-0.0380
	4.7000	0.3879	3.0592	-0.0347	-0.0173	-0.0347
	4.8000	0.3960	3.1135	-0.0315	-0.0157	-0.0315
	4.9000	0.4045	3.1687	-0.0282	-0.0141	-0.0282
	5.0000	0.4131	3.2203	-0.0252	-0.0126	-0.0252
	5.1000	0.4212	3.2699	-0.0223	-0.0112	-0.0223
	5.2000	0.4294	3.3183	-0.0195	-0.0097	-0.0195
	5.3000	0.4376	3.3661	-0.0167	-0.0083	-0.0167
	5.4000	0.4462	3.4157	-0.0138	-0.0069	-0.0138
	5.5000	0.4546	3.4614	-0.0111	-0.0055	-0.0111
	5.6000	0.4627	3.5095	-0.0083	-0.0041	-0.0083
	5.7000	0.4712	3.5590	-0.0053	-0.0027	-0.0053
	5.8000	0.4795	3.6044	-0.0026	-0.0013	-0.0026
	5.9000	0.4879	3.6515	0.0001	0.0000	0.0001
	6.0000	0.4963	3.6971	0.0028	0.0014	0.0028
	6.1000	0.5046	3.7442	0.0056	0.0028	0.0056
	6.2000	0.5129	3.7902	0.0083	0.0042	0.0083
	6.3000	0.5211	3.8357	0.0110	0.0055	0.0110
	6.4000	0.5295	3.8828	0.0138	0.0069	0.0138
	6.5000	0.5377	3.9283	0.0165	0.0082	0.0165
	6.6000	0.5462	3.9751	0.0193	0.0096	0.0193
	6.7000	0.5546	4.0206	0.0220	0.0110	0.0220
	6.8000	0.5627	4.0664	0.0247	0.0124	0.0247
	6.9000	0.5713	4.1143	0.0275	0.0138	0.0275
	7.0000	0.5796	4.1582	0.0302	0.0151	0.0302
	7.1000	0.5879	4.2031	0.0329	0.0164	0.0329
	7.2000	0.5963	4.2473	0.0355	0.0177	0.0355
	7.3000	0.6045	4.2922	0.0381	0.0191	0.0381
	7.4000	0.6129	4.3378	0.0409	0.0204	0.0409
	7.5000	0.6210	4.3808	0.0435	0.0217	0.0435
	7.6000	0.6295	4.4272	0.0462	0.0231	0.0462
	7.7000	0.6380	4.4716	0.0489	0.0244	0.0489
	7.8000	0.6462	4.5167	0.0515	0.0258	0.0515
	7.9000	0.6545	4.5625	0.0543	0.0272	0.0543
	8.0000	0.6628	4.6073	0.0570	0.0285	0.0570
	8.1000	0.6714	4.6538	0.0598	0.0299	0.0598
	8.2000	0.6795	4.6955	0.0623	0.0311	0.0623
	8.3000	0.6877	4.7414	0.0651	0.0325	0.0651
	8.4000	0.6963	4.7892	0.0679	0.0340	0.0679
	8.5000	0.7044	4.8321	0.0705	0.0353	0.0705
	8.6000	0.7129	4.8756	0.0731	0.0366	0.0731
	8.7000	0.7211	4.9204	0.0759	0.0380	0.0759
	8.8000	0.7295	4.9671	0.0787	0.0394	0.0787
	8.9000	0.7380	5.0129	0.0815	0.0407	0.0815
	9.0000	0.7462	5.0582	0.0842	0.0421	0.0842
	9.1000	0.7546	5.1050	0.0871	0.0435	0.0871
	9.2000	0.7626	5.1488	0.0897	0.0449	0.0897
	9.3000	0.7711	5.1954	0.0926	0.0463	0.0926
	9.4000	0.7796	5.2414	0.0954	0.0477	0.0954
	9.5000	0.7877	5.2870	0.0982	0.0491	0.0982
	9.6000	0.7962	5.3346	0.1011	0.0506	0.1011
	9.7000	0.8044	5.3789	0.1039	0.0520	0.1039
	9.8000	0.8128	5.4257	0.1067	0.0534	0.1067
	9.9000	0.8213	5.4722	0.1097	0.0548	0.1097
	10.0000	0.8296	5.5189	0.1125	0.0563	0.1125
	10.1000	0.8380	5.5658	0.1155	0.0577	0.1155
	10.2000	0.8460	5.6092	0.1181	0.0591	0.1181
	10.3000	0.8544	5.6557	0.1211	0.0606	0.1211
	10.4000	0.8630	5.7021	0.1240	0.0620	0.1240
	10.5000	0.8711	5.7472	0.1269	0.0634	0.1269
	10.6000	0.8794	5.7937	0.1298	0.0649	0.1298
	10.7000	0.8877	5.8392	0.1327	0.0664	0.1327
	10.8000	0.8963	5.8862	0.1358	0.0679	0.1358
	10.9000	0.9047	5.9302	0.1386	0.0693	0.1386
	11.0000	0.9128	5.9759	0.1416	0.0708	0.1416
	11.1000	0.9214	6.0240	0.1447	0.0723	0.1447
	11.2000	0.9295	6.0668	0.1475	0.0738	0.1475
	11.3000	0.9378	6.1113	0.1505	0.0753	0.1505
	11.4000	0.9461	6.1559	0.1535	0.0768	0.1535
	11.5000	0.9545	6.2008	0.1566	0.0783	0.1566
	11.6000	0.9629	6.2444	0.1597	0.0798	0.1597
	11.7000	0.9711	6.2867	0.1627	0.0814	0.1627
	11.8000	0.9794	6.3323	0.1660	0.0830	0.1660
	11.9000	0.9877	6.3757	0.1692	0.0846	0.1692
	12.0000	0.9963	6.4199	0.1726	0.0863	0.1726
	12.1000	1.0047	6.4626	0.1759	0.0880	0.1759
	12.2000	1.0128	6.5040	0.1793	0.0897	0.1793
	12.3000	1.0212	6.5471	0.1829	0.0915	0.1829
	12.4000	1.0294	6.5867	0.1865	0.0932	0.1865
	12.5000	1.0377	6.6268	0.1901	0.0951	0.1901
	12.6000	1.0462	6.6666	0.1940	0.0970	0.1940
	12.7000	1.0545	6.7066	0.1980	0.0990	0.1980
	12.8000	1.0628	6.7445	0.2021	0.1010	0.2021
	12.9000	1.0710	6.7803	0.2062	0.1031	0.2062
	13.0000	1.0796	6.8181	0.2106	0.1053	0.2106
	13.1000	1.0882	6.8530	0.2151	0.1076	0.2151
	13.2000	1.0962	6.8856	0.2197	0.1099	0.2197
	13.3000	1.1044	6.9183	0.2244	0.1122	0.2244
	13.4000	1.1127	6.9501	0.2294	0.1147	0.2294
	13.5000	1.1212	6.9814	0.2345	0.1172	0.2345
	13.6000	1.1296	7.0093	0.2396	0.1198	0.2396
	13.7000	1.1377	7.0378	0.2451	0.1226	0.2451
	13.8000	1.1462	7.0666	0.2508	0.1254	0.2508
	13.9000	1.1545	7.0916	0.2564	0.1282	0.2564
	14.0000	1.1629	7.1163	0.2623	0.1311	0.2623
	14.1000	1.1713	7.1394	0.2683	0.1341	0.2683
	14.2000	1.1796	7.1633	0.2746	0.1373	0.2746
	14.3000	1.1879	7.1849	0.2808	0.1404	0.2808
	14.4000	1.1962	7.2052	0.2871	0.1435	0.2871
	14.5000	1.2046	7.2261	0.2938	0.1469	0.2938
	14.6000	1.2128	7.2442	0.3002	0.1501	0.3002
	14.7000	1.2212	7.2633	0.3071	0.1536	0.3071
	14.8000	1.2297	7.2806	0.3139	0.1570	0.3139
	14.9000	1.2378	7.2966	0.3209	0.1604	0.3209
	15.0000	1.2463	7.3142	0.3280	0.1640	0.3280
	15.1000	1.2547	7.3289	0.3351	0.1676	0.3351
	15.2000	1.2629	7.3432	0.3425	0.1712	0.3425
	15.3000	1.2713	7.3570	0.3497	0.1748	0.3497
	15.4000	1.2796	7.3714	0.3571	0.1785	0.3571
	15.5000	1.2879	7.3849	0.3646	0.1823	0.3646
	15.6000	1.2960	7.3957	0.3720	0.1860	0.3720
	15.7000	1.3045	7.4088	0.3797	0.1899	0.3797
	15.8000	1.3130	7.4206	0.3873	0.1936	0.3873
	15.9000	1.3212	7.4313	0.3951	0.1976	0.3951
	16.0000	1.3296	7.4429	0.4030	0.2015	0.4030
	16.1000	1.3378	7.4523	0.4109	0.2054	0.4109
	16.2000	1.3464	7.4630	0.4189	0.2095	0.4189
	16.3000	1.3546	7.4700	0.4267	0.2133	0.4267
	16.4000	1.3627	7.4796	0.4347	0.2173	0.4347
	16.5000	1.3712	7.4910	0.4429	0.2214	0.4429
	16.6000	1.3795	7.4981	0.4509	0.2255	0.4509
	16.7000	1.3879	7.5063	0.4591	0.2295	0.4591
	16.8000	1.3961	7.5130	0.4673	0.2336	0.4673
	16.9000	1.4046	7.5222	0.4757	0.2378	0.4757
	17.0000	1.4130	7.5295	0.4839	0.2420	0.4839
	17.1000	1.4212	7.5350	0.4922	0.2461	0.4922
	17.2000	1.4296	7.5429	0.5007	0.2504	0.5007
	17.3000	1.4378	7.5482	0.5090	0.2545	0.5090
	17.4000	1.4462	7.5555	0.5174	0.2587	0.5174
	17.5000	1.4547	7.5618	0.5259	0.2630	0.5259
	17.6000	1.4628	7.5662	0.5344	0.2672	0.5344
	17.7000	1.4712	7.5737	0.5430	0.2715	0.5430
	17.8000	1.4795	7.5779	0.5514	0.2757	0.5514
	17.9000	1.4878	7.5826	0.5599	0.2800	0.5599
	18.0000	1.4962	7.5885	0.5686	0.2843	0.5686
	18.1000	1.5047	7.5946	0.5773	0.2887	0.5773
	18.2000	1.5131	7.5994	0.5861	0.2930	0.5861
	18.3000	1.5211	7.6011	0.5945	0.2973	0.5945
	18.4000	1.5295	7.6071	0.6032	0.3016	0.6032
	18.5000	1.5381	7.6121	0.6119	0.3059	0.6119
	18.6000	1.5462	7.6149	0.6205	0.3103	0.6205
	18.7000	1.5545	7.6206	0.6292	0.3146	0.6292
	18.8000	1.5627	7.6234	0.6380	0.3190	0.6380
	18.9000	1.5713	7.6284	0.6468	0.3234	0.6468
	19.0000	1.5797	7.6312	0.6555	0.3277	0.6555
	19.1000	1.5879	7.6344	0.6643	0.3322	0.6643
	19.2000	1.5963	7.6401	0.6734	0.3367	0.6734
	19.3000	1.6045	7.6415	0.6820	0.3410	0.6820
	19.4000	1.6129	7.6447	0.6906	0.3453	0.6906
	19.5000	1.6211	7.6478	0.6995	0.3497	0.6995
	19.6000	1.6295	7.6523	0.7084	0.3542	0.7084
	19.7000	1.6380	7.6559	0.7173	0.3586	0.7173
	19.8000	1.6461	7.6573	0.7261	0.3631	0.7261
	19.9000	1.6545	7.6612	0.7351	0.3676	0.7351
	20.0000	1.6628	7.6637	0.7440	0.3720	0.7440
	20.1000	1.6713	7.6675	0.7530	0.3765	0.7530
	20.2000	1.6798	7.6704	0.7620	0.3810	0.7620
	20.3000	1.6878	7.6710	0.7709	0.3855	0.7709
	20.4000	1.6962	7.6754	0.7800	0.3900	0.7800
	20.5000	1.7045	7.6774	0.7888	0.3944	0.7888
	20.6000	1.7128	7.6793	0.7979	0.3989	0.7979
	20.7000	1.7212	7.6822	0.8069	0.4035	0.8069
	20.8000	1.7296	7.6853	0.8160	0.4080	0.8160
	20.9000	1.7379	7.6880	0.8251	0.4125	0.8251
	21.0000	1.7460	7.6888	0.8341	0.4171	0.8341
	21.1000	1.7546	7.6925	0.8433	0.4216	0.8433
	21.2000	1.7632	7.6952	0.8525	0.4262	0.8525
	21.3000	1.7713	7.6957	0.8616	0.4308	0.8616
	21.4000	1.7795	7.6985	0.8706	0.4353	0.8706
	21.5000	1.7878	7.7004	0.8797	0.4399	0.8797
	21.6000	1.7963	7.7035	0.8890	0.4445	0.8890
	21.7000	1.8047	7.7042	0.8980	0.4490	0.8980
	21.8000	1.8127	7.7061	0.9072	0.4536	0.9072
	21.9000	1.8211	7.7100	0.9165	0.4582	0.9165
	22.0000	1.8296	7.7116	0.9257	0.4628	0.9257
	22.1000	1.8380	7.7131	0.9349	0.4674	0.9349
	22.2000	1.8464	7.7144	0.9442	0.4721	0.9442
	22.3000	1.8546	7.7164	0.9535	0.4768	0.9535
	22.4000	1.8629	7.7182	0.9625	0.4813	0.9625
	22.5000	1.8712	7.7199	0.9717	0.4859	0.9717
	22.6000	1.8796	7.7223	0.9811	0.4906	0.9811
	22.7000	1.8878	7.7233	0.9902	0.4951	0.9902
	22.8000	1.8962	7.7258	0.9996	0.4998	0.9996
	22.9000	1.9047	7.7276	1.0089	0.5044	1.0089
	23.0000	1.9128	7.7283	1.0181	0.5091	1.0181
	23.1000	1.9213	7.7317	1.0276	0.5138	1.0276
	23.2000	1.9297	7.7324	1.0368	0.5184	1.0368
	23.3000	1.9379	7.7334	1.0462	0.5231	1.0462
	23.4000	1.9463	7.7348	1.0554	0.5277	1.0554
	23.5000	1.9546	7.7374	1.0647	0.5324	1.0647
	23.6000	1.9629	7.7394	1.0741	0.5370	1.0741
	23.7000	1.9710	7.7396	1.0833	0.5416	1.0833
	23.8000	1.9795	7.7421	1.0927	0.5464	1.0927
	23.9000	1.9880	7.7438	1.1020	0.5510	1.1020
	24.0000	1.9962	7.7448	1.1114	0.5557	1.1114
	24.1000	2.0045	7.7475	1.1209	0.5605	1.1209
	24.2000	2.0129	7.7484	1.1304	0.5652	1.1304
	24.3000	2.0214	7.7505	1.1399	0.5699	1.1399
	24.4000	2.0296	7.7495	1.1490	0.5745	1.1490
	24.5000	2.0378	7.7516	1.1584	0.5792	1.1584
	24.6000	2.0462	7.7555	1.1681	0.5840	1.1681
	24.7000	2.0545	7.7552	1.1774	0.5887	1.1774
	24.8000	2.0629	7.7571	1.1868	0.5934	1.1868
	24.9000	2.0712	7.7580	1.1963	0.5981	1.1963
	25.0000	2.0796	7.7605	1.2059	0.6030	1.2059
	25.1000	2.0881	7.7624	1.2154	0.6077	1.2154
	25.2000	2.0963	7.7626	1.2250	0.6125	1.2250
	25.3000	2.1047	7.7646	1.2346	0.6173	1.2346
	25.4000	2.1128	7.7644	1.2440	0.6220	1.2440
	25.5000	2.1212	7.7668	1.2535	0.6267	1.2535
	25.6000	2.1297	7.7685	1.2629	0.6315	1.2629
	25.7000	2.1378	7.7689	1.2725	0.6363	1.2725
	25.8000	2.1463	7.7720	1.2822	0.6411	1.2822
	25.9000	2.1545	7.7719	1.2916	0.6458	1.2916
	26.0000	2.1628	7.7731	1.3012	0.6506	1.3012
	26.1000	2.1713	7.7751	1.3108	0.6554	1.3108
	26.2000	2.1797	7.7769	1.3205	0.6602	1.3205
	26.3000	2.1880	7.7786	1.3302	0.6651	1.3302
	26.4000	2.1961	7.7776	1.3396	0.6698	1.3396
	26.5000	2.2045	7.7798	1.3492	0.6746	1.3492
	26.6000	2.2131	7.7821	1.3588	0.6794	1.3588
	26.7000	2.2212	7.7821	1.3684	0.6842	1.3684
	26.8000	2.2296	7.7845	1.3780	0.6890	1.3780
	26.9000	2.2377	7.7849	1.3876	0.6938	1.3876
	27.0000	2.2462	7.7870	1.3972	0.6986	1.3972
	27.1000	2.2547	7.7873	1.4068	0.7034	1.4068
	27.2000	2.2628	7.7888	1.4165	0.7082	1.4165
	27.3000	2.2714	7.7923	1.4264	0.7132	1.4264
	27.4000	2.2796	7.7913	1.4358	0.7179	1.4358
	27.5000	2.2878	7.7918	1.4454	0.7227	1.4454
	27.6000	2.2962	7.7934	1.4550	0.7275	1.4550
	27.7000	2.3045	7.7954	1.4648	0.7324	1.4648
	27.8000	2.3130	7.7972	1.4743	0.7372	1.4743
	27.9000	2.3211	7.7970	1.4839	0.7420	1.4839
	28.0000	2.3296	7.7993	1.4937	0.7469	1.4937
	28.1000	2.3378	7.7998	1.5033	0.7516	1.5033
	28.2000	2.3463	7.8017	1.5130	0.7565	1.5130
	28.3000	2.3548	7.8033	1.5227	0.7614	1.5227
	28.4000	2.3628	7.8029	1.5324	0.7662	1.5324
	28.5000	2.3711	7.8052	1.5420	0.7710	1.5420
	28.6000	2.3795	7.8064	1.5516	0.7758	1.5516
	28.7000	2.3879	7.8074	1.5614	0.7807	1.5614
	28.8000	2.3963	7.8086	1.5710	0.7855	1.5710
	28.9000	2.4046	7.8104	1.5809	0.7904	1.5809
	29.0000	2.4129	7.8121	1.5906	0.7953	1.5906
	29.1000	2.4211	7.8115	1.6002	0.8001	1.6002
	29.2000	2.4296	7.8138	1.6101	0.8050	1.6101
	29.3000	2.4382	7.8153	1.6198	0.8099	1.6198
	29.4000	2.4463	7.8155	1.6296	0.8148	1.6296
	29.5000	2.4545	7.8168	1.6392	0.8196	1.6392
	29.6000	2.4628	7.8180	1.6489	0.8245	1.6489
	29.7000	2.4713	7.8203	1.6588	0.8294	1.6588
	29.8000	2.4797	7.8200	1.6684	0.8342	1.6684
	29.9000	2.4878	7.8208	1.6782	0.8391	1.6782
	30.0000	2.4962	7.8239	1.6881	0.8440	1.6881
	30.1000	2.5046	7.8244	1.6977	0.8488	1.6977
	30.2000	2.5130	7.8253	1.7075	0.8537	1.7075
	30.3000	2.5214	7.8260	1.7173	0.8586	1.7173
	30.4000	2.5297	7.8276	1.7271	0.8636	1.7271
	30.5000	2.5380	7.8286	1.7368	0.8684	1.7368
	30.6000	2.5462	7.8290	1.7464	0.8732	1.7464
	30.7000	2.5546	7.8310	1.7562	0.8781	1.7562
	30.8000	2.5628	7.8311	1.7658	0.8829	1.7658
	30.9000	2.5712	7.8336	1.7757	0.8878	1.7757
	31.0000	2.5797	7.8345	1.7854	0.8927	1.7854
	31.1000	2.5878	7.8347	1.7951	0.8976	1.7951
	31.2000	2.5963	7.8375	1.8050	0.9025	1.8050
	31.3000	2.6047	7.8376	1.8146	0.9073	1.8146
	31.4000	2.6129	7.8380	1.8245	0.9122	1.8245
	31.5000	2.6213	7.8391	1.8341	0.9170	1.8341
	31.6000	2.6296	7.8410	1.8438	0.9219	1.8438
	31.7000	2.6379	7.8428	1.8536	0.9268	1.8536
	31.8000	2.6461	7.8423	1.8632	0.9316	1.8632
	31.9000	2.6545	7.8444	1.8730	0.9365	1.8730
	32.0000	2.6630	7.8455	1.8826	0.9413	1.8826
	32.1000	2.6712	7.8464	1.8924	0.9462	1.8924
	32.2000	2.6795	7.8481	1.9021	0.9511	1.9021
	32.3000	2.6878	7.8485	1.9119	0.9559	1.9119
	32.4000	2.6964	7.8513	1.9218	0.9609	1.9218
	32.5000	2.7046	7.8494	1.9312	0.9656	1.9312
	32.6000	2.7127	7.8513	1.9411	0.9705	1.9411
	32.7000	2.7213	7.8549	1.9510	0.9755	1.9510
	32.8000	2.7295	7.8542	1.9605	0.9803	1.9605
	32.9000	2.7379	7.8556	1.9703	0.9852	1.9703
	33.0000	2.7462	7.8559	1.9800	0.9900	1.9800
	33.1000	2.7545	7.8579	1.9899	0.9949	1.9899
	33.2000	2.7630	7.8598	1.9996	0.9998	1.9996
	33.3000	2.7713	7.8602	2.0094	1.0047	2.0094
	33.4000	2.7797	7.8612	2.0193	1.0096	2.0193
	33.5000	2.7878	7.8609	2.0289	1.0144	2.0289
	33.6000	2.7962	7.8630	2.0386	1.0193	2.0386
	33.7000	2.8047	7.8646	2.0483	1.0241	2.0483
	33.8000	2.8128	7.8647	2.0581	1.0290	2.0581
	33.9000	2.8213	7.8678	2.0680	1.0340	2.0680
	34.0000	2.8295	7.8670	2.0775	1.0388	2.0775
	34.1000	2.8378	7.8683	2.0874	1.0437	2.0874
	34.2000	2.8464	7.8705	2.0972	1.0486	2.0972
	34.3000	2.8547	7.8713	2.1070	1.0535	2.1070
	34.4000	2.8631	7.8732	2.1169	1.0584	2.1169
	34.5000	2.8711	7.8716	2.1265	1.0632	2.1265
	34.6000	2.8795	7.8734	2.1361	1.0681	2.1361
	34.7000	2.8881	7.8753	2.1459	1.0729	2.1459
	34.8000	2.8962	7.8754	2.1555	1.0778	2.1555
	34.9000	2.9045	7.8776	2.1653	1.0826	2.1653
	35.0000	2.9127	7.8779	2.1750	1.0875	2.1750
	35.1000	2.9213	7.8799	2.1848	1.0924	2.1848
	35.2000	2.9297	7.8797	2.1943	1.0972	2.1943
	35.3000	2.9379	7.8811	2.2042	1.1021	2.2042
	35.4000	2.9464	7.8844	2.2141	1.1071	2.2141
	35.5000	2.9546	7.8830	2.2236	1.1118	2.2236
	35.6000	2.9629	7.8838	2.2332	1.1166	2.2332
	35.7000	2.9713	7.8853	2.2430	1.1215	2.2430
	35.8000	2.9795	7.8865	2.2527	1.1264	2.2527
	35.9000	2.9880	7.8882	2.2624	1.1312	2.2624
	36.0000	2.9962	7.8880	2.2720	1.1360	2.2720
	36.1000	3.0045	7.8898	2.2818	1.1409	2.2818
	36.2000	3.0127	7.8903	2.2913	1.1457	2.2913
	36.3000	3.0212	7.8923	2.3011	1.1505	2.3011
	36.4000	3.0298	7.8939	2.3108	1.1554	2.3108
	36.5000	3.0378	7.8933	2.3206	1.1603	2.3206
	36.6000	3.0461	7.8956	2.3302	1.1651	2.3302
	36.7000	3.0544	7.8959	2.3398	1.1699	2.3398
	36.8000	3.0628	7.8973	2.3496	1.1748	2.3496
	36.9000	3.0712	7.8979	2.3592	1.1796	2.3592
	37.0000	3.0796	7.8997	2.3690	1.1845	2.3690
	37.1000	3.0879	7.9013	2.3787	1.1893	2.3787
	37.2000	3.0961	7.9008	2.3883	1.1942	2.3883
	37.3000	3.1046	7.9028	2.3981	1.1991	2.3981
	37.4000	3.1132	7.9042	2.4078	1.2039	2.4078
	37.5000	3.1213	7.9039	2.4175	1.2087	2.4175
	37.6000	3.1295	7.9052	2.4271	1.2135	2.4271
	37.7000	3.1378	7.9065	2.4368	1.2184	2.4368
	37.8000	3.1464	7.9086	2.4466	1.2233	2.4466
	37.9000	3.1548	7.9079	2.4561	1.2280	2.4561
	38.0000	3.1628	7.9087	2.4658	1.2329	2.4658
	38.1000	3.1712	7.9117	2.4756	1.2378	2.4756
	38.2000	3.1796	7.9121	2.4852	1.2426	2.4852
	38.3000	3.1879	7.9125	2.4949	1.2475	2.4949
	38.4000	3.1964	7.9135	2.5046	1.2523	2.5046
	38.5000	3.2047	7.9149	2.5144	1.2572	2.5144
	38.6000	3.2130	7.9158	2.5240	1.2620	2.5240
	38.7000	3.2212	7.9161	2.5335	1.2667	2.5335
	38.8000	3.2295	7.9178	2.5432	1.2716	2.5432
	38.9000	3.2378	7.9181	2.5528	1.2764	2.5528
	39.0000	3.2462	7.9201	2.5625	1.2812	2.5625
	39.1000	3.2546	7.9203	2.5720	1.2860	2.5720
	39.2000	3.2628	7.9215	2.5818	1.2909	2.5818
	39.3000	3.2714	7.9240	2.5915	1.2958	2.5915
	39.4000	3.2797	7.9236	2.6011	1.3005	2.6011
	39.5000	3.2879	7.9241	2.6108	1.3054	2.6108
	39.6000	3.2963	7.9249	2.6203	1.3101	2.6203
	39.7000	3.3046	7.9266	2.6299	1.3150	2.6299
	39.8000	3.3129	7.9281	2.6395	1.3198	2.6395
	39.9000	3.3210	7.9279	2.6491	1.3245	2.6491
	40.0000	3.3296	7.9303	2.6589	1.3294	2.6589
	40.1000	3.3380	7.9302	2.6683	1.3341	2.6683
	40.2000	3.3462	7.9312	2.6779	1.3390	2.6779
	40.3000	3.3545	7.9332	2.6876	1.3438	2.6876
	40.4000	3.3628	7.9336	2.6972	1.3486	2.6972
	40.5000	3.3714	7.9356	2.7070	1.3535	2.7070
	40.6000	3.3796	7.9339	2.7163	1.3581	2.7163
	40.7000	3.3878	7.9357	2.7260	1.3630	2.7260
	40.8000	3.3963	7.9392	2.7358	1.3679	2.7358
	40.9000	3.4045	7.9382	2.7453	1.3727	2.7453
	41.0000	3.4129	7.9395	2.7549	1.3775	2.7549
	41.1000	3.4211	7.9394	2.7644	1.3822	2.7644
	41.2000	3.4295	7.9419	2.7742	1.3871	2.7742
	41.3000	3.4380	7.9435	2.7838	1.3919	2.7838
	41.4000	3.4463	7.9432	2.7935	1.3967	2.7935
	41.5000	3.4547	7.9452	2.8033	1.4017	2.8033
	41.6000	3.4628	7.9441	2.8127	1.4063	2.8127
	41.7000	3.4712	7.9464	2.8223	1.4112	2.8223
	41.8000	3.4797	7.9476	2.8320	1.4160	2.8320
	41.9000	3.4878	7.9473	2.8416	1.4208	2.8416
	42.0000	3.4962	7.9502	2.8513	1.4256	2.8513
	42.1000	3.5045	7.9497	2.8607	1.4304	2.8607
	42.2000	3.5128	7.9508	2.8704	1.4352	2.8704
	42.3000	3.5213	7.9524	2.8801	1.4401	2.8801
	42.4000	3.5297	7.9538	2.8898	1.4449	2.8898
	42.5000	3.5381	7.9552	2.8995	1.4498	2.8995
	42.6000	3.5461	7.9534	2.9089	1.4545	2.9089
	42.7000	3.5545	7.9552	2.9185	1.4593	2.9185
	42.8000	3.5631	7.9572	2.9281	1.4641	2.9281
	42.9000	3.5712	7.9572	2.9377	1.4688	2.9377
	43.0000	3.5796	7.9590	2.9473	1.4736	2.9473
	43.1000	3.5877	7.9591	2.9568	1.4784	2.9568
	43.2000	3.5963	7.9611	2.9665	1.4833	2.9665
	43.3000	3.6047	7.9607	2.9760	1.4880	2.9760
	43.4000	3.6128	7.9615	2.9856	1.4928	2.9856
	43.5000	3.6213	7.9648	2.9954	1.4977	2.9954
	43.6000	3.6296	7.9641	3.0048	1.5024	3.0048
	43.7000	3.6378	7.9641	3.0143	1.5071	3.0143
	43.8000	3.6462	7.9654	3.0238	1.5119	3.0238
	43.9000	3.6545	7.9674	3.0335	1.5168	3.0335
	44.0000	3.6630	7.9685	3.0431	1.5215	3.0431
	44.1000	3.6711	7.9676	3.0525	1.5263	3.0525
	44.2000	3.6795	7.9700	3.0622	1.5311	3.0622
	44.3000	3.6878	7.9704	3.0716	1.5358	3.0716
	44.4000	3.6963	7.9722	3.0814	1.5407	3.0814
	44.5000	3.7049	7.9733	3.0910	1.5455	3.0910
	44.6000	3.7128	7.9725	3.1006	1.5503	3.1006
	44.7000	3.7212	7.9746	3.1101	1.5551	3.1101
	44.8000	3.7296	7.9751	3.1196	1.5598	3.1196
	44.9000	3.7378	7.9754	3.1292	1.5646	3.1292
	45.0000	3.7462	7.9764	3.1386	1.5693	3.1386
	45.1000	3.7546	7.9784	3.1482	1.5741	3.1482
	45.2000	3.7629	7.9796	3.1579	1.5789	3.1579
	45.3000	3.7711	7.9791	3.1674	1.5837	3.1674
	45.4000	3.7796	7.9812	3.1771	1.5886	3.1771
	45.5000	3.7882	7.9826	3.1867	1.5933	3.1867
	45.6000	3.7963	7.9818	3.1962	1.5981	3.1962
	45.7000	3.8045	7.9831	3.2057	1.6028	3.2057
	45.8000	3.8128	7.9840	3.2152	1.6076	3.2152
	45.9000	3.8213	7.9858	3.2249	1.6124	3.2249
	46.0000	3.8297	7.9857	3.2343	1.6172	3.2343
	46.1000	3.8377	7.9860	3.2439	1.6220	3.2439
	46.2000	3.8461	7.9886	3.2536	1.6268	3.2536
	46.3000	3.8546	7.9892	3.2631	1.6316	3.2631
	46.4000	3.8630	7.9897	3.2727	1.6364	3.2727
	46.5000	3.8713	7.9901	3.2823	1.6411	3.2823
	46.6000	3.8797	7.9919	3.2920	1.6460	3.2920
	46.7000	3.8880	7.9920	3.3014	1.6507	3.3014
	46.8000	3.8962	7.9923	3.3109	1.6555	3.3109
	46.9000	3.9046	7.9943	3.3206	1.6603	3.3206
	47.0000	3.9128	7.9940	3.3300	1.6650	3.3300
	47.1000	3.9212	7.9957	3.3397	1.6698	3.3397
	47.2000	3.9297	7.9967	3.3491	1.6746	3.3491
	47.3000	3.9378	7.9969	3.3587	1.6793	3.3587
	47.4000	3.9463	7.9993	3.3684	1.6842	3.3684
	47.5000	3.9548	7.9993	3.3779	1.6889	3.3779
	47.6000	3.9629	7.9991	3.3875	1.6937	3.3875
	47.7000	3.9712	7.9997	3.3969	1.6984	3.3969
	47.8000	3.9797	8.0018	3.4065	1.7032	3.4065
	47.9000	3.9879	8.0027	3.4160	1.7080	3.4160
	48.0000	3.9960	8.0022	3.4254	1.7127	3.4254
	48.1000	4.0045	8.0044	3.4350	1.7175	3.4350
	48.2000	4.0130	8.0046	3.4444	1.7222	3.4444
	48.3000	4.0212	8.0055	3.4540	1.7270	3.4540
	48.4000	4.0296	8.0073	3.4636	1.7318	3.4636
	48.5000	4.0379	8.0077	3.4732	1.7366	3.4732
	48.6000	4.0464	8.0090	3.4828	1.7414	3.4828
	48.7000	4.0546	8.0077	3.4921	1.7460	3.4921
	48.8000	4.0627	8.0090	3.5016	1.7508	3.5016
	48.9000	4.0712	8.0125	3.5113	1.7557	3.5113
	49.0000	4.0795	8.0116	3.5207	1.7603	3.5207
	49.1000	4.0880	8.0128	3.5303	1.7652	3.5303
	49.2000	4.0962	8.0125	3.5398	1.7699	3.5398
	49.3000	4.1046	8.0147	3.5495	1.7747	3.5495
	49.4000	4.1130	8.0158	3.5590	1.7795	3.5590
	49.5000	4.1213	8.0156	3.5685	1.7843	3.5685
	49.6000	4.1297	8.0172	3.5783	1.7891	3.5783
	49.7000	4.1378	8.0159	3.5875	1.7938	3.5875
	49.8000	4.1462	8.0183	3.5972	1.7986	3.5972
	49.9000	4.1548	8.0198	3.6067	1.8034	3.6067
	50.0000	4.1628	8.0192	3.6162	1.8081	3.6162
	50.1000	4.1712	8.0218	3.6259	1.8130	3.6259
	50.2000	4.1795	8.0210	3.6353	1.8177	3.6353
	50.3000	4.1878	8.0215	3.6449	1.8225	3.6449
	50.4000	4.1963	8.0237	3.6545	1.8273	3.6545
	50.5000	4.2047	8.0248	3.6641	1.8321	3.6641
	50.6000	4.2131	8.0260	3.6738	1.8369	3.6738
	50.7000	4.2211	8.0241	3.6832	1.8416	3.6832
	50.8000	4.2295	8.0259	3.6927	1.8464	3.6927
	50.9000	4.2381	8.0276	3.7023	1.8511	3.7023
	51.0000	4.2462	8.0274	3.7118	1.8559	3.7118
	51.1000	4.2545	8.0290	3.7213	1.8607	3.7213
	51.2000	4.2627	8.0294	3.7309	1.8655	3.7309
	51.3000	4.2713	8.0310	3.7405	1.8703	3.7405
	51.4000	4.2797	8.0304	3.7499	1.8750	3.7499
	51.5000	4.2879	8.0312	3.7595	1.8797	3.7595
	51.6000	4.2963	8.0341	3.7693	1.8846	3.7693
	51.7000	4.3045	8.0326	3.7786	1.8893	3.7786
	51.8000	4.3128	8.0331	3.7879	1.8940	3.7879
	51.9000	4.3212	8.0345	3.7975	1.8988	3.7975
	52.0000	4.3296	8.0359	3.8072	1.9036	3.8072
	52.1000	4.3380	8.0372	3.8167	1.9083	3.8167
	52.2000	4.3461	8.0363	3.8261	1.9130	3.8261
	52.3000	4.3545	8.0383	3.8357	1.9179	3.8357
	52.4000	4.3628	8.0384	3.8452	1.9226	3.8452
	52.5000	4.3713	8.0401	3.8548	1.9274	3.8548
	52.6000	4.3798	8.0409	3.8643	1.9322	3.8643
	52.7000	4.3879	8.0402	3.8739	1.9370	3.8739
	52.8000	4.3962	8.0421	3.8834	1.9417	3.8834
	52.9000	4.4045	8.0422	3.8928	1.9464	3.8928
	53.0000	4.4128	8.0428	3.9024	1.9512	3.9024
	53.1000	4.4212	8.0437	3.9119	1.9559	3.9119
	53.2000	4.4296	8.0451	3.9215	1.9607	3.9215
	53.3000	4.4379	8.0463	3.9311	1.9655	3.9311
	53.4000	4.4461	8.0459	3.9405	1.9703	3.9405
	53.5000	4.4546	8.0479	3.9503	1.9751	3.9503
	53.6000	4.4632	8.0487	3.9598	1.9799	3.9598
	53.7000	4.4713	8.0479	3.9693	1.9847	3.9693
	53.8000	4.4795	8.0488	3.9788	1.9894	3.9788
	53.9000	4.4878	8.0499	3.9883	1.9942	3.9883
	54.0000	4.4963	8.0514	3.9980	1.9990	3.9980
	54.0690	4.5027	8.0508	4.0054	2.0027	4.0024
	54.1690	4.5055	8.0261	4.0085	2.0043	4.0024
	54.2690	4.5054	7.9831	4.0084	2.0042	4.0024
	54.3690	4.5052	7.9547	4.0082	2.0041	4.0024
	54.4690	4.5051	7.9328	4.0080	2.0040	4.0024
	54.5690	4.5049	7.9152	4.0078	2.0039	4.0024
	54.6690	4.5047	7.9002	4.0077	2.0038	4.0024
	54.7690	4.5046	7.8869	4.0075	2.0037	4.0024
	54.8690	4.5044	7.8752	4.0073	2.0037	4.0024
	54.9690	4.5043	7.8646	4.0071	2.0036	4.0024
	55.0690	4.5042	7.8551	4.0070	2.0035	4.0024
	55.1690	4.5040	7.8464	4.0069	2.0034	4.0024
	55.2690	4.5040	7.8386	4.0068	2.0034	4.0024
	55.3690	4.5039	7.8315	4.0067	2.0034	4.0024
	55.4690	4.5039	7.8247	4.0067	2.0033	4.0024
	55.5690	4.5038	7.8188	4.0067	2.0033	4.0024
	55.6690	4.5038	7.8130	4.0066	2.0033	4.0024
	55.7690	4.5038	7.8076	4.0066	2.0033	4.0024
	55.8690	4.5038	7.8027	4.0066	2.0033	4.0024
	55.9690	4.5038	7.7980	4.0066	2.0033	4.0024
	56.0690	4.5038	7.7935	4.0066	2.0033	4.0024
	56.1690	4.5037	7.7892	4.0065	2.0033	4.0024
	56.2690	4.5037	7.7852	4.0065	2.0033	4.0024
	56.3690	4.5037	7.7813	4.0065	2.0033	4.0024
	56.4690	4.5037	7.7776	4.0065	2.0033	4.0024
	56.5690	4.5037	7.7739	4.0065	2.0033	4.0024
	56.6690	4.5037	7.7706	4.0065	2.0033	4.0024
	56.7690	4.5037	7.7673	4.0065	2.0033	4.0024
	56.8690	4.5037	7.7641	4.0065	2.0033	4.0024
	56.9690	4.5037	7.7610	4.0065	2.0033	4.0024
	57.0690	4.5037	7.7580	4.0065	2.0033	4.0024
	57.1690	4.5037	7.7551	4.0065	2.0033	4.0024
	57.2690	4.5037	7.7523	4.0065	2.0033	4.0024
	57.3690	4.5037	7.7495	4.0065	2.0033	4.0024
	57.4690	4.5037	7.7468	4.0065	2.0033	4.0024
	57.5690	4.5037	7.7444	4.0065	2.0033	4.0024
	57.6690	4.5037	7.7419	4.0065	2.0033	4.0024
	57.7690	4.5037	7.7394	4.0065	2.0033	4.0024
	57.8690	4.5037	7.7370	4.0065	2.0033	4.0024
	57.9690	4.5037	7.7348	4.0065	2.0033	4.0024
	58.0690	4.5037	7.7325	4.0065	2.0033	4.0024
	58.1690	4.5037	7.7303	4.0065	2.0033	4.0024
	58.2690	4.5037	7.7282	4.0065	2.0033	4.0024
	58.3690	4.5037	7.7260	4.0065	2.0033	4.0024
	58.4690	4.5037	7.7240	4.0065	2.0033	4.0024
	58.5690	4.5037	7.7221	4.0065	2.0033	4.0024
	58.6690	4.5037	7.7201	4.0065	2.0033	4.0024
	58.7690	4.5037	7.7182	4.0065	2.0033	4.0024
	58.8690	4.5037	7.7165	4.0065	2.0032	4.0024
	58.9690	4.5037	7.7147	4.0065	2.0033	4.0024
	59.0690	4.5037	7.7131	4.0065	2.0033	4.0024
	59.1690	4.5037	7.7116	4.0065	2.0033	4.0024
	59.2690	4.5037	7.7096	4.0065	2.0033	4.0024
	59.3690	4.5037	7.7080	4.0065	2.0033	4.0024
	59.4690	4.5037	7.7065	4.0065	2.0033	4.0024
	59.5690	4.5037	7.7047	4.0065	2.0033	4.0024
	59.6690	4.5037	7.7016	4.0065	2.0033	4.0024
	59.7690	4.5037	7.7009	4.0065	2.0033	4.0024
	59.8690	4.5037	7.6990	4.0065	2.0033	4.0024
	59.9690	4.5037	7.6980	4.0065	2.0033	4.0024
	60.0690	4.5037	7.6964	4.0065	2.0033	4.0024
	60.1690	4.5037	7.6947	4.0065	2.0032	4.0024
	60.2690	4.5037	7.6934	4.0065	2.0033	4.0024
	60.3690	4.5037	7.6921	4.0065	2.0033	4.0024
	60.4690	4.5037	7.6906	4.0065	2.0033	4.0024
	60.5690	4.5037	7.6891	4.0065	2.0033	4.0024
	60.6690	4.5037	7.6880	4.0065	2.0033	4.0024
	60.7690	4.5037	7.6864	4.0065	2.0033	4.0024
	60.8690	4.5037	7.6852	4.0065	2.0033	4.0024
	60.9690	4.5037	7.6838	4.0065	2.0033	4.0024
	61.0690	4.5037	7.6826	4.0065	2.0033	4.0024
	61.1690	4.5037	7.6813	4.0065	2.0033	4.0024
	61.2690	4.5037	7.6801	4.0065	2.0033	4.0024
	61.3690	4.5037	7.6790	4.0065	2.0033	4.0024
	61.4690	4.5037	7.6776	4.0065	2.0033	4.0024
	61.5690	4.5037	7.6766	4.0065	2.0033	4.0024
	61.6690	4.5037	7.6754	4.0065	2.0033	4.0024
	61.7690	4.5037	7.6742	4.0065	2.0033	4.0024
	61.8690	4.5037	7.6731	4.0065	2.0033	4.0024
	61.9690	4.5037	7.6720	4.0065	2.0033	4.0024
	62.0690	4.5037	7.6710	4.0065	2.0033	4.0024
	62.1690	4.5037	7.6700	4.0065	2.0033	4.0024
	62.2690	4.5037	7.6688	4.0065	2.0033	4.0024
	62.3690	4.5037	7.6668	4.0065	2.0033	4.0024
	62.4690	4.5037	7.6658	4.0065	2.0033	4.0024
	62.5690	4.5037	7.6674	4.0065	2.0033	4.0024
	62.6690	4.5037	7.6655	4.0065	2.0033	4.0024
	62.7690	4.5037	7.6641	4.0065	2.0033	4.0024
	62.8690	4.5037	7.6640	4.0065	2.0032	4.0024
	62.9690	4.5037	7.6635	4.0065	2.0033	4.0024
	63.0690	4.5037	7.6613	4.0065	2.0033	4.0024
	63.1690	4.5037	7.6623	4.0065	2.0033	4.0024
	63.2690	4.5037	7.6610	4.0065	2.0032	4.0024
	63.3690	4.5037	7.6610	4.0065	2.0033	4.0024
	63.4690	4.5037	7.6590	4.0065	2.0033	4.0024
	63.5690	4.5037	7.6595	4.0065	2.0033	4.0024
	63.6690	4.5037	7.6573	4.0065	2.0033	4.0024
	63.7690	4.5037	7.6567	4.0065	2.0033	4.0024
	63.8690	4.5037	7.6554	4.0065	2.0033	4.0024
	63.9690	4.5037	7.6535	4.0065	2.0033	4.0024
	64.0690	4.5037	7.6527	4.0065	2.0033	4.0024
	64.1690	4.5037	7.6520	4.0065	2.0033	4.0024
	64.2690	4.5037	7.6509	4.0065	2.0033	4.0024
	64.3690	4.5037	7.6501	4.0065	2.0033	4.0024
	64.4690	4.5037	7.6491	4.0065	2.0033	4.0024
	64.5690	4.5037	7.6485	4.0065	2.0033	4.0024
	64.6690	4.5037	7.6476	4.0065	2.0033	4.0024
	64.7690	4.5037	7.6466	4.0065	2.0033	4.0024
	64.8690	4.5037	7.6458	4.0065	2.0033	4.0024
	64.9690	4.5037	7.6449	4.0065	2.0033	4.0024
	65.0690	4.5037	7.6441	4.0065	2.0033	4.0024
	65.1690	4.5037	7.6434	4.0065	2.0033	4.0024
	65.2690	4.5037	7.6425	4.0065	2.0033	4.0024
	65.3690	4.5037	7.6418	4.0065	2.0033	4.0024
	65.4690	4.5037	7.6412	4.0065	2.0033	4.0024
	65.5690	4.5037	7.6401	4.0065	2.0033	4.0024
	65.6690	4.5037	7.6396	4.0065	2.0033	4.0024
	65.7690	4.5037	7.6383	4.0065	2.0033	4.0024
	65.8690	4.5037	7.6382	4.0065	2.0033	4.0024
	65.9690	4.5037	7.6378	4.0065	2.0033	4.0024
	66.0690	4.5037	7.6363	4.0065	2.0033	4.0024
	66.1690	4.5037	7.6356	4.0065	2.0033	4.0024
	66.2690	4.5037	7.6346	4.0065	2.0033	4.0024
	66.3690	4.5037	7.6334	4.0065	2.0033	4.0024
	66.4690	4.5037	7.6328	4.0065	2.0033	4.0024
	66.5690	4.5037	7.6323	4.0065	2.0033	4.0024
	66.6690	4.5037	7.6310	4.0065	2.0033	4.0024
	66.7690	4.5037	7.6300	4.0065	2.0033	4.0024
	66.8690	4.5037	7.6292	4.0065	2.0033	4.0024
	66.9690	4.5037	7.6275	4.0065	2.0033	4.0024
	67.0690	4.5037	7.6270	4.0065	2.0033	4.0024
	67.1690	4.5037	7.6263	4.0065	2.0033	4.0024
	67.2690	4.5037	7.6260	4.0065	2.0033	4.0024
	67.3690	4.5037	7.6252	4.0065	2.0033	4.0024
	67.4690	4.5037	7.6247	4.0065	2.0033	4.0024
	67.5690	4.5037	7.6240	4.0065	2.0033	4.0024
	67.6690	4.5037	7.6232	4.0065	2.0033	4.0024
	67.7690	4.5037	7.6227	4.0065	2.0033	4.0024
	67.8690	4.5037	7.6221	4.0065	2.0033	4.0024
	67.9690	4.5037	7.6213	4.0065	2.0033	4.0024
	68.0690	4.5037	7.6207	4.0065	2.0033	4.0024
	68.1690	4.5037	7.6201	4.0065	2.0033	4.0024
	68.2690	4.5037	7.6194	4.0065	2.0033	4.0024
	68.3690	4.5037	7.6188	4.0065	2.0033	4.0024
	68.4690	4.5037	7.6182	4.0065	2.0033	4.0024
	68.5690	4.5037	7.6178	4.0065	2.0033	4.0024
	68.6690	4.5037	7.6170	4.0065	2.0033	4.0024
	68.7690	4.5037	7.6162	4.0065	2.0033	4.0024
	68.8690	4.5037	7.6156	4.0065	2.0033	4.0024
	68.9690	4.5037	7.6151	4.0065	2.0033	4.0024
	69.0690	4.5037	7.6145	4.0065	2.0033	4.0024
	69.1690	4.5037	7.6139	4.0065	2.0033	4.0024
	69.2690	4.5037	7.6133	4.0065	2.0033	4.0024
	69.3690	4.5037	7.6128	4.0065	2.0033	4.0024
	69.4690	4.5037	7.6122	4.0065	2.0033	4.0024
	69.5690	4.5037	7.6116	4.0065	2.0033	4.0024
	69.6690	4.5037	7.6111	4.0065	2.0033	4.0024
	69.7690	4.5037	7.6105	4.0065	2.0033	4.0024
	69.8690	4.5037	7.6099	4.0065	2.0033	4.0024
	69.9690	4.5037	7.6092	4.0065	2.0033	4.0024
	70.0690	4.5037	7.6096	4.0065	2.0033	4.0024
	70.1690	4.5037	7.6091	4.0065	2.0033	4.0024
	70.2690	4.5037	7.6085	4.0065	2.0033	4.0024
	70.3690	4.5037	7.6063	4.0065	2.0033	4.0024
	70.4690	4.5037	7.6065	4.0065	2.0033	4.0024
	70.5690	4.5037	7.6046	4.0065	2.0033	4.0024
	70.6690	4.5037	7.6044	4.0065	2.0033	4.0024
	70.7690	4.5037	7.6052	4.0065	2.0033	4.0024
	70.8690	4.5037	7.6056	4.0065	2.0033	4.0024
	70.9690	4.5037	7.6050	4.0065	2.0033	4.0024
	71.0690	4.5037	7.6028	4.0065	2.0033	4.0024
	71.1690	4.5037	7.6012	4.0065	2.0033	4.0024
	71.2690	4.5037	7.6009	4.0065	2.0033	4.0024
	71.3690	4.5037	7.6003	4.0065	2.0033	4.0024
	71.4690	4.5037	7.6001	4.0065	2.0033	4.0024
	71.5690	4.5037	7.5989	4.0065	2.0033	4.0024
	71.6690	4.5037	7.5981	4.0065	2.0033	4.0024
	71.7690	4.5037	7.5994	4.0065	2.0033	4.0024
	71.8690	4.5037	7.5969	4.0065	2.0033	4.0024
	71.9690	4.5037	7.5975	4.0065	2.0033	4.0024
	72.0690	4.5037	7.5967	4.0065	2.0033	4.0024
	72.1690	4.5037	7.5964	4.0065	2.0033	4.0024
	72.2690	4.5037	7.5954	4.0065	2.0033	4.0024
	72.3690	4.5037	7.5957	4.0065	2.0033	4.0024
	72.4690	4.5037	7.5947	4.0065	2.0033	4.0024
	72.5690	4.5037	7.5945	4.0065	2.0033	4.0024
	72.6690	4.5037	7.5940	4.0065	2.0033	4.0024
	72.7690	4.5037	7.5932	4.0065	2.0033	4.0024
	72.8690	4.5037	7.5930	4.0065	2.0033	4.0024
	72.9690	4.5037	7.5924	4.0065	2.0033	4.0024
	73.0690	4.5037	7.5920	4.0065	2.0033	4.0024
	73.1690	4.5037	7.5913	4.0065	2.0033	4.0024
	73.2690	4.5037	7.5912	4.0065	2.0033	4.0024
	73.3280	4.5037	7.5911	4.0065	2.0033	4.0024
	73.4140	4.5169	7.6559	4.0214	2.0107	4.0024
	73.5140	4.5421	7.8970	4.0498	2.0249	4.0024
	73.6140	4.5667	8.0606	4.0776	2.0388	4.0024
	73.7140	4.5916	8.1380	4.1056	2.0528	4.0024
	73.8140	4.6165	8.1596	4.1337	2.0668	4.0024
	73.9140	4.6417	8.1612	4.1621	2.0810	4.0024
	74.0140	4.6666	8.1563	4.1901	2.0951	4.0024
	74.1140	4.6915	8.1506	4.2182	2.1091	4.0024
	74.2140	4.7166	8.1461	4.2465	2.1232	4.0024
	74.3140	4.7414	8.1409	4.2745	2.1372	4.0024
	74.4140	4.7665	8.1380	4.3027	2.1514	4.0024
	74.5140	4.7915	8.1355	4.3310	2.1655	4.0024
	74.6140	4.8165	8.1326	4.3591	2.1796	4.0024
	74.7140	4.8414	8.1312	4.3872	2.1936	4.0024
	74.8140	4.8664	8.1298	4.4155	2.2077	4.0024
	74.9140	4.8917	8.1295	4.4439	2.2219	4.0024
	75.0140	4.9166	8.1283	4.4720	2.2360	4.0024
	75.1140	4.9414	8.1275	4.4999	2.2500	4.0024
	75.2140	4.9665	8.1283	4.5283	2.2641	4.0024
	75.3140	4.9915	8.1272	4.5564	2.2782	4.0024
	75.4140	5.0165	8.1280	4.5846	2.2923	4.0024
	75.5140	5.0414	8.1289	4.6127	2.3064	4.0024
	75.6140	5.0663	8.1298	4.6408	2.3204	4.0024
	75.7140	5.0914	8.1306	4.6691	2.3345	4.0024
	75.8140	5.1164	8.1315	4.6973	2.3487	4.0024
	75.9140	5.1417	8.1332	4.7258	2.3629	4.0024
	76.0140	5.1665	8.1331	4.7538	2.3769	4.0024
	76.1140	5.1914	8.1343	4.7818	2.3909	4.0024
	76.2140	5.2166	8.1358	4.8102	2.4051	4.0024
	76.3140	5.2415	8.1359	4.8383	2.4191	4.0024
	76.4140	5.2663	8.1371	4.8662	2.4331	4.0024
	76.5140	5.2913	8.1393	4.8944	2.4472	4.0024
	76.6140	5.3165	8.1411	4.9229	2.4614	4.0024
	76.7140	5.3415	8.1418	4.9510	2.4755	4.0024
	76.8140	5.3664	8.1425	4.9791	2.4895	4.0024
	76.9140	5.3916	8.1448	5.0075	2.5037	4.0024
	77.0140	5.4165	8.1449	5.0355	2.5178	4.0024
	77.1140	5.4415	8.1466	5.0637	2.5319	4.0024
	77.2140	5.4665	8.1484	5.0920	2.5460	4.0024
	77.3140	5.4915	8.1495	5.1201	2.5600	4.0024
	77.4140	5.5164	8.1511	5.1482	2.5741	4.0024
	77.5140	5.5414	8.1518	5.1764	2.5882	4.0024
	77.6140	5.5666	8.1541	5.2049	2.6024	4.0024
	77.7140	5.5915	8.1546	5.2329	2.6165	4.0024
	77.8140	5.6164	8.1558	5.2609	2.6305	4.0024
	77.9140	5.6415	8.1577	5.2893	2.6446	4.0024
	78.0140	5.6665	8.1580	5.3174	2.6587	4.0024
	78.1140	5.6915	8.1597	5.3456	2.6728	4.0024
	78.2140	5.7165	8.1612	5.3738	2.6869	4.0024
	78.3140	5.7414	8.1627	5.4018	2.7009	4.0024
	78.4140	5.7664	8.1639	5.4301	2.7150	4.0024
	78.5140	5.7915	8.1651	5.4584	2.7292	4.0024
	78.6140	5.8167	8.1670	5.4867	2.7434	4.0024
	78.7140	5.8415	8.1673	5.5147	2.7574	4.0024
	78.8140	5.8664	8.1685	5.5428	2.7714	4.0024
	78.9140	5.8915	8.1701	5.5712	2.7856	4.0024
	79.0140	5.9165	8.1704	5.5992	2.7996	4.0024
	79.1140	5.9414	8.1719	5.6273	2.8137	4.0024
	79.2140	5.9664	8.1733	5.6555	2.8278	4.0024
	79.3140	5.9916	8.1750	5.6839	2.8420	4.0024
	79.4140	6.0165	8.1754	5.7120	2.8560	4.0024
	79.5140	6.0415	8.1765	5.7402	2.8701	4.0024
	79.6140	6.0665	8.1781	5.7684	2.8842	4.0024
	79.7140	6.0914	8.1782	5.7964	2.8982	4.0024
	79.8140	6.1164	8.1797	5.8247	2.9123	4.0024
	79.9140	6.1415	8.1812	5.8529	2.9265	4.0024
	80.0140	6.1665	8.1821	5.8811	2.9406	4.0024
	80.1140	6.1913	8.1828	5.9091	2.9546	4.0024
	80.2140	6.2165	8.1838	5.9375	2.9687	4.0024
	80.3140	6.2417	8.1855	5.9660	2.9830	4.0024
	80.4140	6.2665	8.1855	5.9939	2.9970	4.0024
	80.5140	6.2915	8.1866	6.0220	3.0110	4.0024
	80.6140	6.3165	8.1875	6.0502	3.0251	4.0024
	80.7140	6.3415	8.1879	6.0785	3.0392	4.0024
	80.8140	6.3665	8.1891	6.1066	3.0533	4.0024
	80.9140	6.3914	8.1901	6.1347	3.0674	4.0024
	81.0140	6.4164	8.1918	6.1629	3.0815	4.0024
	81.1140	6.4414	8.1919	6.1910	3.0955	4.0024
	81.2140	6.4665	8.1933	6.2193	3.1097	4.0024
	81.3140	6.4916	8.1946	6.2477	3.1238	4.0024
	81.4140	6.5165	8.1943	6.2757	3.1379	4.0024
	81.5140	6.5414	8.1952	6.3038	3.1519	4.0024
	81.6140	6.5665	8.1962	6.3321	3.1660	4.0024
	81.7140	6.5915	8.1968	6.3603	3.1802	4.0024
	81.8140	6.6165	8.1973	6.3885	3.1942	4.0024
	81.9140	6.6415	8.1980	6.4166	3.2083	4.0024
	82.0140	6.6666	8.1993	6.4449	3.2225	4.0024
	82.1140	6.6915	8.1994	6.4730	3.2365	4.0024
	82.2140	6.7165	8.2004	6.5012	3.2506	4.0024
	82.3140	6.7415	8.2012	6.5294	3.2647	4.0024
	82.4140	6.7663	8.2007	6.5574	3.2787	4.0024
	82.5140	6.7914	8.2023	6.5857	3.2928	4.0024
	82.6140	6.8164	8.2029	6.6139	3.3069	4.0024
	82.7140	6.8415	8.2037	6.6421	3.3211	4.0024
	82.8140	6.8664	8.2038	6.6702	3.3351	4.0024
	82.9140	6.8915	8.2047	6.6985	3.3493	4.0024
	83.0140	6.9167	8.2059	6.7269	3.3635	4.0024
	83.1140	6.9415	8.2053	6.7549	3.3774	4.0024
	83.2140	6.9664	8.2059	6.7830	3.3915	4.0024
	83.3140	6.9915	8.2065	6.8112	3.4056	4.0024
	83.4140	7.0165	8.2062	6.8394	3.4197	4.0024
	83.5140	7.0416	8.2074	6.8677	3.4338	4.0024
	83.6140	7.0664	8.2076	6.8957	3.4479	4.0024
	83.7140	7.0914	8.2089	6.9239	3.4619	4.0024
	83.8140	7.1164	8.2089	6.9521	3.4760	4.0024
	83.9140	7.1415	8.2094	6.9803	3.4901	4.0024
	84.0140	7.1667	8.2106	7.0087	3.5044	4.0024
	84.1140	7.1914	8.2096	7.0366	3.5183	4.0024
	84.2140	7.2164	8.2105	7.0648	3.5324	4.0024
	84.3140	7.2415	8.2109	7.0931	3.5466	4.0024
	84.4140	7.2665	8.2106	7.1212	3.5606	4.0024
	84.5140	7.2914	8.2109	7.1494	3.5747	4.0024
	84.6140	7.3163	8.2114	7.1774	3.5887	4.0024
	84.7140	7.3416	8.2126	7.2059	3.6029	4.0024
	84.8140	7.3665	8.2120	7.2340	3.6170	4.0024
	84.9140	7.3915	8.2122	7.2622	3.6311	4.0024
	85.0140	7.4166	8.2129	7.2905	3.6452	4.0024
	85.1140	7.4414	8.2121	7.3184	3.6592	4.0024
	85.2140	7.4665	8.2132	7.3468	3.6734	4.0024
	85.3140	7.4915	8.2130	7.3749	3.6875	4.0024
	85.4140	7.5163	8.2129	7.4029	3.7014	4.0024
	85.5140	7.5413	8.2139	7.4311	3.7155	4.0024
	85.6140	7.5664	8.2138	7.4593	3.7297	4.0024
	85.7140	7.5917	8.2147	7.4879	3.7439	4.0024
	85.8140	7.6165	8.2136	7.5159	3.7579	4.0024
	85.9140	7.6415	8.2138	7.5440	3.7720	4.0024
	86.0140	7.6666	8.2139	7.5723	3.7861	4.0024
	86.1140	7.6915	8.2130	7.6004	3.8002	4.0024
	86.2140	7.7165	8.2138	7.6286	3.8143	4.0024
	86.3140	7.7414	8.2138	7.6567	3.8284	4.0024
	86.4140	7.7664	8.2145	7.6849	3.8424	4.0024
	86.5140	7.7914	8.2139	7.7130	3.8565	4.0024
	86.6140	7.8164	8.2139	7.7412	3.8706	4.0024
	86.7140	7.8417	8.2149	7.7697	3.8849	4.0024
	86.8140	7.8665	8.2136	7.7977	3.8988	4.0024
	86.9140	7.8914	8.2138	7.8258	3.9129	4.0024
	87.0140	7.9165	8.2137	7.8541	3.9270	4.0024
	87.1140	7.9415	8.2131	7.8822	3.9411	4.0024
	87.2140	7.9665	8.2132	7.9105	3.9552	4.0024
	87.3140	7.9914	8.2128	7.9385	3.9693	4.0024
	87.4140	8.0166	8.2135	7.9670	3.9835	4.0024
	87.5140	8.0416	8.2125	7.9951	3.9975	4.0024
	87.6140	8.0664	8.2121	8.0231	4.0115	4.0024
	87.7140	8.0916	8.2129	8.0514	4.0257	4.0024
	87.8140	8.1164	8.2113	8.0794	4.0397	4.0024
	87.9140	8.1415	8.2115	8.1077	4.0539	4.0024
	88.0140	8.1665	8.2115	8.1359	4.0680	4.0024
	88.1140	8.1914	8.2110	8.1641	4.0820	4.0024
	88.2140	8.2164	8.2110	8.1922	4.0961	4.0024
	88.3140	8.2415	8.2103	8.2204	4.1102	4.0024
	88.4140	8.2667	8.2107	8.2489	4.1245	4.0024
	88.5140	8.2916	8.2094	8.2769	4.1385	4.0024
	88.6140	8.3164	8.2086	8.3049	4.1525	4.0024
	88.7140	8.3415	8.2087	8.3332	4.1666	4.0024
	88.8140	8.3664	8.2071	8.3613	4.1807	4.0024
	88.9140	8.3915	8.2072	8.3895	4.1948	4.0024
	89.0140	8.4164	8.2069	8.4177	4.2088	4.0024
	89.1140	8.4414	8.2066	8.4458	4.2229	4.0024
	89.2140	8.4664	8.2061	8.4740	4.2370	4.0024
	89.3140	8.4915	8.2053	8.5023	4.2512	4.0024
	89.4140	8.5167	8.2053	8.5307	4.2654	4.0024
	89.5140	8.5415	8.2036	8.5587	4.2794	4.0024
	89.6140	8.5664	8.2028	8.5867	4.2934	4.0024
	89.7140	8.5915	8.2026	8.6151	4.3075	4.0024
[...]
	46.1000	3.8391	7.9691	3.4064	1.7032	3.4064
	46.2000	3.8476	7.9719	3.4160	1.7080	3.4160
	46.3000	3.8559	7.9721	3.4255	1.7128	3.4255
	46.4000	3.8643	7.9728	3.4352	1.7176	3.4352
	46.5000	3.8726	7.9736	3.4448	1.7224	3.4448
	46.6000	3.8810	7.9753	3.4546	1.7273	3.4546
	46.7000	3.8893	7.9752	3.4640	1.7320	3.4640
	46.8000	3.8975	7.9758	3.4735	1.7367	3.4735
	46.9000	3.9060	7.9782	3.4832	1.7416	3.4832
	47.0000	3.9142	7.9779	3.4926	1.7463	3.4926
	47.1000	3.9226	7.9796	3.5024	1.7512	3.5024
	47.2000	3.9311	7.9803	3.5119	1.7559	3.5119
	47.3000	3.9392	7.9811	3.5215	1.7607	3.5215
	47.4000	3.9477	7.9837	3.5312	1.7656	3.5312
	47.5000	3.9561	7.9833	3.5407	1.7704	3.5407
	47.6000	3.9643	7.9834	3.5504	1.7752	3.5504
	47.7000	3.9727	7.9841	3.5598	1.7799	3.5598
	47.8000	3.9810	7.9861	3.5694	1.7847	3.5694
	47.9000	3.9893	7.9871	3.5789	1.7895	3.5789
	48.0000	3.9974	7.9869	3.5884	1.7942	3.5884
	48.1000	4.0059	7.9892	3.5981	1.7990	3.5981
	48.2000	4.0144	7.9893	3.6075	1.8038	3.6075
	48.3000	4.0226	7.9906	3.6172	1.8086	3.6172
	48.4000	4.0310	7.9925	3.6269	1.8134	3.6269
	48.5000	4.0393	7.9929	3.6365	1.8182	3.6365
	48.6000	4.0478	7.9944	3.6462	1.8231	3.6462
	48.7000	4.0559	7.9926	3.6555	1.8277	3.6555
	48.8000	4.0641	7.9942	3.6650	1.8325	3.6650
	48.9000	4.0726	7.9977	3.6748	1.8374	3.6748
	49.0000	4.0809	7.9971	3.6843	1.8422	3.6843
	49.1000	4.0893	7.9982	3.6938	1.8469	3.6938
	49.2000	4.0975	7.9984	3.7035	1.8517	3.7035
	49.3000	4.1060	8.0007	3.7132	1.8566	3.7132
	49.4000	4.1144	8.0014	3.7228	1.8614	3.7228
	49.5000	4.1227	8.0018	3.7325	1.8662	3.7325
	49.6000	4.1311	8.0035	3.7422	1.8711	3.7422
	49.7000	4.1391	8.0024	3.7516	1.8758	3.7516
	49.8000	4.1476	8.0043	3.7612	1.8806	3.7612
	49.9000	4.1561	8.0057	3.7708	1.8854	3.7708
	50.0000	4.1642	8.0056	3.7805	1.8902	3.7805
	50.1000	4.1726	8.0082	3.7901	1.8951	3.7901
	50.2000	4.1809	8.0075	3.7996	1.8998	3.7996
	50.3000	4.1891	8.0083	3.8092	1.9046	3.8092
	50.4000	4.1977	8.0102	3.8189	1.9095	3.8189
	50.5000	4.2061	8.0116	3.8287	1.9143	3.8287
	50.6000	4.2145	8.0129	3.8384	1.9192	3.8384
	50.7000	4.2224	8.0112	3.8478	1.9239	3.8478
	50.8000	4.2309	8.0128	3.8574	1.9287	3.8574
	50.9000	4.2394	8.0143	3.8670	1.9335	3.8670
	51.0000	4.2475	8.0146	3.8766	1.9383	3.8766
	51.1000	4.2558	8.0161	3.8862	1.9431	3.8862
	51.2000	4.2641	8.0167	3.8958	1.9479	3.8958
	51.3000	4.2727	8.0184	3.9054	1.9527	3.9054
	51.4000	4.2811	8.0179	3.9150	1.9575	3.9150
	51.5000	4.2892	8.0186	3.9246	1.9623	3.9246
	51.6000	4.2977	8.0216	3.9344	1.9672	3.9344
	51.7000	4.3060	8.0206	3.9438	1.9719	3.9438
	51.8000	4.3142	8.0207	3.9533	1.9766	3.9533
	51.9000	4.3225	8.0222	3.9629	1.9814	3.9629
	52.0000	4.3309	8.0242	3.9726	1.9863	3.9726
	52.1000	4.3394	8.0250	3.9822	1.9911	3.9822
	52.2000	4.3475	8.0243	3.9917	1.9958	3.9917
	52.3000	4.3559	8.0266	4.0014	2.0007	4.0014
	52.4000	4.3642	8.0268	4.0109	2.0055	4.0109
	52.5000	4.3727	8.0284	4.0206	2.0103	4.0206
	52.6000	4.3812	8.0294	4.0303	2.0151	4.0303
	52.7000	4.3892	8.0289	4.0399	2.0199	4.0399
	52.8000	4.3976	8.0308	4.0495	2.0247	4.0495
	52.9000	4.4059	8.0306	4.0589	2.0294	4.0589
	53.0000	4.4142	8.0315	4.0686	2.0343	4.0686
	53.1000	4.4226	8.0325	4.0781	2.0391	4.0781
	53.2000	4.4309	8.0341	4.0878	2.0439	4.0878
	53.3000	4.4392	8.0350	4.0974	2.0487	4.0974
	53.4000	4.4475	8.0353	4.1070	2.0535	4.1070
	53.5000	4.4560	8.0370	4.1168	2.0584	4.1168
	53.6000	4.4646	8.0376	4.1264	2.0632	4.1264
	53.7000	4.4727	8.0374	4.1361	2.0681	4.1361
	53.8000	4.4809	8.0381	4.1456	2.0728	4.1456
	53.9000	4.4891	8.0392	4.1552	2.0776	4.1552
	54.0000	4.4976	8.0410	4.1649	2.0825	4.1649
	54.0720	4.5078	8.0490	4.1766	2.0883	4.1678
	54.1720	4.5096	8.0212	4.1786	2.0893	4.1678
	54.2720	4.5091	7.9748	4.1781	2.0890	4.1678
	54.3720	4.5084	7.9423	4.1772	2.0886	4.1678
	54.4720	4.5077	7.9162	4.1765	2.0882	4.1678
	54.5720	4.5071	7.8949	4.1758	2.0879	4.1678
	54.6720	4.5066	7.8776	4.1752	2.0876	4.1678
	54.7720	4.5062	7.8630	4.1748	2.0874	4.1678
	54.8720	4.5059	7.8505	4.1745	2.0872	4.1678
	54.9720	4.5057	7.8398	4.1742	2.0871	4.1678
	55.0720	4.5056	7.8305	4.1741	2.0870	4.1678
	55.1720	4.5055	7.8222	4.1740	2.0870	4.1678
	55.2720	4.5054	7.8150	4.1739	2.0869	4.1678
	55.3720	4.5054	7.8084	4.1738	2.0869	4.1678
	55.4720	4.5054	7.8024	4.1738	2.0869	4.1678
	55.5720	4.5053	7.7968	4.1738	2.0869	4.1678
	55.6720	4.5053	7.7914	4.1738	2.0869	4.1678
	55.7720	4.5053	7.7865	4.1738	2.0869	4.1678
	55.8720	4.5053	7.7818	4.1737	2.0869	4.1678
	55.9720	4.5053	7.7772	4.1737	2.0869	4.1678
	56.0720	4.5053	7.7731	4.1737	2.0869	4.1678
	56.1720	4.5053	7.7690	4.1737	2.0869	4.1678
	56.2720	4.5053	7.7650	4.1737	2.0869	4.1678
	56.3720	4.5053	7.7614	4.1738	2.0869	4.1678
	56.4720	4.5053	7.7579	4.1738	2.0869	4.1678
	56.5720	4.5053	7.7544	4.1738	2.0869	4.1678
	56.6720	4.5053	7.7511	4.1738	2.0869	4.1678
	56.7720	4.5053	7.7478	4.1738	2.0869	4.1678
	56.8720	4.5053	7.7446	4.1738	2.0869	4.1678
	56.9720	4.5053	7.7417	4.1738	2.0869	4.1678
	57.0720	4.5053	7.7389	4.1738	2.0869	4.1678
	57.1720	4.5053	7.7362	4.1738	2.0869	4.1678
	57.2720	4.5053	7.7336	4.1738	2.0869	4.1678
	57.3720	4.5053	7.7302	4.1738	2.0869	4.1678
	57.4720	4.5053	7.7276	4.1738	2.0869	4.1678
	57.5720	4.5053	7.7250	4.1738	2.0869	4.1678
	57.6720	4.5053	7.7227	4.1738	2.0869	4.1678
	57.7720	4.5053	7.7213	4.1738	2.0869	4.1678
	57.8720	4.5053	7.7187	4.1738	2.0869	4.1678
	57.9720	4.5053	7.7164	4.1737	2.0869	4.1678
	58.0720	4.5053	7.7142	4.1738	2.0869	4.1678
	58.1720	4.5053	7.7121	4.1738	2.0869	4.1678
	58.2720	4.5053	7.7100	4.1738	2.0869	4.1678
	58.3720	4.5053	7.7078	4.1738	2.0869	4.1678
	58.4720	4.5053	7.7052	4.1738	2.0869	4.1678
	58.5720	4.5053	7.7033	4.1738	2.0869	4.1678
	58.6720	4.5053	7.7023	4.1738	2.0869	4.1678
	58.7720	4.5053	7.7025	4.1738	2.0869	4.1678
	58.8720	4.5053	7.6984	4.1738	2.0869	4.1678
	58.9720	4.5053	7.6979	4.1737	2.0869	4.1678
	59.0720	4.5053	7.6965	4.1737	2.0869	4.1678
	59.1720	4.5053	7.6941	4.1738	2.0869	4.1678
	59.2720	4.5053	7.6939	4.1738	2.0869	4.1678
	59.3720	4.5053	7.6915	4.1738	2.0869	4.1678
	59.4720	4.5053	7.6903	4.1738	2.0869	4.1678
	59.5720	4.5053	7.6886	4.1738	2.0869	4.1678
	59.6720	4.5053	7.6871	4.1738	2.0869	4.1678
	59.7720	4.5053	7.6850	4.1738	2.0869	4.1678
	59.8720	4.5053	7.6833	4.1738	2.0869	4.1678
	59.9720	4.5053	7.6817	4.1738	2.0869	4.1678
	60.0720	4.5053	7.6804	4.1738	2.0869	4.1678
	60.1720	4.5053	7.6787	4.1738	2.0869	4.1678
	60.2720	4.5053	7.6774	4.1738	2.0869	4.1678
	60.3720	4.5053	7.6759	4.1738	2.0869	4.1678
	60.4720	4.5053	7.6744	4.1738	2.0869	4.1678
	60.5720	4.5053	7.6732	4.1738	2.0869	4.1678
	60.6720	4.5053	7.6718	4.1738	2.0869	4.1678
	60.7720	4.5053	7.6705	4.1738	2.0869	4.1678
	60.8720	4.5053	7.6689	4.1738	2.0869	4.1678
	60.9720	4.5053	7.6677	4.1738	2.0869	4.1678
	61.0720	4.5053	7.6666	4.1738	2.0869	4.1678
	61.1720	4.5053	7.6658	4.1738	2.0869	4.1678
	61.2720	4.5053	7.6644	4.1738	2.0869	4.1678
	61.3720	4.5053	7.6624	4.1738	2.0869	4.1678
	61.4720	4.5053	7.6613	4.1738	2.0869	4.1678
	61.5720	4.5053	7.6601	4.1738	2.0869	4.1678
	61.6720	4.5053	7.6594	4.1738	2.0869	4.1678
	61.7720	4.5053	7.6578	4.1738	2.0869	4.1678
	61.8720	4.5053	7.6556	4.1738	2.0869	4.1678
	61.9720	4.5053	7.6545	4.1738	2.0869	4.1678
	62.0720	4.5053	7.6532	4.1738	2.0869	4.1678
	62.1720	4.5053	7.6520	4.1738	2.0869	4.1678
	62.2720	4.5053	7.6508	4.1738	2.0869	4.1678
	62.3720	4.5053	7.6496	4.1738	2.0869	4.1678
	62.4720	4.5053	7.6487	4.1738	2.0869	4.1678
	62.5720	4.5053	7.6476	4.1738	2.0869	4.1678
	62.6720	4.5053	7.6465	4.1738	2.0869	4.1678
	62.7720	4.5053	7.6455	4.1738	2.0869	4.1678
	62.8720	4.5053	7.6444	4.1738	2.0869	4.1678
	62.9720	4.5053	7.6435	4.1738	2.0869	4.1678
	63.0720	4.5053	7.6424	4.1738	2.0869	4.1678
	63.1720	4.5053	7.6414	4.1738	2.0869	4.1678
	63.2720	4.5053	7.6406	4.1738	2.0869	4.1678
	63.3720	4.5053	7.6395	4.1738	2.0869	4.1678
	63.4720	4.5053	7.6387	4.1738	2.0869	4.1678
	63.5720	4.5053	7.6376	4.1738	2.0869	4.1678
	63.6720	4.5053	7.6367	4.1738	2.0869	4.1678
	63.7720	4.5053	7.6357	4.1738	2.0869	4.1678
	63.8720	4.5053	7.6349	4.1738	2.0869	4.1678
	63.9720	4.5053	7.6340	4.1738	2.0869	4.1678
	64.0720	4.5053	7.6330	4.1738	2.0869	4.1678
	64.1720	4.5053	7.6321	4.1738	2.0869	4.1678
	64.2720	4.5053	7.6312	4.1738	2.0869	4.1678
	64.3720	4.5053	7.6303	4.1738	2.0869	4.1678
	64.4720	4.5053	7.6296	4.1738	2.0869	4.1678
	64.5720	4.5053	7.6287	4.1738	2.0869	4.1678
	64.6720	4.5053	7.6277	4.1738	2.0869	4.1678
	64.7720	4.5053	7.6270	4.1738	2.0869	4.1678
	64.8720	4.5053	7.6262	4.1738	2.0869	4.1678
	64.9720	4.5053	7.6254	4.1738	2.0869	4.1678
	65.0720	4.5053	7.6247	4.1738	2.0869	4.1678
	65.1720	4.5053	7.6250	4.1738	2.0869	4.1678
	65.2720	4.5053	7.6238	4.1738	2.0869	4.1678
	65.3720	4.5053	7.6225	4.1738	2.0869	4.1678
	65.4720	4.5053	7.6213	4.1738	2.0869	4.1678
	65.5720	4.5053	7.6197	4.1738	2.0869	4.1678
	65.6720	4.5053	7.6188	4.1738	2.0869	4.1678
	65.7720	4.5053	7.6180	4.1738	2.0869	4.1678
	65.8720	4.5053	7.6166	4.1738	2.0869	4.1678
	65.9720	4.5054	7.6173	4.1738	2.0869	4.1678
	66.0720	4.5053	7.6173	4.1737	2.0869	4.1678
	66.1720	4.5053	7.6167	4.1738	2.0869	4.1678
	66.2720	4.5053	7.6149	4.1738	2.0869	4.1678
	66.3720	4.5053	7.6125	4.1738	2.0869	4.1678
	66.4720	4.5053	7.6125	4.1738	2.0869	4.1678
	66.5720	4.5053	7.6115	4.1738	2.0869	4.1678
	66.6720	4.5053	7.6110	4.1738	2.0869	4.1678
	66.7720	4.5053	7.6101	4.1738	2.0869	4.1678
	66.8720	4.5053	7.6096	4.1738	2.0869	4.1678
	66.9720	4.5053	7.6086	4.1738	2.0869	4.1678
	67.0720	4.5053	7.6081	4.1738	2.0869	4.1678
	67.1720	4.5053	7.6075	4.1738	2.0869	4.1678
	67.2720	4.5053	7.6069	4.1738	2.0869	4.1678
	67.3720	4.5053	7.6061	4.1738	2.0869	4.1678
	67.4720	4.5053	7.6054	4.1738	2.0869	4.1678
	67.5720	4.5053	7.6049	4.1738	2.0869	4.1678
	67.6720	4.5053	7.6042	4.1738	2.0869	4.1678
	67.7720	4.5053	7.6035	4.1738	2.0869	4.1678
	67.8720	4.5053	7.6029	4.1738	2.0869	4.1678
	67.9720	4.5053	7.6022	4.1738	2.0869	4.1678
	68.0410	4.5053	7.6020	4.1738	2.0869	4.1678
	68.1100	4.5061	7.6017	4.1746	2.0873	4.1678
	68.2100	4.5281	7.7615	4.1995	2.0998	4.1678
	68.3100	4.5532	7.9716	4.2280	2.1140	4.1678
	68.4100	4.5778	8.0924	4.2560	2.1280	4.1678
	68.5100	4.6026	8.1388	4.2840	2.1420	4.1678
	68.6100	4.6276	8.1481	4.3124	2.1562	4.1678
	68.7100	4.6526	8.1456	4.3407	2.1704	4.1678
	68.8100	4.6776	8.1410	4.3691	2.1846	4.1678
	68.9100	4.7025	8.1366	4.3973	2.1987	4.1678
	69.0100	4.7276	8.1333	4.4258	2.2129	4.1678
	69.1100	4.7525	8.1291	4.4540	2.2270	4.1678
	69.2100	4.7775	8.1267	4.4824	2.2412	4.1678
	69.3100	4.8028	8.1246	4.5110	2.2555	4.1678
	69.4100	4.8275	8.1219	4.5391	2.2695	4.1678
	69.5100	4.8525	8.1214	4.5674	2.2837	4.1678
	69.6100	4.8775	8.1206	4.5957	2.2979	4.1678
	69.7100	4.9026	8.1203	4.6242	2.3121	4.1678
	69.8100	4.9275	8.1197	4.6524	2.3262	4.1678
	69.9100	4.9525	8.1201	4.6807	2.3404	4.1678
	70.0100	4.9777	8.1217	4.7094	2.3547	4.1678
	70.1100	5.0025	8.1205	4.7375	2.3687	4.1678
	70.2100	5.0275	8.1217	4.7658	2.3829	4.1678
	70.3100	5.0525	8.1230	4.7942	2.3971	4.1678
	70.4100	5.0774	8.1232	4.8224	2.4112	4.1678
	70.5100	5.1024	8.1245	4.8508	2.4254	4.1678
	70.6100	5.1275	8.1258	4.8792	2.4396	4.1678
	70.7100	5.1526	8.1277	4.9076	2.4538	4.1678
	70.8100	5.1775	8.1286	4.9359	2.4679	4.1678
	70.9100	5.2025	8.1301	4.9642	2.4821	4.1678
	71.0100	5.2278	8.1320	4.9930	2.4965	4.1678
	71.1100	5.2526	8.1317	5.0210	2.5105	4.1678
	71.2100	5.2774	8.1337	5.0491	2.5245	4.1678
	71.3100	5.3025	8.1358	5.0776	2.5388	4.1678
	71.4100	5.3274	8.1364	5.1058	2.5529	4.1678
	71.5100	5.3525	8.1379	5.1343	2.5671	4.1678
	71.6100	5.3774	8.1398	5.1625	2.5813	4.1678
	71.7100	5.4027	8.1425	5.1912	2.5956	4.1678
	71.8100	5.4275	8.1430	5.2193	2.6097	4.1678
	71.9100	5.4525	8.1446	5.2477	2.6238	4.1678
	72.0100	5.4777	8.1464	5.2763	2.6381	4.1678
	72.1100	5.5025	8.1470	5.3043	2.6522	4.1678
	72.2100	5.5275	8.1495	5.3327	2.6664	4.1678
	72.3100	5.5525	8.1506	5.3611	2.6805	4.1678
	72.4100	5.5776	8.1521	5.3895	2.6947	4.1678
	72.5100	5.6025	8.1534	5.4177	2.7088	4.1678
	72.6100	5.6275	8.1549	5.4460	2.7230	4.1678
	72.7100	5.6527	8.1575	5.4747	2.7373	4.1678
	72.8100	5.6775	8.1574	5.5028	2.7514	4.1678
	72.9100	5.7024	8.1592	5.5310	2.7655	4.1678
	73.0100	5.7276	8.1614	5.5595	2.7798	4.1678
	73.1100	5.7524	8.1620	5.5877	2.7939	4.1678
	73.2100	5.7775	8.1637	5.6161	2.8081	4.1678
	73.3100	5.8026	8.1652	5.6446	2.8223	4.1678
	73.4100	5.8276	8.1670	5.6729	2.8365	4.1678
	73.5100	5.8525	8.1681	5.7012	2.8506	4.1678
	73.6100	5.8774	8.1693	5.7295	2.8647	4.1678
	73.7100	5.9027	8.1714	5.7581	2.8791	4.1678
	73.8100	5.9275	8.1710	5.7862	2.8931	4.1678
	73.9100	5.9524	8.1733	5.8145	2.9072	4.1678
	74.0100	5.9776	8.1751	5.8430	2.9215	4.1678
	74.1100	6.0024	8.1751	5.8712	2.9356	4.1678
	74.2100	6.0275	8.1768	5.8996	2.9498	4.1678
	74.3100	6.0525	8.1782	5.9279	2.9639	4.1678
	74.4100	6.0776	8.1805	5.9564	2.9782	4.1678
	74.5100	6.1024	8.1807	5.9845	2.9923	4.1678
	74.6100	6.1274	8.1822	6.0128	3.0064	4.1678
	74.7100	6.1527	8.1841	6.0415	3.0208	4.1678
	74.8100	6.1775	8.1840	6.0697	3.0348	4.1678
	74.9100	6.2025	8.1857	6.0980	3.0490	4.1678
	75.0100	6.2275	8.1870	6.1264	3.0632	4.1678
	75.1100	6.2526	8.1878	6.1548	3.0774	4.1678
	75.2100	6.2775	8.1889	6.1830	3.0915	4.1678
	75.3100	6.3025	8.1901	6.2114	3.1057	4.1678
	75.4100	6.3277	8.1918	6.2400	3.1200	4.1678
	75.5100	6.3526	8.1917	6.2682	3.1341	4.1678
	75.6100	6.3775	8.1929	6.2964	3.1482	4.1678
	75.7100	6.4026	8.1947	6.3248	3.1624	4.1678
	75.8100	6.4275	8.1947	6.3531	3.1765	4.1678
	75.9100	6.4524	8.1961	6.3814	3.1907	4.1678
	76.0100	6.4775	8.1975	6.4098	3.2049	4.1678
	76.1100	6.5025	8.1989	6.4381	3.2191	4.1678
	76.2100	6.5275	8.1996	6.4665	3.2332	4.1678
	76.3100	6.5524	8.2002	6.4947	3.2474	4.1678
	76.4100	6.5778	8.2020	6.5235	3.2617	4.1678
	76.5100	6.6027	8.2015	6.5517	3.2759	4.1678
	76.6100	6.6275	8.2024	6.5798	3.2899	4.1678
	76.7100	6.6526	8.2039	6.6083	3.3042	4.1678
	76.8100	6.6775	8.2038	6.6366	3.3183	4.1678
	76.9100	6.7025	8.2050	6.6649	3.3325	4.1678
	77.0100	6.7274	8.2062	6.6932	3.3466	4.1678
	77.1100	6.7525	8.2080	6.7216	3.3608	4.1678
	77.2100	6.7774	8.2081	6.7498	3.3749	4.1678
	77.3100	6.8024	8.2089	6.7782	3.3891	4.1678
	77.4100	6.8277	8.2100	6.8069	3.4034	4.1678
	77.5100	6.8525	8.2098	6.8350	3.4175	4.1678
	77.6100	6.8775	8.2109	6.8633	3.4316	4.1678
	77.7100	6.9026	8.2119	6.8917	3.4459	4.1678
	77.8100	6.9276	8.2121	6.9201	3.4601	4.1678
	77.9100	6.9525	8.2125	6.9483	3.4742	4.1678
	78.0100	6.9775	8.2137	6.9767	3.4883	4.1678
	78.1100	7.0027	8.2151	7.0052	3.5026	4.1678
	78.2100	7.0276	8.2146	7.0335	3.5167	4.1678
	78.3100	7.0525	8.2152	7.0617	3.5309	4.1678
	78.4100	7.0776	8.2166	7.0902	3.5451	4.1678
	78.5100	7.1024	8.2162	7.1183	3.5592	4.1678
	78.6100	7.1274	8.2173	7.1466	3.5733	4.1678
	78.7100	7.1526	8.2182	7.1752	3.5876	4.1678
	78.8100	7.1776	8.2192	7.2035	3.6018	4.1678
	78.9100	7.2025	8.2191	7.2317	3.6159	4.1678
	79.0100	7.2275	8.2198	7.2601	3.6301	4.1678
	79.1100	7.2528	8.2208	7.2888	3.6444	4.1678
	79.2100	7.2776	8.2201	7.3170	3.6585	4.1678
	79.3100	7.3025	8.2206	7.3451	3.6726	4.1678
	79.4100	7.3275	8.2219	7.3736	3.6868	4.1678
	79.5100	7.3525	8.2214	7.4019	3.7009	4.1678
	79.6100	7.3775	8.2220	7.4302	3.7151	4.1678
	79.7100	7.4025	8.2229	7.4585	3.7293	4.1678
	79.8100	7.4276	8.2242	7.4870	3.7435	4.1678
	79.9100	7.4525	8.2239	7.5152	3.7576	4.1678
	80.0100	7.4775	8.2244	7.5436	3.7718	4.1678
	80.1100	7.5027	8.2252	7.5722	3.7861	4.1678
	80.2100	7.5274	8.2241	7.6002	3.8001	4.1678
	80.3100	7.5524	8.2254	7.6285	3.8143	4.1678
	80.4100	7.5775	8.2258	7.6569	3.8285	4.1678
	80.5100	7.6026	8.2260	7.6854	3.8427	4.1678
	80.6100	7.6274	8.2258	7.7136	3.8568	4.1678
	80.7100	7.6526	8.2267	7.7421	3.8710	4.1678
	80.8100	7.6777	8.2274	7.7706	3.8853	4.1678
	80.9100	7.7026	8.2264	7.7988	3.8994	4.1678
	81.0100	7.7275	8.2269	7.8270	3.9135	4.1678
	81.1100	7.7525	8.2278	7.8554	3.9277	4.1678
	81.2100	7.7775	8.2274	7.8837	3.9418	4.1678
	81.3100	7.8024	8.2275	7.9120	3.9560	4.1678
	81.4100	7.8275	8.2284	7.9404	3.9702	4.1678
	81.5100	7.8525	8.2290	7.9688	3.9844	4.1678
	81.6100	7.8775	8.2287	7.9970	3.9985	4.1678
	81.7100	7.9025	8.2289	8.0254	4.0127	4.1678
	81.8100	7.9277	8.2294	8.0540	4.0270	4.1678
	81.9100	7.9526	8.2281	8.0822	4.0411	4.1678
	82.0100	7.9775	8.2289	8.1105	4.0552	4.1678
	82.1100	8.0026	8.2291	8.1389	4.0694	4.1678
	82.2100	8.0275	8.2288	8.1672	4.0836	4.1678
	82.3100	8.0525	8.2286	8.1956	4.0978	4.1678
	82.4100	8.0775	8.2291	8.2238	4.1119	4.1678
	82.5100	8.1026	8.2302	8.2523	4.1262	4.1678
	82.6100	8.1274	8.2292	8.2805	4.1402	4.1678
	82.7100	8.1525	8.2295	8.3089	4.1544	4.1678
	82.8100	8.1776	8.2298	8.3374	4.1687	4.1678
	82.9100	8.2025	8.2291	8.3656	4.1828	4.1678
	83.0100	8.2275	8.2296	8.3939	4.1970	4.1678
	83.1100	8.2525	8.2293	8.4222	4.2111	4.1678
	83.2100	8.2776	8.2295	8.4507	4.2254	4.1678
	83.3100	8.3025	8.2289	8.4789	4.2395	4.1678
	83.4100	8.3275	8.2288	8.5073	4.2536	4.1678
	83.5100	8.3527	8.2297	8.5358	4.2679	4.1678
	83.6100	8.3775	8.2284	8.5640	4.2820	4.1678
	83.7100	8.4024	8.2285	8.5922	4.2961	4.1678
	83.8100	8.4275	8.2289	8.6207	4.3104	4.1678
	83.9100	8.4524	8.2277	8.6490	4.3245	4.1678
	84.0100	8.4774	8.2280	8.6772	4.3386	4.1678
	84.1100	8.5025	8.2284	8.7058	4.3529	4.1678
	84.2100	8.5276	8.2288	8.7341	4.3671	4.1678
	84.3100	8.5525	8.2278	8.7624	4.3812	4.1678
	84.4100	8.5774	8.2272	8.7906	4.3953	4.1678
	84.5100	8.6027	8.2281	8.8194	4.4097	4.1678
	84.6100	8.6276	8.2263	8.8475	4.4238	4.1678
	84.7100	8.6525	8.2266	8.8758	4.4379	4.1678
	84.8100	8.6776	8.2265	8.9042	4.4521	4.1678
	84.9100	8.7024	8.2252	8.9324	4.4662	4.1678
	85.0100	8.7275	8.2252	8.9608	4.4804	4.1678
	85.1100	8.7524	8.2250	8.9891	4.4945	4.1678
	85.2100	8.7776	8.2259	9.0176	4.5088	4.1678
	85.3100	8.8024	8.2244	9.0458	4.5229	4.1678
	85.4100	8.8275	8.2245	9.0742	4.5371	4.1678
	85.5100	8.8527	8.2244	9.1028	4.5514	4.1678
	85.6100	8.8775	8.2229	9.1309	4.5655	4.1678
	85.7100	8.9025	8.2232	9.1592	4.5796	4.1678
	85.8100	8.9275	8.2225	9.1876	4.5938	4.1678
	85.9100	8.9526	8.2218	9.2160	4.6080	4.1678
	86.0100	8.9774	8.2210	9.2442	4.6221	4.1678
	86.1100	9.0024	8.2206	9.2725	4.6363	4.1678
	86.2100	9.0277	8.2211	9.3011	4.6506	4.1678
	86.3100	9.0525	8.2190	9.3293	4.6647	4.1678
	86.4100	9.0775	8.2186	9.3577	4.6788	4.1678
	86.5100	9.1026	8.2183	9.3861	4.6930	4.1678
	86.6100	9.1274	8.2167	9.4142	4.7071	4.1678
	86.7100	9.1525	8.2166	9.4426	4.7213	4.1678
	86.8100	9.1776	8.2159	9.4711	4.7356	4.1678
	86.9100	9.2026	8.2156	9.4994	4.7497	4.1678
	87.0100	9.2275	8.2145	9.5277	4.7638	4.1678
	87.1100	9.2524	8.2134	9.5560	4.7780	4.1678
	87.2100	9.2778	8.2135	9.5847	4.7924	4.1678
	87.3100	9.3026	8.2106	9.6129	4.8064	4.1678
	87.4100	9.3275	8.2101	9.6411	4.8205	4.1678
	87.5100	9.3525	8.2094	9.6695	4.8347	4.1678
	87.6100	9.3775	8.2074	9.6978	4.8489	4.1678
	87.7100	9.4026	8.2065	9.7262	4.8631	4.1678
	87.8100	9.4275	8.2054	9.7545	4.8772	4.1678
	87.9100	9.4526	8.2050	9.7829	4.8915	4.1678
	88.0100	9.4775	8.2028	9.8111	4.9056	4.1678
	88.1100	9.5025	8.2014	9.8395	4.9198	4.1678
	88.2100	9.5277	8.2003	9.8681	4.9341	4.1678
	88.3100	9.5525	8.1973	9.8962	4.9481	4.1678
	88.4100	9.5774	8.1962	9.9245	4.9622	4.1678
	88.5100	9.6025	8.1944	9.9529	4.9765	4.1678
	88.6100	9.6276	8.1919	9.9813	4.9907	4.1678
	88.7100	9.6525	8.1897	10.0096	5.0048	4.1678
	88.8100	9.6775	8.1876	10.0380	5.0190	4.1678
	88.9100	9.7027	8.1859	10.0665	5.0333	4.1678
	89.0100	9.7276	8.1817	10.0947	5.0473	4.1678
	89.1100	9.7525	8.1790	10.1229	5.0614	4.1678
	89.2100	9.7774	8.1764	10.1512	5.0756	4.1678
	89.3100	9.8024	8.1726	10.1795	5.0897	4.1678
	89.4100	9.8274	8.1692	10.2079	5.1039	4.1678
	89.5100	9.8525	8.1657	10.2363	5.1182	4.1678
	89.6100	9.8775	8.1616	10.2647	5.1323	4.1678
	89.7100	9.9025	8.1569	10.2931	5.1465	4.1678
	89.8100	9.9275	8.1515	10.3214	5.1607	4.1678
	89.9100	9.9528	8.1466	10.3500	5.1750	4.1678
	90.0100	9.9776	8.1394	10.3782	5.1891	4.1678
	90.1100	10.0024	8.1339	10.4063	5.2031	4.1678
	90.2100	10.0276	8.1280	10.4348	5.2174	4.1678
	90.3100	10.0525	8.1193	10.4631	5.2315	4.1678
	90.4100	10.0775	8.1120	10.4914	5.2457	4.1678
	90.5100	10.1024	8.1034	10.5197	5.2598	4.1678
	90.6100	10.1276	8.0943	10.5482	5.2741	4.1678
	90.7100	10.1525	8.0823	10.5764	5.2882	4.1678
	90.8100	10.1775	8.0687	10.6048	5.3024	4.1678
	90.9100	10.2027	8.0543	10.6334	5.3167	4.1678
	91.0100	10.2276	8.0310	10.6616	5.3308	4.1678
	91.1100	10.2525	7.9773	10.6898	5.3449	4.1678
	91.1420	10.2656	4.6871	10.7047	5.3523	4.1678