File: P2_Plasticity/B_comp.csv
True Plastic Strain (-)	 True Stress (MPa)
0.0	275.625
0.002	284.99420415101500
0.004	294.04039068385200
0.006	302.7746961240880
0.008	311.2078730485750
0.01	319.35030332266300
0.012	327.2120108810410
0.014	334.80267406794500
0.016	342.1316375519190
0.018000000000000000	349.20792382978800
0.02	356.04024433402400
0.022	362.63701015716600
0.024	369.0063424064930
0.026000000000000000	375.1560822017130
0.028	381.0938003279570
0.03	386.826806555983
0.032	392.3621586410400
0.034	397.70667101148800
0.036000000000000000	402.86692315786600
0.038	407.84926773273100
0.04	412.6598383712440
0.042	417.3045572421270
0.044	421.78914233829400
0.046	426.1191145161260
0.048	430.29980429204600
0.05	434.3363584047890
0.052000000000000000	438.23374615141000
0.054	441.996765504864
0.056	445.63004902066100
0.058	449.1380695398880
0.06	452.5251456956050
0.062	455.79544722940500
0.064	458.9530001246700
0.066	462.00169156286200
0.068	464.9452747089250
0.07	467.7873733317110
0.07200000000000000	470.53148626510900
0.074	473.1809917153660
0.076	475.739151419913
0.078	478.2091146628010
0.08	480.59392215170500
0.082	482.8965097612620
0.084	485.11971214734600
0.08600000000000000	487.26626623674500
0.088	489.3388145965140
0.09	491.3399086871750
0.092	493.27201200375400
0.094	495.13750310852300
0.096	496.9386785591890
0.098	498.6777557361270
0.1	500.35687557213500
0.10200000000000000	501.9781051880850
0.10400000000000000	503.5434404377030
0.106	505.05480836460800
0.108	506.5140695746500
0.11	507.9230205264480
0.112	509.28339574297100
0.114	510.5968699468590
0.116	511.86506012213100
0.11800000000000000	513.0895275048150
0.12	514.2717795049420
0.122	515.4132715622810
0.124	516.5154089380920
0.126	517.5795484451090
0.128	518.607000117874
0.13	519.5990288254880
0.132	520.5568558287600
0.134	521.4816602836670
0.136	522.3745806929820
0.138	523.2367163078590
0.14	524.0691284810880
0.14200000000000000	524.872841973704
0.14400000000000000	525.6488462165370
0.146	526.3980965282820
0.148	527.1215152915590
0.15	527.8199930884440
0.152	528.4943897968330
0.154	529.1455356490190
0.156	529.7742322537690
0.158	530.3812535831650
0.16	530.9673469254190
0.162	531.5332338048410
0.164	532.0796108700890
0.166	532.6071507517930
0.168	533.1165028906190
0.17	533.6082943367700
0.17200000000000000	534.083130521939
0.17400000000000000	534.5415960046360
0.176	534.9842551898230
0.178	535.4116530237410
0.18	535.824315664776
0.182	536.2227511312000
0.184	536.6074499265810
0.186	536.9788856436260
0.188	537.3375155472110
0.19	537.6837811373080
0.192	538.0181086925010
0.194	538.3409097947710
0.196	538.6525818361820
0.198	538.9535085080990
0.2	539.2440602735410
0.202	539.5245948232500
0.20400000000000000	539.7954575160330
0.20600000000000000	540.0569818039240
0.20800000000000000	540.3094896426890
0.21	540.5532918881800
0.212	540.7886886790150
0.214	541.0159698060790
0.216	541.2354150692700
0.218	541.4472946219590
0.22	541.6518693035680
0.222	541.8493909606800
0.224	542.0401027570840
0.226	542.224239473124
0.228	542.4020277947360
0.23	542.5736865925090
0.232	542.7394271911380
0.234	542.8994536295730
0.23600000000000000	543.0539629122110
0.23800000000000000	543.2031452514230
0.24	543.3471843017170
0.242	543.4862573858300
0.244	543.6205357130290
0.246	543.7501845898790
0.248	543.87536362375
0.25	543.9962269193020
0.252	544.1129232682040
0.254	544.2255963323030
0.256	544.3343848204870
0.258	544.4394226594400
0.26	544.5408391585210
0.262	544.6387591689520
0.264	544.733303237517
0.266	544.8245877549670
0.268	544.9127250993030
0.27	544.997823774123
0.272	545.0799885421990
0.274	545.1593205544440
0.276	545.235917474442
0.278	545.3098735986730
0.28	545.3812799726040
0.28200000000000000	545.4502245027690
0.28400000000000000	545.5167920649910
0.28600000000000000	545.5810646088690
0.28800000000000000	545.6431212586640
0.29	545.703038410708
0.292	545.7608898274530
0.294	545.8167467282770
0.296	545.8706778771610
0.298	545.9227496673450
0.3	545.9730262030590
0.302	546.0215693784400
0.304	546.068438953733
0.306	546.1136926288570
0.308	546.1573861144370
0.31	546.1995732003890
0.312	546.2403058221410
0.314	546.2796341245670
0.316	546.3176065237200
0.318	546.3542697664350
0.32	546.3896689878790
0.322	546.4238477671160
0.324	546.4568481807540
0.326	546.4887108547460
0.328	546.5194750144030
0.33	546.5491785326860
0.332	546.577857976823
0.334	546.6055486533360
0.336	546.6322846514970
0.338	546.6580988853000
0.34	546.6830231339800
0.342	546.7070880811310
0.34400000000000000	546.730323352487
0.34600000000000000	546.7527575523870
0.34800000000000000	546.7744182989920
0.35000000000000000	546.7953322582860
0.352	546.8155251769010
0.354	546.8350219138170
0.356	546.8538464709590
0.358	546.8720220227520
0.36	546.8895709446460
0.362	546.9065148406640
0.364	546.922874569996
0.366	546.9386702726810
0.368	546.9539213943990
0.37	546.9686467104110
0.372	546.9828643486690
0.374	546.9965918121410
0.376	547.009846000351
0.378	547.0226432301850
0.38	547.0349992559820
0.382	547.0469292889240
0.384	547.0584480157650
0.386	547.0695696169120
0.388	547.0803077838780
0.39	547.0906757361430
0.392	547.1006862374230
0.394	547.1103516113880
0.396	547.1196837568280
0.398	547.1286941623050
0.4	547.1373939202970
0.402	547.1457937408480
0.404	547.1539039647610
0.406	547.1617345763220
0.40800000000000000	547.1692952155940
0.41000000000000000	547.1765951902830
0.41200000000000000	547.1836434871980
0.41400000000000000	547.1904487833160
0.41600000000000000	547.1970194564600
0.418	547.2033635956150
0.42	547.2094890108870
0.422	547.2154032431140
0.424	547.2211135731560
0.426	547.2266270308500
0.428	547.2319504036730
0.43	547.2370902450900
0.432	547.2420528826260
0.434	547.2468444256560
0.436	547.2514707729240
0.438	547.255937619807
0.44	547.2602504653240
0.442	547.2644146189060
0.444	547.2684352069350
0.446	547.2723171790540
0.448	547.2760653142570
0.45	547.2796842267750
0.452	547.2831783717600
0.454	547.286552050761
0.456	547.2898094170280
0.458	547.2929544806190
0.46	547.2959911133410
0.462	547.2989230535130
0.464	547.3017539105710
0.466	547.3044871695100
0.468	547.3071261951740
0.47000000000000000	547.3096742363990
0.47200000000000000	547.3121344300130
0.47400000000000000	547.3145098046950
0.47600000000000000	547.3168032847080
0.47800000000000000	547.3190176934960
0.48	547.3211557571600
0.482	547.3232201078150
0.484	547.3252132868290
0.486	547.3271377479540
0.488	547.3289958603430
0.49	547.3307899114700
0.492	547.3325221099450
0.494	547.3341945882340
0.496	547.3358094052790
0.498	547.3373685490420
0.5	547.3388739389430
0.502	547.340327428228
0.504	547.3417308062510
0.506	547.3430858006740
0.508	547.3443940795960
0.51	547.345657253604
0.512	547.3468768777600
0.514	547.3480544535100
0.516	547.3491914305390
0.518	547.3502892085490
0.52	547.3513491389860
0.522	547.3523725267020
0.524	547.3533606315650
0.526	547.3543146700040
0.528	547.3552358165110
0.53	547.3561252050850
0.532	547.356983930631
0.534	547.3578130503020
0.536	547.3586135848070
0.538	547.3593865196630
0.54	547.3601328064090
0.542	547.3608533637800
0.544	547.3615490788360
0.546	547.3622208080520
0.548	547.362869378379
0.55	547.3634955882530
0.552	547.3641002085860
0.554	547.3646839837100
0.556	547.3652476322940
0.558	547.3657918482340
0.56	547.3663173014980
0.562	547.366824638958
0.5640000000000000	547.3673144851850
0.5660000000000000	547.3677874432150
0.5680000000000000	547.368244095295
0.5700000000000000	547.3686850035970
0.5720000000000000	547.3691107109130
0.5740000000000000	547.3695217413190
0.5760000000000000	547.3699186008240
0.578	547.3703017779910
0.58	547.3706717445410
0.582	547.3710289559290
0.584	547.3713738519090
0.586	547.3717068570730
0.588	547.3720283813760
0.59	547.3723388206380
0.592	547.3726385570320
0.594	547.3729279595570
0.596	547.3732073844870
0.598	547.3734771758170
0.6	547.3737376656780
0.602	547.3739891747540
0.604	547.3742320126700
0.606	547.3744664783790
0.608	547.3746928605240
0.61	547.3749114377990
0.612	547.3751224792880
0.614	547.3753262448000
0.616	547.3755229851850
0.618	547.3757129426450
0.62	547.3758963510320
0.622	547.3760734361340
0.624	547.3762444159570
0.626	547.3764095009890
0.628	547.3765688944630
0.63	547.3767227926040
0.632	547.376871384871
0.634	547.3770148541930
0.636	547.3771533771910
0.638	547.3772871243970
0.64	547.377416260464
0.642	547.3775409443680
0.644	547.3776613296040
0.646	547.377777564375
0.648	547.3778897917750
0.65	547.3779981499640
0.652	547.3781027723390
0.654	547.3782037876980
0.656	547.3783013203980
0.658	547.3783954905090
0.66	547.3784864139620
0.662	547.3785742026900
0.664	547.378658964768
0.666	547.3787408045440
0.668	547.378819822768
0.67	547.3788961167190
0.672	547.3789697803190
0.674	547.3790409042540
0.676	547.3791095760820
0.678	547.379175880345
0.68	547.3792398986670
0.682	547.3793017098590
0.684	547.3793613900170
0.686	547.3794190126090
0.6880000000000000	547.3794746485750
0.6900000000000000	547.3795283664060
0.6920000000000000	547.379580232233
0.6940000000000000	547.3796303099060
0.6960000000000000	547.3796786610750
0.6980000000000000	547.3797253452640
0.7000000000000000	547.3797704199440
0.7020000000000000	547.3798139406050
0.704	547.3798559608250
0.706	547.3798965323340
0.708	547.3799357050790
0.71	547.3799735272830
0.712	547.3800100455090
0.714	547.3800453047130
0.716	547.3800793483020
0.718	547.3801122181870
0.72	547.380143954832
0.722	547.3801745973080
0.724	547.3802041833380
0.726	547.3802327493440
0.728	547.3802603304930
0.73	547.3802869607410
0.732	547.3803126728690
0.734	547.3803374985330
0.736	547.3803614682950
0.738	547.3803846116620
0.74	547.3804069571260
0.742	547.3804285321960
0.744	547.380449363433
0.746	547.380469476481
0.748	547.380488896101
0.75	547.3805076462
0.752	547.3805257498610
0.754	547.38054322937
0.756	547.3805601062470
0.758	547.380576401267
0.76	547.380592134492
0.762	547.3806073252900
0.764	547.3806219923620
0.766	547.3806361537640
0.768	547.38064982693
0.77	547.3806630286930
0.772	547.3806757753050
0.774	547.3806880824580
0.776	547.3806999653030
0.778	547.3807114384690
0.78	547.3807225160800
0.782	547.3807332117740
0.784	547.3807435387170
0.786	547.3807535096230
0.788	547.3807631367670
0.79	547.380772432
0.792	547.3807814067660
0.794	547.3807900721130
0.796	547.3807984387090
0.798	547.3808065168540
0.8	547.3808143164930
0.802	547.3808218472270
0.804	547.3808291183270
0.806	547.3808361387460
0.808	547.3808429171240
0.81	547.3808494618080
0.812	547.3808557808540
0.8140000000000000	547.3808618820410
0.8160000000000000	547.3808677728800
0.8180000000000000	547.3808734606230
0.8200000000000000	547.3808789522730
0.8220000000000000	547.3808842545900
0.8240000000000000	547.3808893741020
0.8260000000000000	547.38089431711
0.8280000000000000	547.3808990897010
0.8300000000000000	547.3809036977490
0.8320000000000000	547.3809081469280
0.834	547.3809124427150
0.836	547.3809165903970
0.838	547.3809205950820
0.84	547.3809244617000
0.842	547.3809281950100
0.844	547.3809317996080
0.846	547.3809352799320
0.848	547.3809386402670
0.85	547.3809418847490
0.852	547.380945017373
0.854	547.3809480419950
0.856	547.380950962338
0.858	547.380953781998
0.86	547.380956504446
0.862	547.3809591330330
0.864	547.3809616709960
0.866	547.3809641214590
0.868	547.3809664874380
0.87	547.3809687718460
0.872	547.3809709774960
0.874	547.380973107103
0.876	547.3809751632880
0.878	547.3809771485840
0.88	547.3809790654330
0.882	547.3809809161960
0.884	547.3809827031510
0.886	547.3809844284980
0.888	547.3809860943610
0.89	547.3809877027900
0.892	547.3809892557670
0.894	547.3809907552030
0.896	547.3809922029430
0.898	547.3809936007700
0.9	547.380994950405
0.902	547.3809962535090
0.904	547.3809975116870
0.906	547.380998726487
0.908	547.380999899405
0.91	547.3810010318850
0.912	547.3810021253210
0.914	547.3810031810590
0.916	547.3810042003990
0.918	547.3810051845950
0.92	547.38100613486
0.922	547.381007052363
0.924	547.3810079382340
0.926	547.3810087935630
0.928	547.3810096194030
0.93	547.381010416771
0.932	547.3810111866490
0.934	547.3810119299840
0.936	547.3810126476910
0.9380000000000000	547.381013340654
0.9400000000000000	547.3810140097260
0.9420000000000000	547.3810146557310
0.9440000000000000	547.3810152794640
0.9460000000000000	547.3810158816930
0.9480000000000000	547.3810164631590
0.9500000000000000	547.3810170245780
0.9520000000000000	547.3810175666420
0.9540000000000000	547.3810180900170
0.9560000000000000	547.3810185953470
0.9580000000000000	547.381019083256
0.96	547.3810195543430
0.962	547.3810200091890
0.964	547.3810204483540
0.966	547.381020872377
0.968	547.3810212817820
0.97	547.3810216770710
0.972	547.3810220587330
0.974	547.3810224272360
0.976	547.3810227830350
0.978	547.3810231265660
0.98	547.3810234582550
0.982	547.3810237785070
0.984	547.3810240877180
0.986	547.3810243862690
0.988	547.381024674527
0.99	547.3810249528470
0.992	547.3810252215710
0.994	547.3810254810300
0.996	547.3810257315450
0.998	547.3810259734220
1.0	547.3810262069600
1.002	547.3810264324470
1.004	547.3810266501600
1.006	547.3810268603670
1.008	547.3810270633260
1.01	547.3810272592880
1.012	547.3810274484950
1.014	547.3810276311770
1.016	547.3810278075620
1.018	547.3810279778660
1.02	547.3810281422980
1.022	547.3810283010610
1.024	547.3810284543500
1.026	547.3810286023550
1.028	547.3810287452560
1.03	547.3810288832320
1.032	547.3810290164500
1.034	547.381029145075
1.036	547.3810292692660
1.038	547.3810293891750
1.04	547.3810295049500
1.042	547.3810296167330
1.044	547.3810297246630
1.046	547.3810298288710
1.048	547.3810299294870
1.05	547.3810300266340
1.052	547.3810301204320
1.054	547.3810302109960
1.056	547.381030298437
1.058	547.3810303828640
1.06	547.38103046438
1.062	547.3810305430860
1.064	547.3810306190780
1.066	547.38103069245
1.068	547.3810307632930
1.07	547.3810308316930
1.072	547.381030897735
1.074	547.3810309615000
1.076	547.3810310230670
1.078	547.3810310825110
1.08	547.3810311399060
1.082	547.3810311953210
1.084	547.3810312488270
1.086	547.3810313004870
1.088	547.381031350367
1.09	547.3810313985270
1.092	547.3810314450270
1.094	547.3810314899230
1.096	547.3810315332710
1.098	547.3810315751260
1.1	547.3810316155370
1.102	547.3810316545540
1.104	547.3810316922270
1.106	547.3810317286010
1.108	547.3810317637200
1.11	547.3810317976290
1.112	547.3810318303690
1.114	547.3810318619800
1.116	547.3810318925020
1.118	547.3810319219710
1.12	547.3810319504240
1.122	547.3810319778960
1.124	547.3810320044210
1.1260000000000000	547.3810320300310
1.1280000000000000	547.3810320547580
1.1300000000000000	547.3810320786330
1.1320000000000000	547.3810321016850
1.1340000000000000	547.3810321239420
1.1360000000000000	547.3810321454320
1.1380000000000000	547.3810321661810
1.1400000000000000	547.3810321862140
1.1420000000000000	547.3810322055570
1.1440000000000000	547.3810322242330
1.1460000000000000	547.3810322422650
1.1480000000000000	547.3810322596760
1.1500000000000000	547.3810322764860
1.1520000000000000	547.3810322927160
1.154	547.3810323083870
1.156	547.381032323518
1.158	547.3810323381270
1.16	547.3810323522320
1.162	547.3810323658520
1.164	547.381032379001
1.166	547.3810323916970
1.168	547.3810324039560
1.17	547.3810324157920
1.172	547.3810324272190
1.174	547.3810324382530
1.176	547.3810324489070
1.178	547.3810324591930
1.18	547.3810324691240
1.182	547.3810324787130
1.184	547.3810324879720
1.186	547.3810324969110
1.188	547.381032505542
1.19	547.3810325138750
1.192	547.3810325219220
1.194	547.3810325296900
1.196	547.3810325371920
1.198	547.3810325444340
1.2	547.3810325514260
1.202	547.3810325581780
1.204	547.3810325646970
1.206	547.3810325709910
1.208	547.3810325770680
1.21	547.3810325829350
1.212	547.3810325886010
1.214	547.3810325940710
1.216	547.3810325993520
1.218	547.3810326044510
1.22	547.3810326093750
1.222	547.3810326141280
1.224	547.3810326187180
1.226	547.3810326231500
1.228	547.3810326274290
1.23	547.3810326315600
1.232	547.3810326355490
1.234	547.3810326394
1.236	547.3810326431190
1.238	547.381032646709
1.24	547.3810326501760
1.242	547.3810326535220
1.244	547.3810326567540
1.246	547.3810326598740
1.248	547.381032662887
1.25	547.3810326657960
1.252	547.3810326686040
1.254	547.381032671316
1.256	547.3810326739340
1.258	547.3810326764620
1.26	547.3810326789030
1.262	547.3810326812600
1.264	547.3810326835350
1.266	547.3810326857320
1.268	547.3810326878530
1.27	547.3810326899010
1.272	547.3810326918780
1.274	547.3810326937880
1.276	547.3810326956310
1.278	547.381032697411
1.28	547.3810326991300
1.282	547.3810327007890
1.284	547.3810327023910
1.286	547.3810327039380
1.288	547.3810327054310
1.29	547.3810327068730
1.292	547.3810327082660
1.294	547.3810327096100
1.296	547.3810327109080
1.298	547.381032712161
1.3	547.381032713371
1.302	547.3810327145390
1.304	547.3810327156670
1.306	547.3810327167560
1.308	547.381032717808
1.31	547.3810327188230
1.312	547.3810327198040
1.314	547.3810327207500
1.316	547.381032721664
1.318	547.3810327225460
1.32	547.3810327233980
1.322	547.3810327242210
1.324	547.3810327250150
1.326	547.3810327257820
1.328	547.3810327265220
1.33	547.3810327272370
1.332	547.3810327279270
1.334	547.3810327285940
1.336	547.3810327292370
1.338	547.3810327298590
1.34	547.3810327304580
1.342	547.3810327310380
1.344	547.3810327315970
1.346	547.3810327321370
1.348	547.381032732658
1.35	547.3810327331610
1.352	547.3810327336470
1.354	547.3810327341170
1.356	547.3810327345700
1.358	547.381032735007
1.36	547.3810327354290
1.362	547.3810327358370
1.364	547.3810327362310
1.366	547.3810327366110
1.368	547.3810327369780
1.37	547.3810327373320
1.372	547.3810327376750
1.374	547.3810327380050
1.3760000000000000	547.3810327383240
1.3780000000000000	547.3810327386320
1.3800000000000000	547.3810327389290
1.3820000000000000	547.3810327392160
1.3840000000000000	547.3810327394940
1.3860000000000000	547.3810327397610
1.3880000000000000	547.3810327400200
1.3900000000000000	547.3810327402690
1.3920000000000000	547.3810327405100
1.3940000000000000	547.3810327407430
1.3960000000000000	547.3810327409670
1.3980000000000000	547.3810327411840
1.4000000000000000	547.3810327413940
1.4020000000000000	547.3810327415960
1.4040000000000000	547.3810327417910
1.4060000000000000	547.3810327419790
1.408	547.3810327421610
1.41	547.3810327423370
1.412	547.3810327425070
1.414	547.3810327426700
1.416	547.3810327428290
1.418	547.3810327429810
1.42	547.3810327431290
1.422	547.3810327432710
1.424	547.3810327434090
1.426	547.3810327435410
1.428	547.3810327436690
1.43	547.381032743793
1.432	547.3810327439120
1.434	547.3810327440280
1.436	547.381032744139
1.438	547.3810327442470
1.44	547.3810327443500
1.442	547.3810327444510
1.444	547.3810327445470
1.446	547.3810327446410
1.448	547.381032744731
1.45	547.3810327448180
1.452	547.3810327449020
1.454	547.3810327449830
1.456	547.3810327450620
1.458	547.3810327451370
1.46	547.3810327452110
1.462	547.3810327452810
1.464	547.3810327453490
1.466	547.381032745415
1.468	547.3810327454790
1.47	547.3810327455400
1.472	547.381032745599
1.474	547.3810327456560
1.476	547.3810327457110
1.478	547.3810327457650
1.48	547.3810327458160
1.482	547.3810327458660
1.484	547.3810327459140
1.486	547.3810327459600
1.488	547.3810327460050
1.49	547.381032746048
1.492	547.3810327460900
1.494	547.3810327461300
1.496	547.3810327461690
1.498	547.3810327462060
1.5	547.3810327462430
1.502	547.3810327462780
1.504	547.3810327463110
1.506	547.3810327463440
1.508	547.3810327463760
1.51	547.3810327464060
1.512	547.3810327464350
1.514	547.3810327464640
1.516	547.381032746491
1.518	547.3810327465170
1.52	547.3810327465430
1.522	547.3810327465670
1.524	547.3810327465910
1.526	547.3810327466140
1.528	547.3810327466360
1.53	547.3810327466580
1.532	547.3810327466780
1.534	547.3810327466980
1.536	547.3810327467180
1.538	547.3810327467360
1.54	547.3810327467540
1.542	547.3810327467720
1.544	547.3810327467880
1.546	547.3810327468050
1.548	547.3810327468200
1.55	547.3810327468350
1.552	547.3810327468500
1.554	547.3810327468640
1.556	547.3810327468770
1.558	547.3810327468910
1.56	547.3810327469030
1.562	547.3810327469150
1.564	547.3810327469270
1.566	547.3810327469380
1.568	547.3810327469500
1.57	547.38103274696
1.572	547.3810327469700
1.574	547.3810327469800
1.576	547.3810327469900
1.578	547.3810327469990
1.58	547.3810327470080
1.582	547.3810327470160
1.584	547.3810327470250
1.586	547.3810327470330
1.588	547.3810327470410
1.59	547.381032747048
1.592	547.3810327470550
1.594	547.3810327470620
1.596	547.381032747069
1.598	547.3810327470750
1.6	547.3810327470820
1.602	547.3810327470880
1.604	547.3810327470940
1.606	547.3810327470990
1.608	547.3810327471050
1.61	547.3810327471100
1.612	547.3810327471150
1.614	547.3810327471200
1.616	547.3810327471250
1.618	547.3810327471290
1.62	547.3810327471340
1.622	547.3810327471380
1.624	547.381032747142
1.6260000000000000	547.381032747146
1.6280000000000000	547.3810327471500
1.6300000000000000	547.3810327471540
1.6320000000000000	547.3810327471570
1.6340000000000000	547.3810327471610
1.6360000000000000	547.3810327471640
1.6380000000000000	547.3810327471670
1.6400000000000000	547.3810327471700
1.6420000000000000	547.3810327471730
1.6440000000000000	547.381032747176
1.6460000000000000	547.3810327471790
1.6480000000000000	547.3810327471820
1.6500000000000000	547.3810327471840
1.6520000000000000	547.3810327471870
1.6540000000000000	547.3810327471890
1.6560000000000000	547.3810327471920
1.6580000000000000	547.3810327471940
1.6600000000000000	547.381032747196
1.6620000000000000	547.3810327471980
1.6640000000000000	547.3810327472000
1.666	547.3810327472020
1.668	547.381032747204
1.67	547.3810327472060
1.672	547.3810327472080
1.674	547.3810327472090
1.676	547.381032747211
1.678	547.3810327472130
1.68	547.381032747214
1.682	547.3810327472160
1.684	547.381032747217
1.686	547.3810327472180
1.688	547.3810327472200
1.69	547.3810327472210
1.692	547.3810327472220
1.694	547.3810327472240
1.696	547.3810327472250
1.698	547.3810327472260
1.7	547.3810327472270
1.702	547.3810327472280
1.704	547.3810327472290
1.706	547.3810327472300
1.708	547.3810327472310
1.71	547.3810327472320
1.712	547.3810327472330
1.714	547.3810327472340
1.716	547.3810327472340
1.718	547.381032747235
1.72	547.3810327472360
1.722	547.3810327472370
1.724	547.3810327472370
1.726	547.3810327472380
1.728	547.3810327472390
1.73	547.3810327472390
1.732	547.3810327472400
1.734	547.3810327472400
1.736	547.3810327472410
1.738	547.3810327472420
1.74	547.3810327472420
1.742	547.3810327472430
1.744	547.3810327472430
1.746	547.3810327472440
1.748	547.3810327472440
1.75	547.3810327472450
1.752	547.3810327472450
1.754	547.3810327472450
1.756	547.3810327472460
1.758	547.3810327472460
1.76	547.3810327472470
1.762	547.381032747247
1.764	547.3810327472470
1.766	547.3810327472480
1.768	547.381032747248
1.77	547.3810327472480
1.772	547.3810327472490
1.774	547.3810327472490
1.776	547.3810327472490
1.778	547.3810327472500
1.78	547.3810327472500
1.782	547.38103274725
1.784	547.3810327472500
1.786	547.3810327472510
1.788	547.3810327472510
1.79	547.381032747251
1.792	547.3810327472510
1.794	547.3810327472510
1.796	547.3810327472520
1.798	547.3810327472520
1.8	547.381032747252
1.802	547.3810327472520
1.804	547.3810327472520
1.806	547.3810327472520
1.808	547.3810327472530
1.81	547.3810327472530
1.812	547.3810327472530
1.814	547.3810327472530
1.816	547.3810327472530
1.818	547.3810327472530
1.82	547.3810327472540
1.822	547.3810327472540
1.824	547.3810327472540
1.826	547.3810327472540
1.828	547.381032747254
1.83	547.381032747254
1.832	547.3810327472540
1.834	547.3810327472540
1.836	547.3810327472550
1.838	547.3810327472550
1.84	547.3810327472550
1.842	547.3810327472550
1.844	547.3810327472550
1.846	547.381032747255
1.848	547.381032747255
1.85	547.3810327472550
1.852	547.3810327472550
1.854	547.3810327472550
1.856	547.3810327472550
1.858	547.3810327472550
1.86	547.3810327472550
1.862	547.3810327472550
1.864	547.3810327472560
1.866	547.3810327472560
1.868	547.3810327472560
1.87	547.3810327472560
1.872	547.3810327472560
1.874	547.3810327472560
1.8760000000000000	547.3810327472560
1.8780000000000000	547.3810327472560
1.8800000000000000	547.3810327472560
1.8820000000000000	547.381032747256
1.8840000000000000	547.3810327472560
1.8860000000000000	547.3810327472560
1.8880000000000000	547.3810327472560
1.8900000000000000	547.3810327472560
1.8920000000000000	547.3810327472560
1.8940000000000000	547.3810327472560
1.8960000000000000	547.3810327472560
1.8980000000000000	547.3810327472560
1.9000000000000000	547.3810327472560
1.9020000000000000	547.3810327472560
1.9040000000000000	547.3810327472560
1.9060000000000000	547.3810327472560
1.9080000000000000	547.3810327472560
1.9100000000000000	547.3810327472570
1.9120000000000000	547.3810327472570
1.9140000000000000	547.3810327472570
1.9160000000000000	547.3810327472570
1.9180000000000000	547.3810327472570
1.92	547.3810327472570
1.922	547.3810327472570
1.924	547.3810327472570
1.926	547.3810327472570
1.928	547.3810327472570
1.93	547.3810327472570
1.932	547.3810327472570
1.934	547.3810327472570
1.936	547.3810327472570
1.938	547.3810327472570
1.94	547.3810327472570
1.942	547.3810327472570
1.944	547.3810327472570
1.946	547.3810327472570
1.948	547.3810327472570
1.95	547.3810327472570
1.952	547.3810327472570
1.954	547.3810327472570
1.956	547.3810327472570
1.958	547.3810327472570
1.96	547.3810327472570
1.962	547.381032747257
1.964	547.381032747257
1.966	547.381032747257
1.968	547.381032747257
1.97	547.381032747257
1.972	547.381032747257
1.974	547.381032747257
1.976	547.381032747257
1.978	547.381032747257
1.98	547.381032747257
1.982	547.381032747257
1.984	547.381032747257
1.986	547.381032747257
1.988	547.381032747257
1.99	547.381032747257
1.992	547.381032747257
1.994	547.381032747257
1.996	547.381032747257
1.998	547.381032747257
2.0	547.381032747257