File: P2_Plasticity/Brass.csv
Tensile strain (Strain 1) : Primary source		Strain 1

Results Table 1
	Tensile strain (Strain 1) gauge length	Strain 1 gauge length	Time at removal
	(mm)	(mm)	(s)
1	50.00	50.00	54.05
2	50.00	50.00	54.07
3	50.00	50.00	54.05

Results Table 2



1	Time	Displacement	Force	Tensile strain (Strain 1)	Tensile displacement	Strain 1
	(s)	(mm)	(kN)	(%)	(mm)	(%)
	0.0000	0.0000	-0.0002	0.0000	0.0000	0.0000
	0.1600	0.0093	0.0604	0.0025	0.0013	0.0025
	0.3200	0.0225	0.1612	0.0064	0.0032	0.0064
	0.4800	0.0359	0.2825	0.0107	0.0054	0.0107
	0.6400	0.0493	0.4170	0.0156	0.0078	0.0156
	0.8000	0.0626	0.5478	0.0204	0.0102	0.0204
	0.9600	0.0759	0.6728	0.0249	0.0125	0.0249
	1.1200	0.0891	0.7928	0.0293	0.0147	0.0293
	1.2800	0.1024	0.9077	0.0336	0.0168	0.0336
	1.4400	0.1158	1.0167	0.0376	0.0188	0.0376
	1.6000	0.1293	1.1182	0.0414	0.0207	0.0414
	1.7600	0.1428	1.2122	0.0449	0.0224	0.0449
	1.9200	0.1559	1.3041	0.0483	0.0241	0.0483
	2.0800	0.1692	1.3980	0.0518	0.0259	0.0518
	2.2400	0.1826	1.4913	0.0552	0.0276	0.0552
	2.4000	0.1959	1.5845	0.0587	0.0293	0.0587
	2.5600	0.2094	1.6770	0.0621	0.0311	0.0621
	2.7200	0.2228	1.7698	0.0656	0.0328	0.0656
	2.8800	0.2359	1.8600	0.0689	0.0345	0.0689
	3.0400	0.2492	1.9526	0.0724	0.0362	0.0724
	3.2000	0.2625	2.0463	0.0759	0.0379	0.0759
	3.3600	0.2758	2.1406	0.0794	0.0397	0.0794
	3.5200	0.2891	2.2344	0.0829	0.0414	0.0829
	3.6800	0.3026	2.3248	0.0862	0.0431	0.0862
	3.8400	0.3158	2.4114	0.0894	0.0447	0.0894
	4.0000	0.3292	2.4992	0.0926	0.0463	0.0926
	4.1600	0.3425	2.5880	0.0959	0.0480	0.0959
	4.3200	0.3559	2.6780	0.0992	0.0496	0.0992
	4.4800	0.3693	2.7677	0.1025	0.0513	0.1025
	4.6400	0.3826	2.8572	0.1059	0.0529	0.1059
	4.8000	0.3960	2.9469	0.1091	0.0546	0.1091
	4.9600	0.4092	3.0350	0.1123	0.0562	0.1123
	5.1200	0.4226	3.1230	0.1156	0.0578	0.1156
	5.2800	0.4359	3.2099	0.1188	0.0594	0.1188
	5.4400	0.4491	3.2962	0.1220	0.0610	0.1220
	5.6000	0.4626	3.3838	0.1253	0.0627	0.1253
	5.7600	0.4762	3.4722	0.1285	0.0643	0.1285
	5.9200	0.4894	3.5591	0.1317	0.0659	0.1317
	6.0800	0.5027	3.6475	0.1350	0.0675	0.1350
	6.2400	0.5159	3.7355	0.1382	0.0691	0.1382
	6.4000	0.5291	3.8235	0.1415	0.0707	0.1415
	6.5600	0.5425	3.9128	0.1449	0.0724	0.1449
	6.7200	0.5560	4.0031	0.1482	0.0741	0.1482
	6.8800	0.5693	4.0912	0.1514	0.0757	0.1514
	7.0400	0.5826	4.1803	0.1547	0.0774	0.1547
	7.2000	0.5958	4.2692	0.1581	0.0790	0.1581
	7.3600	0.6091	4.3594	0.1614	0.0807	0.1614
	7.5200	0.6225	4.4504	0.1648	0.0824	0.1648
	7.6800	0.6359	4.5426	0.1682	0.0841	0.1682
	7.8400	0.6493	4.6342	0.1716	0.0858	0.1716
	8.0000	0.6625	4.7239	0.1750	0.0875	0.1750
	8.1600	0.6758	4.8158	0.1784	0.0892	0.1784
	8.3200	0.6892	4.9078	0.1818	0.0909	0.1818
	8.4800	0.7026	5.0009	0.1853	0.0927	0.1853
	8.6400	0.7160	5.0945	0.1889	0.0944	0.1889
	8.8000	0.7295	5.1886	0.1925	0.0962	0.1925
	8.9600	0.7426	5.2781	0.1958	0.0979	0.1958
	9.1200	0.7560	5.3712	0.1994	0.0997	0.1994
	9.2800	0.7693	5.4637	0.2029	0.1015	0.2029
	9.4400	0.7826	5.5583	0.2066	0.1033	0.2066
	9.6000	0.7959	5.6523	0.2102	0.1051	0.2102
	9.7600	0.8092	5.7463	0.2139	0.1070	0.2139
	9.9200	0.8225	5.8381	0.2176	0.1088	0.2176
	10.0800	0.8358	5.9307	0.2213	0.1106	0.2213
	10.2400	0.8492	6.0237	0.2251	0.1126	0.2251
	10.4000	0.8626	6.1170	0.2290	0.1145	0.2290
	10.5600	0.8759	6.2084	0.2328	0.1164	0.2328
	10.7200	0.8892	6.2999	0.2368	0.1184	0.2368
	10.8800	0.9026	6.3920	0.2408	0.1204	0.2408
	11.0400	0.9159	6.4826	0.2449	0.1225	0.2449
	11.2000	0.9293	6.5747	0.2492	0.1246	0.2492
	11.3600	0.9426	6.6650	0.2535	0.1268	0.2535
	11.5200	0.9559	6.7542	0.2580	0.1290	0.2580
	11.6800	0.9692	6.8420	0.2626	0.1313	0.2626
	11.8400	0.9828	6.9309	0.2674	0.1337	0.2674
	12.0000	0.9960	7.0149	0.2722	0.1361	0.2722
	12.1600	1.0094	7.1009	0.2773	0.1386	0.2773
	12.3200	1.0225	7.1823	0.2825	0.1413	0.2825
	12.4800	1.0358	7.2640	0.2879	0.1440	0.2879
	12.6400	1.0491	7.3443	0.2936	0.1468	0.2936
	12.8000	1.0626	7.4239	0.2996	0.1498	0.2996
	12.9600	1.0759	7.5001	0.3058	0.1529	0.3058
	13.1200	1.0892	7.5750	0.3121	0.1560	0.3121
	13.2800	1.1024	7.6462	0.3187	0.1593	0.3187
	13.4400	1.1158	7.7164	0.3255	0.1628	0.3255
	13.6000	1.1292	7.7856	0.3327	0.1663	0.3327
	13.7600	1.1427	7.8528	0.3401	0.1700	0.3401
	13.9200	1.1561	7.9172	0.3478	0.1739	0.3478
	14.0800	1.1692	7.9775	0.3556	0.1778	0.3556
	14.2400	1.1826	8.0373	0.3639	0.1819	0.3639
	14.4000	1.1959	8.0944	0.3722	0.1861	0.3722
	14.5600	1.2093	8.1501	0.3809	0.1904	0.3809
	14.7200	1.2227	8.2033	0.3899	0.1950	0.3899
	14.8800	1.2361	8.2543	0.3992	0.1996	0.3992
	15.0400	1.2493	8.3001	0.4084	0.2042	0.4084
	15.2000	1.2627	8.3463	0.4180	0.2090	0.4180
	15.3600	1.2760	8.3896	0.4279	0.2139	0.4279
	15.5200	1.2892	8.4319	0.4381	0.2190	0.4381
	15.6800	1.3025	8.4728	0.4486	0.2243	0.4486
	15.8400	1.3159	8.5107	0.4593	0.2296	0.4593
	16.0000	1.3291	8.5459	0.4701	0.2351	0.4701
	16.1600	1.3426	8.5816	0.4811	0.2405	0.4811
	16.3200	1.3559	8.6143	0.4924	0.2462	0.4924
	16.4800	1.3693	8.6468	0.5040	0.2520	0.5040
	16.6400	1.3826	8.6759	0.5157	0.2579	0.5157
	16.8000	1.3960	8.7039	0.5276	0.2638	0.5276
	16.9600	1.4093	8.7301	0.5398	0.2699	0.5398
	17.1200	1.4226	8.7564	0.5519	0.2759	0.5519
	17.2800	1.4361	8.7811	0.5645	0.2822	0.5645
	17.4400	1.4493	8.8034	0.5770	0.2885	0.5770
	17.6000	1.4626	8.8245	0.5898	0.2949	0.5898
	17.7600	1.4759	8.8450	0.6026	0.3013	0.6026
	17.9200	1.4895	8.8653	0.6157	0.3079	0.6157
	18.0800	1.5027	8.8827	0.6287	0.3143	0.6287
	18.2400	1.5161	8.9015	0.6419	0.3209	0.6419
	18.4000	1.5293	8.9158	0.6552	0.3276	0.6552
	18.5600	1.5426	8.9309	0.6686	0.3343	0.6686
	18.7200	1.5559	8.9462	0.6821	0.3410	0.6821
	18.8800	1.5694	8.9618	0.6959	0.3479	0.6959
	19.0400	1.5826	8.9748	0.7097	0.3548	0.7097
	19.2000	1.5959	8.9894	0.7233	0.3617	0.7233
	19.3600	1.6092	9.0006	0.7372	0.3686	0.7372
	19.5200	1.6226	9.0128	0.7512	0.3756	0.7512
	19.6800	1.6360	9.0249	0.7652	0.3826	0.7652
	19.8400	1.6494	9.0372	0.7794	0.3897	0.7794
	20.0000	1.6627	9.0472	0.7937	0.3968	0.7937
	20.1600	1.6759	9.0577	0.8077	0.4039	0.8077
	20.3200	1.6892	9.0668	0.8221	0.4110	0.8221
	20.4800	1.7026	9.0772	0.8364	0.4182	0.8364
	20.6400	1.7160	9.0871	0.8509	0.4254	0.8509
	20.8000	1.7294	9.0967	0.8655	0.4327	0.8655
	20.9600	1.7428	9.1054	0.8801	0.4401	0.8801
	21.1200	1.7559	9.1121	0.8944	0.4472	0.8944
	21.2800	1.7694	9.1214	0.9090	0.4545	0.9090
	21.4400	1.7828	9.1289	0.9236	0.4618	0.9236
	21.6000	1.7961	9.1375	0.9385	0.4692	0.9385
	21.7600	1.8094	9.1444	0.9533	0.4767	0.9533
	21.9200	1.8227	9.1513	0.9681	0.4841	0.9681
	22.0800	1.8358	9.1572	0.9829	0.4914	0.9829
	22.2400	1.8492	9.1665	0.9975	0.4988	0.9975
	22.4000	1.8625	9.1729	1.0123	0.5062	1.0123
	22.5600	1.8759	9.1803	1.0272	0.5136	1.0272
	22.7200	1.8892	9.1865	1.0422	0.5211	1.0422
	22.8800	1.9026	9.1924	1.0570	0.5285	1.0570
	23.0400	1.9160	9.1984	1.0719	0.5360	1.0719
	23.2000	1.9293	9.2058	1.0866	0.5433	1.0866
	23.3600	1.9427	9.2130	1.1016	0.5508	1.1016
	23.5200	1.9560	9.2193	1.1163	0.5582	1.1163
	23.6800	1.9693	9.2251	1.1313	0.5656	1.1313
	23.8400	1.9827	9.2311	1.1462	0.5731	1.1462
	24.0000	1.9962	9.2384	1.1613	0.5807	1.1613
	24.1600	2.0094	9.2433	1.1760	0.5880	1.1760
	24.3200	2.0228	9.2502	1.1910	0.5955	1.1910
	24.4800	2.0360	9.2535	1.2058	0.6029	1.2058
	24.6400	2.0493	9.2581	1.2209	0.6104	1.2209
	24.8000	2.0627	9.2631	1.2359	0.6180	1.2359
	24.9600	2.0761	9.2699	1.2510	0.6255	1.2510
	25.1200	2.0892	9.2740	1.2660	0.6330	1.2660
	25.2800	2.1025	9.2808	1.2809	0.6405	1.2809
	25.4400	2.1158	9.2847	1.2960	0.6480	1.2960
	25.6000	2.1293	9.2898	1.3110	0.6555	1.3110
	25.7600	2.1427	9.2959	1.3261	0.6630	1.3261
	25.9200	2.1561	9.3021	1.3412	0.6706	1.3412
	26.0800	2.1694	9.3064	1.3563	0.6782	1.3563
	26.2400	2.1826	9.3115	1.3712	0.6856	1.3712
	26.4000	2.1959	9.3162	1.3862	0.6931	1.3862
	26.5600	2.2094	9.3222	1.4012	0.7006	1.4012
	26.7200	2.2227	9.3273	1.4163	0.7082	1.4163
	26.8800	2.2361	9.3329	1.4314	0.7157	1.4314
	27.0400	2.2494	9.3370	1.4466	0.7233	1.4466
	27.2000	2.2625	9.3404	1.4613	0.7306	1.4613
	27.3600	2.2760	9.3466	1.4762	0.7381	1.4762
	27.5200	2.2894	9.3506	1.4911	0.7456	1.4911
	27.6800	2.3027	9.3549	1.5061	0.7531	1.5061
	27.8400	2.3160	9.3591	1.5212	0.7606	1.5212
	28.0000	2.3293	9.3629	1.5362	0.7681	1.5362
	28.1600	2.3424	9.3661	1.5511	0.7756	1.5511
	28.3200	2.3559	9.3732	1.5661	0.7830	1.5661
	28.4800	2.3693	9.3777	1.5812	0.7906	1.5812
	28.6400	2.3827	9.3827	1.5963	0.7981	1.5963
	28.8000	2.3960	9.3862	1.6113	0.8057	1.6113
	28.9600	2.4093	9.3909	1.6264	0.8132	1.6264
	29.1200	2.4227	9.3944	1.6416	0.8208	1.6416
	29.2800	2.4360	9.3998	1.6565	0.8282	1.6565
	29.4400	2.4493	9.4042	1.6717	0.8358	1.6717
	29.6000	2.4626	9.4081	1.6867	0.8434	1.6867
	29.7600	2.4759	9.4123	1.7018	0.8509	1.7018
	29.9200	2.4893	9.4164	1.7169	0.8585	1.7169
	30.0800	2.5029	9.4220	1.7322	0.8661	1.7322
	30.2400	2.5160	9.4257	1.7471	0.8736	1.7471
	30.4000	2.5294	9.4315	1.7622	0.8811	1.7622
	30.5600	2.5427	9.4340	1.7772	0.8886	1.7772
	30.7200	2.5561	9.4372	1.7923	0.8961	1.7923
	30.8800	2.5695	9.4410	1.8074	0.9037	1.8074
	31.0400	2.5829	9.4463	1.8226	0.9113	1.8226
	31.2000	2.5958	9.4489	1.8376	0.9188	1.8376
	31.3600	2.6091	9.4545	1.8526	0.9263	1.8526
	31.5200	2.6225	9.4571	1.8676	0.9338	1.8676
	31.6800	2.6359	9.4613	1.8826	0.9413	1.8826
	31.8400	2.6493	9.4656	1.8976	0.9488	1.8976
	32.0000	2.6627	9.4702	1.9127	0.9564	1.9127
	32.1600	2.6760	9.4727	1.9278	0.9639	1.9278
	32.3200	2.6892	9.4770	1.9426	0.9713	1.9426
	32.4800	2.7026	9.4809	1.9575	0.9787	1.9575
	32.6400	2.7160	9.4854	1.9724	0.9862	1.9724
	32.8000	2.7294	9.4902	1.9874	0.9937	1.9874
	32.9600	2.7428	9.4942	2.0024	1.0012	2.0024
	33.1200	2.7561	9.4975	2.0174	1.0087	2.0174
	33.2800	2.7693	9.5009	2.0320	1.0160	2.0320
	33.4400	2.7827	9.5059	2.0469	1.0235	2.0469
	33.6000	2.7962	9.5098	2.0617	1.0309	2.0617
	33.7600	2.8095	9.5129	2.0765	1.0383	2.0765
	33.9200	2.8227	9.5155	2.0914	1.0457	2.0914
	34.0800	2.8361	9.5184	2.1064	1.0532	2.1064
	34.2400	2.8491	9.5202	2.1212	1.0606	2.1212
	34.4000	2.8626	9.5265	2.1362	1.0681	2.1362
	34.5600	2.8759	9.5297	2.1513	1.0757	2.1513
	34.7200	2.8892	9.5339	2.1664	1.0832	2.1664
	34.8800	2.9026	9.5367	2.1816	1.0908	2.1816
	35.0400	2.9160	9.5401	2.1969	1.0985	2.1969
	35.2000	2.9294	9.5433	2.2125	1.1062	2.2125
	35.3600	2.9427	9.5482	2.2279	1.1139	2.2279
	35.5200	2.9560	9.5520	2.2435	1.1217	2.2435
	35.6800	2.9693	9.5555	2.2592	1.1296	2.2592
	35.8400	2.9826	9.5586	2.2750	1.1375	2.2750
	36.0000	2.9961	9.5626	2.2910	1.1455	2.2910
	36.1600	3.0095	9.5670	2.3071	1.1536	2.3071
	36.3200	3.0226	9.5702	2.3230	1.1615	2.3230
	36.4800	3.0360	9.5748	2.3391	1.1696	2.3391
	36.6400	3.0493	9.5764	2.3551	1.1776	2.3551
	36.8000	3.0628	9.5790	2.3712	1.1856	2.3712
	36.9600	3.0761	9.5816	2.3871	1.1936	2.3871
	37.1200	3.0895	9.5865	2.4032	1.2016	2.4032
	37.2800	3.1025	9.5879	2.4189	1.2094	2.4189
	37.4400	3.1158	9.5926	2.4344	1.2172	2.4344
	37.6000	3.1292	9.5948	2.4498	1.2249	2.4498
	37.7600	3.1426	9.5988	2.4647	1.2324	2.4647
	37.9200	3.1560	9.6031	2.4794	1.2397	2.4794
	38.0800	3.1695	9.6074	2.4938	1.2469	2.4938
	38.2400	3.1827	9.6090	2.5078	1.2539	2.5078
	38.4000	3.1959	9.6127	2.5210	1.2605	2.5210
	38.5600	3.2093	9.6158	2.5340	1.2670	2.5340
	38.7200	3.2226	9.6199	2.5464	1.2732	2.5464
	38.8800	3.2361	9.6235	2.5584	1.2792	2.5584
	39.0400	3.2494	9.6252	2.5697	1.2849	2.5697
	39.2000	3.2627	9.6272	2.5803	1.2902	2.5803
	39.3600	3.2758	9.6294	2.5900	1.2950	2.5900
	39.5200	3.2893	9.6348	2.5994	1.2997	2.5994
	39.6800	3.3027	9.6387	2.6085	1.3042	2.6085
	39.8400	3.3161	9.6422	2.6174	1.3087	2.6174
	40.0000	3.3294	9.6450	2.6264	1.3132	2.6264
	40.1600	3.3428	9.6511	2.6359	1.3180	2.6359
	40.3200	3.3558	9.6560	2.6463	1.3232	2.6463
	40.4800	3.3693	9.6632	2.6582	1.3291	2.6582
	40.6400	3.3825	9.6648	2.6720	1.3360	2.6720
	40.8000	3.3959	9.6653	2.6878	1.3439	2.6878
	40.9600	3.4092	9.6638	2.7054	1.3527	2.7054
	41.1200	3.4227	9.6649	2.7245	1.3623	2.7245
	41.2800	3.4361	9.6658	2.7447	1.3724	2.7447
	41.4400	3.4493	9.6709	2.7651	1.3826	2.7651
	41.6000	3.4626	9.6744	2.7866	1.3933	2.7866
	41.7600	3.4759	9.6768	2.8085	1.4042	2.8085
	41.9200	3.4893	9.6784	2.8310	1.4155	2.8310
	42.0800	3.5027	9.6803	2.8539	1.4269	2.8539
	42.2400	3.5162	9.6844	2.8771	1.4386	2.8771
	42.4000	3.5292	9.6880	2.8998	1.4499	2.8998
	42.5600	3.5426	9.6939	2.9230	1.4615	2.9230
	42.7200	3.5560	9.6991	2.9456	1.4728	2.9456
	42.8800	3.5695	9.7043	2.9683	1.4842	2.9683
	43.0400	3.5829	9.7068	2.9912	1.4956	2.9912
	43.2000	3.5963	9.7094	3.0144	1.5072	3.0144
	43.3600	3.6092	9.7100	3.0376	1.5188	3.0376
	43.5200	3.6225	9.7155	3.0605	1.5302	3.0605
	43.6800	3.6358	9.7157	3.0836	1.5418	3.0836
	43.8400	3.6492	9.7166	3.1067	1.5534	3.1067
	44.0000	3.6626	9.7180	3.1298	1.5649	3.1298
	44.1600	3.6760	9.7206	3.1529	1.5764	3.1529
	44.3200	3.6893	9.7366	3.1738	1.5869	3.1738
	44.4800	3.7025	9.7487	3.1929	1.5965	3.1929
	44.6400	3.7159	9.7491	3.2099	1.6049	3.2099
	44.8000	3.7293	9.7480	3.2224	1.6112	3.2224
	44.9600	3.7427	9.7474	3.2316	1.6158	3.2316
	45.1200	3.7561	9.7481	3.2385	1.6193	3.2385
	45.2800	3.7695	9.7490	3.2441	1.6221	3.2441
	45.4400	3.7825	9.7507	3.2487	1.6244	3.2487
	45.6000	3.7960	9.7539	3.2528	1.6264	3.2528
	45.7600	3.8094	9.7549	3.2562	1.6281	3.2562
	45.9200	3.8228	9.7559	3.2590	1.6295	3.2590
	46.0800	3.8361	9.7571	3.2615	1.6308	3.2615
	46.2400	3.8496	9.7381	3.2626	1.6313	3.2626
	46.4000	3.8626	9.7699	3.2656	1.6328	3.2656
	46.5600	3.8760	9.8017	3.2700	1.6350	3.2700
	46.7200	3.8891	9.8083	3.2751	1.6375	3.2751
	46.8800	3.9024	9.8011	3.2821	1.6411	3.2821
	47.0400	3.9158	9.7945	3.2916	1.6458	3.2916
	47.2000	3.9294	9.7929	3.3035	1.6517	3.3035
	47.3600	3.9427	9.7940	3.3170	1.6585	3.3170
	47.5200	3.9560	9.7976	3.3314	1.6657	3.3314
	47.6800	3.9692	9.7961	3.3474	1.6737	3.3474
	47.8400	3.9826	9.7967	3.3644	1.6822	3.3644
	48.0000	3.9960	9.8007	3.3812	1.6906	3.3812
	48.1600	4.0095	9.8052	3.3965	1.6982	3.3965
	48.3200	4.0229	9.8047	3.4090	1.7045	3.4090
	48.4800	4.0359	9.8042	3.4183	1.7092	3.4183
	48.6400	4.0493	9.8046	3.4257	1.7128	3.4257
	48.8000	4.0626	9.8039	3.4313	1.7157	3.4313
	48.9600	4.0761	9.8046	3.4360	1.7180	3.4360
	49.1200	4.0894	9.8061	3.4399	1.7199	3.4399
	49.2800	4.1029	9.7785	3.4413	1.7207	3.4413
	49.4400	4.1158	9.8224	3.4458	1.7229	3.4458
	49.6000	4.1291	9.8517	3.4519	1.7260	3.4519
	49.7600	4.1424	9.8572	3.4609	1.7305	3.4609
	49.9200	4.1559	9.8500	3.4754	1.7377	3.4754
	50.0800	4.1693	9.8324	3.4977	1.7489	3.4977
	50.2400	4.1827	9.8514	3.5184	1.7592	3.5184
	50.4000	4.1960	9.8578	3.5405	1.7703	3.5405
	50.5600	4.2092	9.8566	3.5639	1.7819	3.5639
	50.7200	4.2226	9.8540	3.5886	1.7943	3.5886
	50.8800	4.2360	9.8578	3.6129	1.8065	3.6129
	51.0400	4.2494	9.8618	3.6375	1.8188	3.6375
	51.2000	4.2627	9.8627	3.6625	1.8313	3.6625
	51.3600	4.2761	9.8594	3.6882	1.8441	3.6882
	51.5200	4.2892	9.8581	3.7133	1.8567	3.7133
	51.6800	4.3027	9.8601	3.7390	1.8695	3.7390
	51.8400	4.3160	9.8644	3.7641	1.8821	3.7641
	52.0000	4.3293	9.8700	3.7892	1.8946	3.7892
	52.1600	4.3427	9.8708	3.8146	1.9073	3.8146
	52.3200	4.3562	9.8674	3.8409	1.9204	3.8409
	52.4800	4.3693	9.8606	3.8673	1.9336	3.8673
	52.6400	4.3827	9.8494	3.8947	1.9474	3.8947
	52.8000	4.3958	9.8431	3.9213	1.9607	3.9213
	52.9600	4.4091	9.8672	3.9450	1.9725	3.9450
	53.1200	4.4225	9.8827	3.9693	1.9846	3.9693
	53.2800	4.4361	9.8923	3.9942	1.9971	3.9942
	53.4400	4.4494	9.8927	4.0201	2.0101	4.0201
	53.6000	4.4626	9.8931	4.0459	2.0229	4.0459
	53.7600	4.4759	9.8936	4.0718	2.0359	4.0718
	53.9200	4.4892	9.8952	4.0975	2.0487	4.0975
	54.0500	4.5001	9.8969	4.1185	2.0592	4.1184
	54.2100	4.5044	9.8404	4.1236	2.0618	4.1184
	54.3700	4.5042	9.8110	4.1233	2.0617	4.1184
	54.5300	4.5040	9.7971	4.1231	2.0615	4.1184
	54.6900	4.5037	9.7879	4.1227	2.0614	4.1184
	54.8500	4.5035	9.7806	4.1225	2.0613	4.1184
	55.0100	4.5033	9.7746	4.1223	2.0611	4.1184
	55.1700	4.5031	9.7695	4.1221	2.0610	4.1184
	55.3300	4.5030	9.7653	4.1220	2.0610	4.1184
	55.4900	4.5030	9.7620	4.1219	2.0609	4.1184
	55.6500	4.5029	9.7593	4.1218	2.0609	4.1184
	55.8100	4.5029	9.7568	4.1218	2.0609	4.1184
	55.9700	4.5029	9.7548	4.1217	2.0609	4.1184
	56.1300	4.5028	9.7529	4.1217	2.0609	4.1184
	56.2900	4.5028	9.7515	4.1217	2.0609	4.1184
	56.4500	4.5028	9.7499	4.1217	2.0609	4.1184
	56.6100	4.5028	9.7485	4.1217	2.0609	4.1184
	56.7700	4.5028	9.7471	4.1217	2.0609	4.1184
	56.9300	4.5028	9.7459	4.1217	2.0608	4.1184
	57.0900	4.5028	9.7448	4.1217	2.0608	4.1184
	57.2500	4.5028	9.7437	4.1217	2.0608	4.1184
	57.4100	4.5028	9.7426	4.1217	2.0608	4.1184
	57.5700	4.5028	9.7416	4.1217	2.0608	4.1184
	57.7300	4.5028	9.7408	4.1217	2.0608	4.1184
	57.8900	4.5028	9.7398	4.1217	2.0608	4.1184
	58.0500	4.5028	9.7389	4.1217	2.0608	4.1184
	58.2100	4.5028	9.7382	4.1217	2.0608	4.1184
	58.3700	4.5028	9.7374	4.1217	2.0608	4.1184
	58.5300	4.5028	9.7364	4.1217	2.0608	4.1184
	58.6900	4.5028	9.7359	4.1217	2.0608	4.1184
	58.8500	4.5028	9.7351	4.1217	2.0608	4.1184
	59.0100	4.5028	9.7344	4.1217	2.0608	4.1184
	59.1700	4.5028	9.7338	4.1217	2.0608	4.1184
	59.3300	4.5028	9.7332	4.1217	2.0608	4.1184
	59.4900	4.5028	9.7326	4.1217	2.0608	4.1184
	59.6500	4.5028	9.7319	4.1217	2.0608	4.1184
	59.8100	4.5028	9.7314	4.1217	2.0608	4.1184
	59.9700	4.5028	9.7308	4.1217	2.0608	4.1184
	60.1300	4.5028	9.7302	4.1217	2.0608	4.1184
	60.2900	4.5028	9.7297	4.1217	2.0608	4.1184
	60.4500	4.5028	9.7291	4.1217	2.0608	4.1184
	60.6100	4.5028	9.7286	4.1217	2.0608	4.1184
	60.7700	4.5028	9.7283	4.1217	2.0608	4.1184
	60.9300	4.5028	9.7279	4.1217	2.0608	4.1184
	61.0900	4.5028	9.7274	4.1217	2.0608	4.1184
	61.2500	4.5028	9.7269	4.1217	2.0608	4.1184
	61.4100	4.5028	9.7266	4.1217	2.0608	4.1184
	61.5700	4.5028	9.7261	4.1217	2.0608	4.1184
	61.7300	4.5028	9.7257	4.1217	2.0608	4.1184
	61.8900	4.5028	9.7252	4.1217	2.0608	4.1184
	62.0500	4.5028	9.7248	4.1217	2.0608	4.1184
	62.2100	4.5028	9.7246	4.1217	2.0608	4.1184
	62.3700	4.5028	9.7241	4.1217	2.0608	4.1184
	62.5300	4.5028	9.7238	4.1217	2.0608	4.1184
	62.6900	4.5028	9.7234	4.1217	2.0608	4.1184
	62.8500	4.5028	9.7231	4.1217	2.0608	4.1184
	63.0100	4.5028	9.7226	4.1217	2.0608	4.1184
	63.1700	4.5028	9.7223	4.1217	2.0608	4.1184
	63.3300	4.5028	9.7219	4.1217	2.0608	4.1184
	63.4900	4.5028	9.7218	4.1217	2.0608	4.1184
	63.6500	4.5028	9.7217	4.1217	2.0608	4.1184
	63.8100	4.5028	9.7218	4.1217	2.0608	4.1184
	63.9700	4.5028	9.7203	4.1216	2.0608	4.1184
	64.1300	4.5028	9.7206	4.1217	2.0608	4.1184
	64.2900	4.5028	9.7214	4.1216	2.0608	4.1184
	64.4500	4.5028	9.7219	4.1217	2.0608	4.1184
	64.6100	4.5028	9.7216	4.1216	2.0608	4.1184
	64.7700	4.5028	9.7219	4.1217	2.0608	4.1184
	64.9300	4.5028	9.7207	4.1217	2.0608	4.1184
	65.0900	4.5028	9.7208	4.1217	2.0608	4.1184
	65.2500	4.5028	9.7204	4.1217	2.0608	4.1184
	65.4100	4.5028	9.7203	4.1217	2.0608	4.1184
	65.5700	4.5028	9.7200	4.1217	2.0608	4.1184
	65.7300	4.5028	9.7196	4.1217	2.0608	4.1184
	65.8900	4.5028	9.7194	4.1217	2.0608	4.1184
	66.0500	4.5028	9.7194	4.1217	2.0608	4.1184
	66.2100	4.5028	9.7193	4.1217	2.0608	4.1184
	66.3700	4.5028	9.7185	4.1217	2.0608	4.1184
	66.5300	4.5028	9.7176	4.1217	2.0608	4.1184
	66.6900	4.5028	9.7165	4.1217	2.0608	4.1184
	66.8500	4.5028	9.7160	4.1217	2.0608	4.1184
	67.0100	4.5028	9.7160	4.1217	2.0608	4.1184
	67.1700	4.5028	9.7158	4.1217	2.0608	4.1184
	67.3300	4.5028	9.7156	4.1217	2.0608	4.1184
	67.4900	4.5028	9.7154	4.1217	2.0608	4.1184
	67.6500	4.5028	9.7150	4.1217	2.0608	4.1184
	67.8100	4.5028	9.7147	4.1217	2.0608	4.1184
	67.9700	4.5028	9.7145	4.1217	2.0608	4.1184
	68.1300	4.5028	9.7142	4.1217	2.0608	4.1184
	68.2900	4.5028	9.7138	4.1217	2.0608	4.1184
	68.4500	4.5028	9.7136	4.1217	2.0608	4.1184
	68.6100	4.5028	9.7134	4.1217	2.0608	4.1184
	68.7700	4.5028	9.7133	4.1217	2.0608	4.1184
	68.9300	4.5028	9.7130	4.1217	2.0608	4.1184
	69.0900	4.5028	9.7129	4.1217	2.0608	4.1184
	69.2500	4.5028	9.7127	4.1217	2.0608	4.1184
	69.4100	4.5028	9.7125	4.1217	2.0608	4.1184
	69.5700	4.5028	9.7123	4.1217	2.0608	4.1184
	69.7300	4.5028	9.7137	4.1217	2.0608	4.1184
	69.8900	4.5028	9.7127	4.1217	2.0608	4.1184
	70.0500	4.5028	9.7111	4.1217	2.0608	4.1184
	70.2100	4.5028	9.7107	4.1217	2.0608	4.1184
	70.3700	4.5028	9.7103	4.1217	2.0608	4.1184
	70.5300	4.5028	9.7098	4.1217	2.0608	4.1184
	70.6900	4.5028	9.7089	4.1217	2.0608	4.1184
	70.8500	4.5028	9.7110	4.1217	2.0608	4.1184
	71.0100	4.5028	9.7099	4.1217	2.0608	4.1184
	71.1700	4.5028	9.7074	4.1217	2.0608	4.1184
	71.3300	4.5028	9.7071	4.1217	2.0608	4.1184
	71.4900	4.5028	9.7067	4.1217	2.0608	4.1184
	71.6500	4.5028	9.7075	4.1217	2.0608	4.1184
	71.8100	4.5028	9.7059	4.1217	2.0608	4.1184
	71.9700	4.5028	9.7040	4.1217	2.0608	4.1184
	72.1300	4.5028	9.7046	4.1217	2.0608	4.1184
	72.2900	4.5028	9.7057	4.1217	2.0608	4.1184
	72.4500	4.5028	9.7056	4.1217	2.0608	4.1184
	72.6100	4.5028	9.7054	4.1217	2.0608	4.1184
	72.7700	4.5028	9.7051	4.1217	2.0608	4.1184
	72.9300	4.5028	9.7048	4.1217	2.0608	4.1184
	73.0900	4.5028	9.7046	4.1217	2.0608	4.1184
	73.2500	4.5028	9.7047	4.1217	2.0608	4.1184
	73.4100	4.5028	9.7045	4.1217	2.0608	4.1184
	73.5700	4.5028	9.7045	4.1217	2.0608	4.1184
	73.7300	4.5028	9.7043	4.1217	2.0608	4.1184
	73.8900	4.5028	9.7042	4.1217	2.0608	4.1184
	73.9970	4.5028	9.7041	4.1217	2.0608	4.1184
	74.1430	4.5314	10.0023	4.1555	2.0777	4.1184
	74.3030	4.5711	9.9518	4.2024	2.1012	4.1184
	74.4630	4.6111	10.0482	4.2497	2.1249	4.1184
	74.6230	4.6507	10.0776	4.2966	2.1483	4.1184
	74.7830	4.6908	10.0078	4.3441	2.1720	4.1184
	74.9430	4.7306	10.0050	4.3911	2.1956	4.1184
	75.1030	4.7707	10.0024	4.4386	2.2193	4.1184
	75.2630	4.8107	10.0045	4.4859	2.2429	4.1184
	75.4230	4.8506	10.0122	4.5330	2.2665	4.1184
	75.5830	4.8907	10.0204	4.5805	2.2903	4.1184
	75.7430	4.9306	10.0150	4.6277	2.3138	4.1184
	75.9030	4.9707	10.0000	4.6750	2.3375	4.1184
	76.0630	5.0106	10.0029	4.7223	2.3611	4.1184
	76.2230	5.0506	10.0250	4.7696	2.3848	4.1184
	76.3830	5.0906	10.0582	4.8169	2.4084	4.1184
	76.5430	5.1306	10.0695	4.8643	2.4321	4.1184
	76.7030	5.1706	10.0620	4.9115	2.4558	4.1184
	76.8630	5.2108	10.0637	4.9591	2.4795	4.1184
	77.0230	5.2507	10.0592	5.0062	2.5031	4.1184
	77.1830	5.2908	10.0483	5.0537	2.5268	4.1184
	77.3430	5.3307	10.0414	5.1008	2.5504	4.1184
	77.5030	5.3708	10.0723	5.1483	2.5741	4.1184
	77.6630	5.4105	10.0605	5.1952	2.5976	4.1184
	77.8230	5.4507	10.0602	5.2428	2.6214	4.1184
	77.9830	5.4907	10.0672	5.2901	2.6450	4.1184
	78.1430	5.5307	10.0653	5.3374	2.6687	4.1184
	78.3030	5.5707	10.0381	5.3847	2.6924	4.1184
	78.4630	5.6107	10.0135	5.4320	2.7160	4.1184
	78.6230	5.6507	10.0545	5.4793	2.7396	4.1184
	78.7830	5.6906	10.0673	5.5266	2.7633	4.1184
	78.9430	5.7305	10.0466	5.5738	2.7869	4.1184
	79.1030	5.7707	10.0334	5.6213	2.8107	4.1184
	79.2630	5.8107	10.0358	5.6685	2.8343	4.1184
	79.4230	5.8506	10.0645	5.7158	2.8579	4.1184
	79.5830	5.8907	10.0651	5.7632	2.8816	4.1184
	79.7430	5.9306	10.0748	5.8104	2.9052	4.1184
	79.9030	5.9707	10.1151	5.8578	2.9289	4.1184
	80.0630	6.0106	10.1362	5.9050	2.9525	4.1184
	80.2230	6.0508	10.1622	5.9526	2.9763	4.1184
	80.3830	6.0906	10.1810	5.9996	2.9998	4.1184
	80.5430	6.1308	10.1977	6.0472	3.0236	4.1184
	80.7030	6.1706	10.2018	6.0942	3.0471	4.1184
	80.8630	6.2108	10.2178	6.1418	3.0709	4.1184
	81.0230	6.2507	10.2195	6.1889	3.0945	4.1184
	81.1830	6.2907	10.2167	6.2363	3.1181	4.1184
	81.3430	6.3308	10.2029	6.2837	3.1418	4.1184
	81.5030	6.3705	10.1930	6.3307	3.1654	4.1184
	81.6630	6.4106	10.1934	6.3782	3.1891	4.1184
	81.8230	6.4505	10.1818	6.4253	3.2127	4.1184
	81.9830	6.4906	10.2173	6.4728	3.2364	4.1184
	82.1430	6.5307	10.2312	6.5201	3.2600	4.1184
	82.3030	6.5707	10.2304	6.5674	3.2837	4.1184
	82.4630	6.6107	10.2334	6.6147	3.3074	4.1184
	82.6230	6.6507	10.2323	6.6620	3.3310	4.1184
	82.7830	6.6906	10.2284	6.7093	3.3546	4.1184
	82.9430	6.7306	10.2271	6.7565	3.3783	4.1184
	83.1030	6.7706	10.2254	6.8039	3.4019	4.1184
	83.2630	6.8108	10.2258	6.8514	3.4257	4.1184
	83.4230	6.8506	10.2267	6.8985	3.4493	4.1184
	83.5830	6.8908	10.2290	6.9461	3.4730	4.1184
	83.7430	6.9307	10.2306	6.9932	3.4966	4.1184
	83.9030	6.9708	10.2311	7.0407	3.5203	4.1184
	84.0630	7.0106	10.2238	7.0877	3.5439	4.1184
	84.2230	7.0507	10.2132	7.1352	3.5676	4.1184
	84.3830	7.0906	10.2070	7.1824	3.5912	4.1184
	84.5430	7.1307	10.1664	7.2298	3.6149	4.1184
	84.7030	7.1707	10.2629	7.2771	3.6385	4.1184
	84.8630	7.2106	10.2796	7.3243	3.6621	4.1184
	85.0230	7.2506	10.2952	7.3716	3.6858	4.1184
	85.1830	7.2906	10.3049	7.4189	3.7094	4.1184
	85.3430	7.3307	10.3212	7.4663	3.7332	4.1184
	85.5030	7.3706	10.3293	7.5135	3.7568	4.1184
	85.6630	7.4107	10.3219	7.5609	3.7804	4.1184
	85.8230	7.4506	10.3548	7.6082	3.8041	4.1184
	85.9830	7.4907	10.3578	7.6555	3.8278	4.1184
	86.1430	7.5306	10.3541	7.7028	3.8514	4.1184
	86.3030	7.5709	10.3380	7.7504	3.8752	4.1184
	86.4630	7.6106	10.3371	7.7974	3.8987	4.1184
	86.6230	7.6508	10.3461	7.8449	3.9225	4.1184
	86.7830	7.6907	10.3498	7.8921	3.9461	4.1184
	86.9430	7.7307	10.3651	7.9394	3.9697	4.1184
	87.1030	7.7705	10.3607	7.9866	3.9933	4.1184
	87.2630	7.8107	10.3713	8.0340	4.0170	4.1184
	87.4230	7.8506	10.3964	8.0813	4.0406	4.1184
	87.5830	7.8906	10.4068	8.1286	4.0643	4.1184
	87.7430	7.9308	10.4005	8.1761	4.0880	4.1184
	87.9030	7.9707	10.4037	8.2233	4.1116	4.1184
	88.0630	8.0106	10.4034	8.2705	4.1353	4.1184
	88.2230	8.0506	10.3968	8.3178	4.1589	4.1184
	88.3830	8.0906	10.3828	8.3650	4.1825	4.1184
	88.5430	8.1307	10.3668	8.4125	4.2063	4.1184
	88.7030	8.1706	10.3532	8.4597	4.2299	4.1184
	88.8630	8.2107	10.3351	8.5072	4.2536	4.1184
	89.0230	8.2507	10.3414	8.5544	4.2772	4.1184
	89.1830	8.2906	10.3489	8.6016	4.3008	4.1184
	89.3430	8.3308	10.3610	8.6492	4.3246	4.1184
	89.5030	8.3706	10.3635	8.6963	4.3481	4.1184
	89.6630	8.4108	10.3611	8.7438	4.3719	4.1184
	89.8230	8.4506	10.3583	8.7909	4.3954	4.1184
	89.9830	8.4909	10.3874	8.8385	4.4192	4.1184
	90.1430	8.5306	10.3678	8.8854	4.4427	4.1184
	90.3030	8.5708	10.4329	8.9330	4.4665	4.1184
	90.4630	8.6106	10.4511	8.9801	4.4900	4.1184
	90.6230	8.6506	10.4688	9.0274	4.5137	4.1184
	90.7830	8.6906	10.4885	9.0748	4.5374	4.1184
	90.9430	8.7306	10.4989	9.1220	4.5610	4.1184
	91.1030	8.7707	10.5022	9.1694	4.5847	4.1184
	91.2630	8.8107	10.5027	9.2168	4.6084	4.1184
	91.4230	8.8507	10.4977	9.2641	4.6320	4.1184
	91.5830	8.8906	10.4942	9.3113	4.6556	4.1184
	91.7430	8.9307	10.4777	9.3587	4.6793	4.1184
	91.9030	8.9706	10.4623	9.4059	4.7030	4.1184
	92.0630	9.0107	10.4722	9.4533	4.7267	4.1184
	92.2230	9.0505	10.4666	9.5004	4.7502	4.1184
	92.3830	9.0907	10.4690	9.5480	4.7740	4.1184
	92.5430	9.1306	10.4712	9.5952	4.7976	4.1184
	92.7030	9.1709	10.4697	9.6427	4.8214	4.1184
	92.8630	9.2108	10.4706	9.6899	4.8450	4.1184
	93.0230	9.2508	10.4797	9.7373	4.8686	4.1184
	93.1830	9.2905	10.4841	9.7843	4.8921	4.1184
	93.3430	9.3307	10.4813	9.8318	4.9159	4.1184
	93.5030	9.3707	10.4823	9.8791	4.9395	4.1184
	93.6630	9.4106	10.5287	9.9263	4.9632	4.1184
	93.8230	9.4506	10.5202	9.9736	4.9868	4.1184
	93.9830	9.4906	10.5163	10.0209	5.0105	4.1184
	94.1430	9.5306	10.5161	10.0683	5.0341	4.1184
	94.3030	9.5707	10.5316	10.1156	5.0578	4.1184
	94.4630	9.6106	10.5312	10.1629	5.0814	4.1184
	94.6230	9.6507	10.5361	10.2103	5.1051	4.1184
	94.7830	9.6906	10.5374	10.2575	5.1288	4.1184
	94.9430	9.7306	10.5380	10.3048	5.1524	4.1184
	95.1030	9.7707	10.5415	10.3521	5.1761	4.1184
	95.2630	9.8106	10.5274	10.3994	5.1997	4.1184
	95.4230	9.8507	10.5341	10.4469	5.2234	4.1184
	95.5830	9.8906	10.5524	10.4940	5.2470	4.1184
	95.7430	9.9309	10.5427	10.5417	5.2709	4.1184
	95.9030	9.9706	10.5382	10.5887	5.2943	4.1184
	96.0630	10.0109	10.5423	10.6363	5.3182	4.1184
	96.2230	10.0505	10.5413	10.6832	5.3416	4.1184
	96.3830	10.0907	10.5310	10.7306	5.3653	4.1184
	96.5430	10.1306	10.4761	10.7779	5.3890	4.1184
	96.7030	10.1706	10.5651	10.8252	5.4126	4.1184
	96.8630	10.2107	10.5746	10.8726	5.4363	4.1184
	97.0230	10.2507	10.6013	10.9199	5.4599	4.1184
	97.1830	10.2907	10.5982	10.9672	5.4836	4.1184
	97.3430	10.3306	10.6053	11.0144	5.5072	4.1184
	97.5030	10.3707	10.5909	11.0618	5.5309	4.1184
	97.6630	10.4106	10.6037	11.1090	5.5545	4.1184
	97.8230	10.4506	10.6143	11.1564	5.5782	4.1184
	97.9830	10.4906	10.6244	11.2037	5.6018	4.1184
	98.1430	10.5306	10.6329	11.2510	5.6255	4.1184
	98.3030	10.5706	10.6386	11.2983	5.6492	4.1184
	98.4630	10.6107	10.6412	11.3457	5.6729	4.1184
	98.6230	10.6507	10.6414	11.3930	5.6965	4.1184
	98.7830	10.6908	10.6329	11.4404	5.7202	4.1184
	98.9430	10.7307	10.6111	11.4876	5.7438	4.1184
	99.1030	10.7708	10.6186	11.5351	5.7675	4.1184
	99.2630	10.8106	10.6199	11.5821	5.7911	4.1184
	99.4230	10.8507	10.6172	11.6296	5.8148	4.1184
	99.5830	10.8906	10.6238	11.6767	5.8383	4.1184
	99.7430	10.9307	10.6256	11.7241	5.8621	4.1184
	99.9030	10.9707	10.6277	11.7714	5.8857	4.1184
	100.0630	11.0108	10.6263	11.8189	5.9094	4.1184
	100.2230	11.0507	10.6177	11.8661	5.9330	4.1184
	100.3830	11.0906	10.6217	11.9133	5.9567	4.1184
	100.5430	11.1306	10.6326	11.9606	5.9803	4.1184
	100.7030	11.1706	10.6413	12.0079	6.0040	4.1184
	100.8630	11.2106	10.6336	12.0553	6.0276	4.1184
	101.0230	11.2507	10.6348	12.1026	6.0513	4.1184
	101.1830	11.2906	10.6358	12.1499	6.0749	4.1184
	101.3430	11.3306	10.6511	12.1972	6.0986	4.1184
	101.5030	11.3708	10.6562	12.2447	6.1223	4.1184
	101.6630	11.4106	10.6467	12.2917	6.1459	4.1184
	101.8230	11.4509	10.6390	12.3394	6.1697	4.1184
	101.9830	11.4905	10.6326	12.3863	6.1932	4.1184
	102.1430	11.5308	10.6778	12.4340	6.2170	4.1184
	102.3030	11.5707	10.6812	12.4811	6.2405	4.1184
	102.4630	11.6107	10.6845	12.5284	6.2642	4.1184
	102.6230	11.6507	10.7194	12.5757	6.2878	4.1184
	102.7830	11.6907	10.6691	12.6230	6.3115	4.1184
	102.9430	11.7306	10.6747	12.6703	6.3351	4.1184
	103.1030	11.7706	10.6565	12.7176	6.3588	4.1184
	103.2630	11.8107	10.6642	12.7650	6.3825	4.1184
	103.4230	11.8505	10.6742	12.8121	6.4060	4.1184
	103.5830	11.8906	10.6610	12.8595	6.4298	4.1184
	103.7430	11.9306	10.6984	12.9068	6.4534	4.1184
	103.9030	11.9706	10.7000	12.9541	6.4771	4.1184
	104.0630	12.0107	10.7137	13.0015	6.5008	4.1184
	104.2230	12.0506	10.7208	13.0487	6.5243	4.1184
	104.3830	12.0906	10.7259	13.0960	6.5480	4.1184
	104.5430	12.1306	10.7253	13.1433	6.5717	4.1184
	104.7030	12.1706	10.7314	13.1907	6.5953	4.1184
	104.8630	12.2109	10.7374	13.2383	6.6191	4.1184
	105.0230	12.2507	10.7308	13.2854	6.6427	4.1184
	105.1830	12.2908	10.7256	13.3328	6.6664	4.1184
	105.3430	12.3306	10.7174	13.3799	6.6900	4.1184
	105.5030	12.3708	10.6865	13.4274	6.7137	4.1184
	105.6630	12.4106	10.7322	13.4745	6.7372	4.1184
	105.8230	12.4507	10.7355	13.5220	6.7610	4.1184
	105.9830	12.4906	10.7398	13.5691	6.7846	4.1184
	106.1430	12.5307	10.7350	13.6165	6.8083	4.1184
	106.3030	12.5707	10.7278	13.6639	6.8319	4.1184
	106.4630	12.6106	10.7507	13.7111	6.8555	4.1184
	106.6230	12.6506	10.7574	13.7584	6.8792	4.1184
	106.7830	12.6907	10.7720	13.8057	6.9029	4.1184
	106.9430	12.7306	10.7721	13.8530	6.9265	4.1184
	107.1030	12.7706	10.7551	13.9003	6.9502	4.1184
	107.2630	12.8107	10.7571	13.9477	6.9738	4.1184
	107.4230	12.8506	10.7562	13.9949	6.9974	4.1184
	107.5830	12.8907	10.7485	14.0423	7.0211	4.1184
	107.7430	12.9306	10.7354	14.0895	7.0447	4.1184
	107.9030	12.9708	10.7214	14.1371	7.0686	4.1184
	108.0630	13.0107	10.7350	14.1842	7.0921	4.1184
	108.2230	13.0509	10.7604	14.2318	7.1159	4.1184
	108.3830	13.0907	10.7600	14.2788	7.1394	4.1184
	108.5430	13.1306	10.7854	14.3260	7.1630	4.1184
	108.7030	13.1705	10.8018	14.3732	7.1866	4.1184
	108.8630	13.2107	10.8189	14.4208	7.2104	4.1184
	109.0230	13.2508	10.8209	14.4682	7.2341	4.1184
	109.1830	13.2906	10.8320	14.5153	7.2577	4.1184
	109.3430	13.3307	10.8024	14.5628	7.2814	4.1184
	109.5030	13.3707	10.8146	14.6100	7.3050	4.1184
	109.6630	13.4106	10.8230	14.6572	7.3286	4.1184
	109.8230	13.4506	10.8334	14.7045	7.3523	4.1184
	109.9830	13.4906	10.8447	14.7518	7.3759	4.1184
	110.1430	13.5306	10.8420	14.7991	7.3996	4.1184
	110.3030	13.5707	10.8369	14.8465	7.4233	4.1184
	110.4630	13.6107	10.8268	14.8939	7.4469	4.1184
	110.6230	13.6507	10.8038	14.9412	7.4706	4.1184
	110.7830	13.6907	10.7946	14.9885	7.4942	4.1184
	110.9430	13.7308	10.7997	15.0359	7.5180	4.1184
	111.1030	13.7707	10.8012	15.0831	7.5415	4.1184
	111.2630	13.8109	10.7999	15.1306	7.5653	4.1184
	111.4230	13.8505	10.7988	15.1775	7.5887	4.1184
	111.5830	13.8909	10.7978	15.2252	7.6126	4.1184
	111.7430	13.9306	10.7938	15.2722	7.6361	4.1184
	111.9030	13.9707	10.7990	15.3197	7.6599	4.1184
	112.0630	14.0107	10.8016	15.3670	7.6835	4.1184
	112.2230	14.0507	10.7967	15.4143	7.7072	4.1184
	112.3830	14.0907	10.7872	15.4616	7.7308	4.1184
	112.5430	14.1306	10.7710	15.5088	7.7544	4.1184
	112.7030	14.1706	10.7850	15.5561	7.7781	4.1184
	112.8630	14.2106	10.8241	15.6034	7.8017	4.1184
	113.0230	14.2507	10.8131	15.6508	7.8254	4.1184
	113.1830	14.2905	10.8359	15.6979	7.8490	4.1184
	113.3430	14.3306	10.8345	15.7454	7.8727	4.1184
	113.5030	14.3707	10.8208	15.7927	7.8964	4.1184
	113.6630	14.4107	10.8108	15.8400	7.9200	4.1184
	113.8230	14.4506	10.8165	15.8873	7.9436	4.1184
	113.9830	14.4907	10.8106	15.9347	7.9674	4.1184
	114.1430	14.5306	10.8343	15.9819	7.9909	4.1184
	114.3030	14.5708	10.8577	16.0295	8.0147	4.1184
	114.4630	14.6107	10.8428	16.0766	8.0383	4.1184
	114.6230	14.6508	10.8332	16.1241	8.0620	4.1184
	114.7830	14.6907	10.8388	16.1712	8.0856	4.1184
	114.9430	14.7307	10.8413	16.2186	8.1093	4.1184
	115.1030	14.7707	10.8386	16.2658	8.1329	4.1184
	115.2630	14.8107	10.8427	16.3131	8.1566	4.1184
	115.4230	14.8506	10.8578	16.3604	8.1802	4.1184
	115.5830	14.8907	10.8606	16.4078	8.2039	4.1184
	115.7430	14.9307	10.8480	16.4551	8.2275	4.1184
	115.9030	14.9707	10.8605	16.5024	8.2512	4.1184
	116.0630	15.0107	10.8495	16.5497	8.2748	4.1184
	116.2230	15.0507	10.8142	16.5970	8.2985	4.1184
	116.3830	15.0906	10.8349	16.6442	8.3221	4.1184
	116.5430	15.1306	10.8408	16.6916	8.3458	4.1184
	116.7030	15.1705	10.8528	16.7388	8.3694	4.1184
	116.8630	15.2106	10.8709	16.7861	8.3930	4.1184
	117.0230	15.2508	10.8832	16.8337	8.4169	4.1184
	117.1830	15.2906	10.9048	16.8807	8.4404	4.1184
	117.3430	15.3309	10.9193	16.9284	8.4642	4.1184
	117.5030	15.3705	10.9242	16.9753	8.4876	4.1184
	117.6630	15.4109	10.9336	17.0230	8.5115	4.1184
	117.8230	15.4506	10.9134	17.0700	8.5350	4.1184
	117.9830	15.4907	10.8783	17.1175	8.5587	4.1184
	118.1430	15.5306	10.8907	17.1647	8.5823	4.1184
	118.3030	15.5707	10.9026	17.2121	8.6060	4.1184
	118.4630	15.6107	10.9110	17.2593	8.6297	4.1184
	118.6230	15.6506	10.9109	17.3066	8.6533	4.1184
	118.7830	15.6907	10.8701	17.3540	8.6770	4.1184
	118.9430	15.7305	10.8986	17.4011	8.7005	4.1184
	119.1030	15.7707	10.8823	17.4485	8.7243	4.1184
	119.2630	15.8106	10.8976	17.4958	8.7479	4.1184
	119.4230	15.8506	10.9183	17.5431	8.7715	4.1184
	119.5830	15.8906	10.9157	17.5904	8.7952	4.1184
	119.7430	15.9307	10.9154	17.6378	8.8189	4.1184
	119.9030	15.9706	10.9261	17.6850	8.8425	4.1184
	120.0630	16.0108	10.9294	17.7325	8.8663	4.1184
	120.2230	16.0507	10.9320	17.7797	8.8899	4.1184
	120.3830	16.0908	10.9336	17.8272	8.9136	4.1184
	120.5430	16.1307	10.9323	17.8744	8.9372	4.1184
	120.7030	16.1708	10.9271	17.9218	8.9609	4.1184
	120.8630	16.2105	10.9227	17.9688	8.9844	4.1184
	121.0230	16.2507	10.9034	18.0163	9.0082	4.1184
	121.1830	16.2906	10.9349	18.0635	9.0318	4.1184
	121.3430	16.3307	10.9367	18.1110	9.0555	4.1184
	121.5030	16.3707	10.9299	18.1582	9.0791	4.1184
	121.6630	16.4107	10.9448	18.2056	9.1028	4.1184
	121.8230	16.4507	10.9472	18.2528	9.1264	4.1184
	121.9830	16.4906	10.9456	18.3000	9.1500	4.1184
	122.1430	16.5306	10.9452	18.3474	9.1737	4.1184
	122.3030	16.5707	10.9350	18.3948	9.1974	4.1184
	122.4630	16.6106	10.9144	18.4420	9.2210	4.1184
	122.6230	16.6506	10.9114	18.4893	9.2446	4.1184
	122.7830	16.6907	10.9075	18.5367	9.2684	4.1184
	122.9430	16.7306	10.8982	18.5839	9.2919	4.1184
	123.1030	16.7707	10.9027	18.6314	9.3157	4.1184
	123.2630	16.8106	10.9056	18.6785	9.3392	4.1184
	123.4230	16.8508	10.9016	18.7260	9.3630	4.1184
	123.5830	16.8905	10.9145	18.7731	9.3865	4.1184
	123.7430	16.9309	10.9310	18.8208	9.4104	4.1184
	123.9030	16.9707	10.9502	18.8678	9.4339	4.1184
	124.0630	17.0108	10.9696	18.9153	9.4576	4.1184
	124.2230	17.0506	10.9986	18.9624	9.4812	4.1184
	124.3830	17.0907	11.0342	19.0097	9.5049	4.1184
	124.5430	17.1307	11.0377	19.0572	9.5286	4.1184
	124.7030	17.1706	11.0072	19.1043	9.5521	4.1184
	124.8630	17.2108	10.9629	19.1518	9.5759	4.1184
	125.0230	17.2506	10.9745	19.1990	9.5995	4.1184
	125.1830	17.2906	10.9496	19.2462	9.6231	4.1184
	125.3430	17.3307	10.9449	19.2936	9.6468	4.1184
	125.5030	17.3707	10.9248	19.3409	9.6705	4.1184
	125.6630	17.4106	10.9271	19.3882	9.6941	4.1184
	125.8230	17.4507	10.9328	19.4356	9.7178	4.1184
	125.9830	17.4906	10.9502	19.4828	9.7414	4.1184
	126.1430	17.5306	10.9531	19.5301	9.7650	4.1184
	126.3030	17.5707	10.9851	19.5775	9.7888	4.1184
	126.4630	17.6107	10.9810	19.6248	9.8124	4.1184
	126.6230	17.6506	10.9098	19.6720	9.8360	4.1184
	126.7830	17.6908	10.9318	19.7196	9.8598	4.1184
	126.9430	17.7306	10.9414	19.7666	9.8833	4.1184
	127.1030	17.7708	10.9249	19.8142	9.9071	4.1184
	127.2630	17.8106	10.9385	19.8613	9.9306	4.1184
	127.4230	17.8507	10.9416	19.9087	9.9543	4.1184
	127.5830	17.8906	10.9427	19.9559	9.9779	4.1184
	127.7430	17.9307	10.9458	20.0033	10.0016	4.1184
	127.9030	17.9707	10.9510	20.0506	10.0253	4.1184
	128.0630	18.0106	10.9532	20.0978	10.0489	4.1184
	128.2230	18.0506	10.9547	20.1451	10.0726	4.1184
	128.3830	18.0906	10.9584	20.1925	10.0962	4.1184
	128.5430	18.1307	10.9576	20.2398	10.1199	4.1184
	128.7030	18.1706	10.9612	20.2870	10.1435	4.1184
	128.8630	18.2107	10.9646	20.3344	10.1672	4.1184
	129.0230	18.2506	10.9675	20.3817	10.1908	4.1184
	129.1830	18.2906	10.9612	20.4290	10.2145	4.1184
	129.3430	18.3307	10.9466	20.4764	10.2382	4.1184
	129.5030	18.3709	10.9547	20.5239	10.2620	4.1184
	129.6630	18.4106	10.9572	20.5709	10.2855	4.1184
	129.8230	18.4508	10.9555	20.6185	10.3092	4.1184
	129.9830	18.4906	10.9528	20.6655	10.3328	4.1184
	130.1430	18.5307	10.9584	20.7129	10.3564	4.1184
	130.3030	18.5706	10.9612	20.7601	10.3801	4.1184
	130.4630	18.6107	10.9693	20.8075	10.4038	4.1184
	130.6230	18.6507	10.9751	20.8549	10.4274	4.1184
	130.7830	18.6907	10.9812	20.9022	10.4511	4.1184
	130.9430	18.7307	10.9892	20.9495	10.4748	4.1184
	131.1030	18.7707	10.9939	20.9968	10.4984	4.1184
	131.2630	18.8106	10.9985	21.0440	10.5220	4.1184
	131.4230	18.8506	10.9904	21.0913	10.5456	4.1184
	131.5830	18.8906	11.0103	21.1386	10.5693	4.1184
	131.7430	18.9307	11.0126	21.1860	10.5930	4.1184
	131.9030	18.9706	11.0288	21.2332	10.6166	4.1184
	132.0630	19.0107	11.0485	21.2806	10.6403	4.1184
	132.2230	19.0506	11.0473	21.3279	10.6639	4.1184
	132.3830	19.0906	11.0482	21.3751	10.6876	4.1184
	132.5430	19.1308	11.0201	21.4227	10.7113	4.1184
	132.7030	19.1706	11.0313	21.4698	10.7349	4.1184
	132.8630	19.2109	11.0396	21.5174	10.7587	4.1184
	133.0230	19.2506	11.0217	21.5644	10.7822	4.1184
	133.1830	19.2908	10.9868	21.6119	10.8060	4.1184
	133.3430	19.3306	10.9913	21.6590	10.8295	4.1184
	133.5030	19.3708	10.9861	21.7065	10.8533	4.1184
	133.6630	19.4107	10.9947	21.7537	10.8768	4.1184
	133.8230	19.4507	10.9941	21.8011	10.9005	4.1184
	133.9830	19.4907	10.9945	21.8483	10.9242	4.1184
	134.1430	19.5306	10.9945	21.8956	10.9478	4.1184
	134.3030	19.5706	10.9956	21.9429	10.9714	4.1184
	134.4630	19.6106	10.9991	21.9902	10.9951	4.1184
	134.6230	19.6507	11.0018	22.0375	11.0188	4.1184
	134.7830	19.6906	11.0073	22.0848	11.0424	4.1184
	134.9430	19.7307	11.0091	22.1322	11.0661	4.1184
	135.1030	19.7707	11.0110	22.1795	11.0898	4.1184
	135.2630	19.8108	11.0089	22.2269	11.1134	4.1184
	135.4230	19.8506	11.0063	22.2740	11.1370	4.1184
	135.5830	19.8907	11.0063	22.3214	11.1607	4.1184
	135.7430	19.9306	11.0078	22.3686	11.1843	4.1184
	135.9030	19.9708	11.0087	22.4162	11.2081	4.1184
	136.0630	20.0108	11.0108	22.4635	11.2317	4.1184
	136.2230	20.0508	11.0148	22.5108	11.2554	4.1184
	136.3830	20.0906	11.0143	22.5579	11.2789	4.1184
	136.5430	20.1307	11.0082	22.6053	11.3027	4.1184
	136.7030	20.1706	11.0064	22.6525	11.3263	4.1184
	136.8630	20.2107	11.0178	22.6999	11.3499	4.1184
	137.0230	20.2507	11.0169	22.7472	11.3736	4.1184
	137.1830	20.2906	11.0244	22.7945	11.3972	4.1184
	137.3430	20.3307	11.0305	22.8418	11.4209	4.1184
	137.5030	20.3707	11.0321	22.8891	11.4446	4.1184
	137.6630	20.4106	11.0308	22.9364	11.4682	4.1184
	137.8230	20.4507	11.0290	22.9838	11.4919	4.1184
	137.9830	20.4906	11.0252	23.0309	11.5155	4.1184
	138.1430	20.5306	11.0196	23.0783	11.5391	4.1184
	138.3030	20.5707	11.0156	23.1257	11.5628	4.1184
	138.4630	20.6106	11.0146	23.1729	11.5864	4.1184
	138.6230	20.6508	11.0080	23.2204	11.6102	4.1184
	138.7830	20.6906	11.0077	23.2675	11.6337	4.1184
	138.9430	20.7308	11.0057	23.3151	11.6576	4.1184
	139.1030	20.7707	11.0032	23.3622	11.6811	4.1184
	139.2630	20.8110	11.0085	23.4099	11.7049	4.1184
	139.4230	20.8505	11.0166	23.4566	11.7283	4.1184
[...]
	101.9760	10.1014	10.7363	10.8556	5.4278	4.0413
	102.1560	10.1463	10.7282	10.9102	5.4551	4.0413
	102.3360	10.1914	10.7584	10.9650	5.4825	4.0413
	102.5160	10.2364	10.7840	11.0197	5.5099	4.0413
	102.6960	10.2813	10.8143	11.0744	5.5372	4.0413
	102.8760	10.3263	10.8319	11.1292	5.5646	4.0413
	103.0560	10.3714	10.7860	11.1840	5.5920	4.0413
	103.2360	10.4162	10.7358	11.2386	5.6193	4.0413
	103.4160	10.4614	10.7288	11.2935	5.6467	4.0413
	103.5960	10.5063	10.7427	11.3482	5.6741	4.0413
	103.7760	10.5514	10.7517	11.4030	5.7015	4.0413
	103.9560	10.5964	10.7558	11.4578	5.7289	4.0413
	104.1360	10.6413	10.7572	11.5124	5.7562	4.0413
	104.3160	10.6866	10.7564	11.5674	5.7837	4.0413
	104.4960	10.7313	10.7578	11.6219	5.8109	4.0413
	104.6760	10.7765	10.7584	11.6769	5.8384	4.0413
	104.8560	10.8214	10.7510	11.7314	5.8657	4.0413
	105.0360	10.8663	10.7412	11.7861	5.8930	4.0413
	105.2160	10.9113	10.7325	11.8409	5.9204	4.0413
	105.3960	10.9563	10.7348	11.8956	5.9478	4.0413
	105.5760	11.0014	10.7352	11.9505	5.9752	4.0413
	105.7560	11.0463	10.7707	12.0051	6.0025	4.0413
	105.9360	11.0912	10.7959	12.0597	6.0299	4.0413
	106.1160	11.1364	10.8156	12.1147	6.0573	4.0413
	106.2960	11.1813	10.8047	12.1693	6.0847	4.0413
	106.4760	11.2264	10.7971	12.2241	6.1121	4.0413
	106.6560	11.2714	10.7970	12.2789	6.1394	4.0413
	106.8360	11.3163	10.7390	12.3336	6.1668	4.0413
	107.0160	11.3616	10.7579	12.3886	6.1943	4.0413
	107.1960	11.4063	10.7629	12.4431	6.2215	4.0413
	107.3760	11.4515	10.7731	12.4980	6.2490	4.0413
	107.5560	11.4963	10.7738	12.5526	6.2763	4.0413
	107.7360	11.5413	10.7754	12.6073	6.3036	4.0413
	107.9160	11.5864	10.7780	12.6621	6.3311	4.0413
	108.0960	11.6313	10.7834	12.7168	6.3584	4.0413
	108.2760	11.6763	10.7921	12.7715	6.3858	4.0413
	108.4560	11.7213	10.8058	12.8262	6.4131	4.0413
	108.6360	11.7662	10.8237	12.8809	6.4404	4.0413
	108.8160	11.8114	10.8403	12.9358	6.4679	4.0413
	108.9960	11.8563	10.8556	12.9905	6.4952	4.0413
	109.1760	11.9014	10.8715	13.0453	6.5226	4.0413
	109.3560	11.9464	10.8806	13.1001	6.5501	4.0413
	109.5360	11.9913	10.8806	13.1547	6.5773	4.0413
	109.7160	12.0366	10.8720	13.2098	6.6049	4.0413
	109.8960	12.0813	10.8591	13.2642	6.6321	4.0413
	110.0760	12.1265	10.8608	13.3192	6.6596	4.0413
	110.2560	12.1713	10.8524	13.3737	6.6868	4.0413
	110.4360	12.2164	10.8399	13.4286	6.7143	4.0413
	110.6160	12.2614	10.8365	13.4833	6.7416	4.0413
	110.7960	12.3063	10.8356	13.5379	6.7690	4.0413
	110.9760	12.3513	10.8401	13.5927	6.7963	4.0413
	111.1560	12.3964	10.8503	13.6475	6.8237	4.0413
	111.3360	12.4413	10.8637	13.7021	6.8511	4.0413
	111.5160	12.4863	10.8788	13.7570	6.8785	4.0413
	111.6960	12.5313	10.8992	13.8117	6.9058	4.0413
	111.8760	12.5763	10.9209	13.8664	6.9332	4.0413
	112.0560	12.6214	10.9447	13.9213	6.9606	4.0413
	112.2360	12.6662	10.9601	13.9758	6.9879	4.0413
	112.4160	12.7116	10.9593	14.0309	7.0155	4.0413
	112.5960	12.7564	10.9473	14.0854	7.0427	4.0413
	112.7760	12.8015	10.9424	14.1403	7.0702	4.0413
	112.9560	12.8463	10.9467	14.1949	7.0974	4.0413
	113.1360	12.8914	10.9581	14.2497	7.1248	4.0413
	113.3160	12.9363	10.9691	14.3044	7.1522	4.0413
	113.4960	12.9813	11.0109	14.3591	7.1795	4.0413
	113.6760	13.0264	10.9033	14.4140	7.2070	4.0413
	113.8560	13.0714	10.9395	14.4687	7.2343	4.0413
	114.0360	13.1162	10.9448	14.5232	7.2616	4.0413
	114.2160	13.1613	10.9185	14.5781	7.2890	4.0413
	114.3960	13.2063	10.9023	14.6328	7.3164	4.0413
	114.5760	13.2515	10.9201	14.6878	7.3439	4.0413
	114.7560	13.2964	10.8909	14.7425	7.3712	4.0413
	114.9360	13.3413	10.8596	14.7970	7.3985	4.0413
	115.1160	13.3866	10.8606	14.8522	7.4261	4.0413
	115.2960	13.4313	10.8843	14.9065	7.4533	4.0413
	115.4760	13.4765	10.9072	14.9615	7.4807	4.0413
	115.6560	13.5213	10.9330	15.0160	7.5080	4.0413
	115.8360	13.5664	10.9510	15.0708	7.5354	4.0413
	116.0160	13.6113	10.9548	15.1256	7.5628	4.0413
	116.1960	13.6563	10.9540	15.1802	7.5901	4.0413
	116.3760	13.7014	10.9576	15.2351	7.6175	4.0413
	116.5560	13.7463	10.9622	15.2898	7.6449	4.0413
	116.7360	13.7912	10.9644	15.3444	7.6722	4.0413
	116.9160	13.8364	10.9582	15.3994	7.6997	4.0413
	117.0960	13.8814	10.9439	15.4541	7.7270	4.0413
	117.2760	13.9264	10.9353	15.5088	7.7544	4.0413
	117.4560	13.9714	10.9337	15.5636	7.7818	4.0413
	117.6360	14.0163	10.9312	15.6182	7.8091	4.0413
	117.8160	14.0616	10.9307	15.6734	7.8367	4.0413
	117.9960	14.1063	10.9299	15.7277	7.8638	4.0413
	118.1760	14.1515	10.9114	15.7827	7.8913	4.0413
	118.3560	14.1964	10.9437	15.8373	7.9186	4.0413
	118.5360	14.2414	10.9465	15.8920	7.9460	4.0413
	118.7160	14.2864	10.9572	15.9467	7.9734	4.0413
	118.8960	14.3313	10.9628	16.0014	8.0007	4.0413
	119.0760	14.3764	10.9301	16.0562	8.0281	4.0413
	119.2560	14.4213	10.9478	16.1109	8.0555	4.0413
	119.4360	14.4663	10.9536	16.1656	8.0828	4.0413
	119.6160	14.5114	10.9595	16.2205	8.1103	4.0413
	119.7960	14.5563	10.9679	16.2751	8.1376	4.0413
	119.9760	14.6013	10.9774	16.3299	8.1650	4.0413
	120.1560	14.6464	10.9831	16.3848	8.1924	4.0413
	120.3360	14.6913	10.9884	16.4394	8.2197	4.0413
	120.5160	14.7366	10.9943	16.4944	8.2472	4.0413
	120.6960	14.7813	10.9986	16.5489	8.2744	4.0413
	120.8760	14.8265	11.0093	16.6039	8.3019	4.0413
	121.0560	14.8713	11.0131	16.6584	8.3292	4.0413
	121.2360	14.9163	11.0182	16.7131	8.3566	4.0413
	121.4160	14.9614	11.0201	16.7680	8.3840	4.0413
	121.5960	15.0063	11.0165	16.8226	8.4113	4.0413
	121.7760	15.0514	11.0101	16.8774	8.4387	4.0413
	121.9560	15.0963	10.9998	16.9321	8.4661	4.0413
	122.1360	15.1413	11.0043	16.9868	8.4934	4.0413
	122.3160	15.1864	11.0041	17.0417	8.5208	4.0413
	122.4960	15.2313	11.0007	17.0963	8.5482	4.0413
	122.6760	15.2764	10.9981	17.1511	8.5756	4.0413
	122.8560	15.3215	10.9932	17.2060	8.6030	4.0413
	123.0360	15.3662	10.9933	17.2604	8.6302	4.0413
	123.2160	15.4115	10.9958	17.3155	8.6578	4.0413
	123.3960	15.4563	11.0011	17.3700	8.6850	4.0413
	123.5760	15.5015	11.0120	17.4251	8.7125	4.0413
	123.7560	15.5463	11.0243	17.4795	8.7398	4.0413
	123.9360	15.5914	11.0356	17.5343	8.7672	4.0413
	124.1160	15.6364	11.0482	17.5891	8.7946	4.0413
	124.2960	15.6813	11.0614	17.6437	8.8219	4.0413
	124.4760	15.7263	11.0762	17.6985	8.8492	4.0413
	124.6560	15.7713	11.0833	17.7533	8.8766	4.0413
	124.8360	15.8163	11.0856	17.8080	8.9040	4.0413
	125.0160	15.8614	11.0826	17.8628	8.9314	4.0413
	125.1960	15.9063	11.0774	17.9175	8.9588	4.0413
	125.3760	15.9514	11.0748	17.9723	8.9862	4.0413
	125.5560	15.9964	11.0784	18.0271	9.0136	4.0413
	125.7360	16.0412	11.0872	18.0816	9.0408	4.0413
	125.9160	16.0866	11.1017	18.1368	9.0684	4.0413
	126.0960	16.1313	11.1215	18.1913	9.0956	4.0413
	126.2760	16.1765	11.1442	18.2462	9.1231	4.0413
	126.4560	16.2213	11.0476	18.3007	9.1504	4.0413
	126.6360	16.2664	11.0740	18.3555	9.1778	4.0413
	126.8160	16.3114	11.0684	18.4103	9.2051	4.0413
	126.9960	16.3563	11.0281	18.4650	9.2325	4.0413
	127.1760	16.4014	11.0294	18.5198	9.2599	4.0413
	127.3560	16.4464	11.0202	18.5746	9.2873	4.0413
	127.5360	16.4912	11.0348	18.6291	9.3145	4.0413
	127.7160	16.5364	11.0485	18.6840	9.3420	4.0413
	127.8960	16.5813	11.0514	18.7387	9.3693	4.0413
	128.0760	16.6264	11.0608	18.7935	9.3967	4.0413
	128.2560	16.6714	11.0681	18.8482	9.4241	4.0413
	128.4360	16.7163	11.0587	18.9029	9.4515	4.0413
	128.6160	16.7616	11.0554	18.9580	9.4790	4.0413
	128.7960	16.8063	11.0799	19.0124	9.5062	4.0413
	128.9760	16.8514	11.0827	19.0673	9.5336	4.0413
	129.1560	16.8963	11.0761	19.1219	9.5609	4.0413
	129.3360	16.9414	11.0712	19.1767	9.5884	4.0413
	129.5160	16.9864	11.0558	19.2314	9.6157	4.0413
	129.6960	17.0313	11.0652	19.2861	9.6431	4.0413
	129.8760	17.0764	11.0708	19.3409	9.6705	4.0413
	130.0560	17.1214	11.0718	19.3957	9.6978	4.0413
	130.2360	17.1662	11.0758	19.4502	9.7251	4.0413
	130.4160	17.2114	11.0772	19.5052	9.7526	4.0413
	130.5960	17.2564	11.0705	19.5599	9.7800	4.0413
	130.7760	17.3014	11.0727	19.6147	9.8073	4.0413
	130.9560	17.3464	11.0788	19.6694	9.8347	4.0413
	131.1360	17.3913	11.0838	19.7240	9.8620	4.0413
	131.3160	17.4366	11.0860	19.7791	9.8896	4.0413
	131.4960	17.4813	11.0905	19.8335	9.9168	4.0413
	131.6760	17.5265	11.1010	19.8885	9.9443	4.0413
	131.8560	17.5713	11.1104	19.9431	9.9715	4.0413
	132.0360	17.6162	11.1145	19.9976	9.9988	4.0413
	132.2160	17.6612	11.1143	20.0525	10.0262	4.0413
	132.3960	17.7063	11.1105	20.1072	10.0536	4.0413
	132.5760	17.7514	11.1032	20.1621	10.0811	4.0413
	132.7560	17.7964	11.0960	20.2168	10.1084	4.0413
	132.9360	17.8413	11.1058	20.2715	10.1357	4.0413
	133.1160	17.8864	11.0958	20.3264	10.1632	4.0413
	133.2960	17.9313	11.0778	20.3810	10.1905	4.0413
	133.4760	17.9763	11.0822	20.4358	10.2179	4.0413
	133.6560	18.0214	11.0850	20.4906	10.2453	4.0413
	133.8360	18.0663	11.0890	20.5452	10.2726	4.0413
	134.0160	18.1116	11.0917	20.6003	10.3001	4.0413
	134.1960	18.1563	11.0874	20.6547	10.3274	4.0413
	134.3760	18.2016	11.0836	20.7098	10.3549	4.0413
	134.5560	18.2463	11.0789	20.7642	10.3821	4.0413
	134.7360	18.2913	11.0772	20.8189	10.4095	4.0413
	134.9160	18.3364	11.0865	20.8738	10.4369	4.0413
	135.0960	18.3813	11.1019	20.9285	10.4642	4.0413
	135.2760	18.4263	11.1306	20.9832	10.4916	4.0413
	135.4560	18.4713	11.1854	21.0379	10.5190	4.0413
	135.6360	18.5163	11.1118	21.0926	10.5463	4.0413
	135.8160	18.5614	11.1302	21.1475	10.5738	4.0413
	135.9960	18.6063	11.0945	21.2022	10.6011	4.0413
	136.1760	18.6514	11.1057	21.2570	10.6285	4.0413
	136.3560	18.6965	11.1028	21.3119	10.6559	4.0413
	136.5360	18.7413	11.1027	21.3664	10.6832	4.0413
	136.7160	18.7866	11.1002	21.4214	10.7107	4.0413
	136.8960	18.8313	11.0980	21.4759	10.7379	4.0413
	137.0760	18.8765	11.1019	21.5309	10.7655	4.0413
	137.2560	18.9213	11.1059	21.5853	10.7927	4.0413
	137.4360	18.9664	11.1126	21.6402	10.8201	4.0413
	137.6160	19.0114	11.1188	21.6949	10.8475	4.0413
	137.7960	19.0563	11.1257	21.7496	10.8748	4.0413
	137.9760	19.1013	11.1340	21.8043	10.9022	4.0413
	138.1560	19.1464	11.1395	21.8592	10.9296	4.0413
	138.3360	19.1913	11.1470	21.9138	10.9569	4.0413
	138.5160	19.2363	11.1516	21.9686	10.9843	4.0413
	138.6960	19.2813	11.1540	22.0234	11.0117	4.0413
	138.8760	19.3264	11.1552	22.0781	11.0391	4.0413
	139.0560	19.3715	11.1531	22.1330	11.0665	4.0413
	139.2360	19.4162	11.1516	22.1875	11.0937	4.0413
	139.4160	19.4616	11.1516	22.2426	11.1213	4.0413
	139.5960	19.5064	11.1549	22.2971	11.1486	4.0413
	139.7760	19.5515	11.1571	22.3520	11.1760	4.0413
	139.9560	19.5963	11.1637	22.4065	11.2033	4.0413
	140.1360	19.6413	11.1719	22.4613	11.2307	4.0413
	140.3160	19.6864	11.1827	22.5161	11.2581	4.0413
	140.4960	19.7313	11.1930	22.5708	11.2854	4.0413
	140.6760	19.7764	11.2055	22.6256	11.3128	4.0413
	140.8560	19.8214	11.2122	22.6804	11.3402	4.0413
	141.0360	19.8662	11.2022	22.7349	11.3674	4.0413
	141.2160	19.9113	11.2033	22.7898	11.3949	4.0413
	141.3960	19.9563	11.1808	22.8445	11.4223	4.0413
	141.5760	20.0014	11.1842	22.8994	11.4497	4.0413
	141.7560	20.0464	11.1808	22.9542	11.4771	4.0413
	141.9360	20.0913	11.1562	23.0088	11.5044	4.0413
	142.1160	20.1366	11.1573	23.0638	11.5319	4.0413
	142.2960	20.1813	11.1584	23.1183	11.5591	4.0413
	142.4760	20.2265	11.1508	23.1732	11.5866	4.0413
	142.6560	20.2713	11.1492	23.2277	11.6138	4.0413
	142.8360	20.3164	11.1448	23.2825	11.6413	4.0413
	143.0160	20.3613	11.1413	23.3372	11.6686	4.0413
	143.1960	20.4063	11.1367	23.3920	11.6960	4.0413
	143.3760	20.4514	11.1356	23.4468	11.7234	4.0413
	143.5560	20.4963	11.1330	23.5015	11.7507	4.0413
	143.7360	20.5412	11.1326	23.5561	11.7780	4.0413
	143.9160	20.5864	11.1333	23.6111	11.8055	4.0413
	144.0960	20.6313	11.1317	23.6657	11.8329	4.0413
	144.2760	20.6764	11.1347	23.7205	11.8602	4.0413
	144.4560	20.7214	11.1358	23.7753	11.8876	4.0413
	144.6360	20.7663	11.1379	23.8299	11.9149	4.0413
	144.8160	20.8116	11.1368	23.8850	11.9425	4.0413
	144.9960	20.8563	11.1419	23.9394	11.9697	4.0413
	145.1760	20.9015	11.1480	23.9944	11.9972	4.0413
	145.3560	20.9464	11.1536	24.0490	12.0245	4.0413
	145.5360	20.9914	11.1455	24.1037	12.0519	4.0413
	145.7160	21.0363	11.1268	24.1584	12.0792	4.0413
	145.8960	21.0813	11.1167	24.2131	12.1065	4.0413
	146.0760	21.1263	11.1367	24.2679	12.1340	4.0413
	146.2560	21.1713	11.1396	24.3226	12.1613	4.0413
	146.4360	21.2163	11.1493	24.3773	12.1887	4.0413
	146.6160	21.2614	11.1487	24.4322	12.2161	4.0413
	146.7960	21.3063	11.1500	24.4869	12.2434	4.0413
	146.9760	21.3513	11.1503	24.5416	12.2708	4.0413
	147.1560	21.3964	11.1471	24.5965	12.2982	4.0413
	147.3360	21.4413	11.1433	24.6511	12.3256	4.0413
	147.5160	21.4866	11.1394	24.7061	12.3531	4.0413
	147.6960	21.5313	11.1373	24.7606	12.3803	4.0413
	147.8760	21.5765	11.1369	24.8155	12.4078	4.0413
	148.0560	21.6214	11.1361	24.8701	12.4351	4.0413
	148.2360	21.6663	11.1338	24.9248	12.4624	4.0413
	148.4160	21.7114	11.1349	24.9796	12.4898	4.0413
	148.5960	21.7563	11.1384	25.0343	12.5172	4.0413
	148.7760	21.8013	11.1430	25.0891	12.5445	4.0413
	148.9560	21.8463	11.1420	25.1438	12.5719	4.0413
	149.1360	21.8912	11.1418	25.1984	12.5992	4.0413
	149.3160	21.9364	11.1418	25.2533	12.6267	4.0413
	149.4960	21.9813	11.1388	25.3080	12.6540	4.0413
	149.6760	22.0264	11.1386	25.3629	12.6814	4.0413
	149.8560	22.0715	11.1401	25.4177	12.7088	4.0413
	150.0360	22.1162	11.1327	25.4721	12.7361	4.0413
	150.2160	22.1615	11.1292	25.5272	12.7636	4.0413
	150.3960	22.2063	11.1302	25.5817	12.7909	4.0413
	150.5760	22.2516	11.1402	25.6368	12.8184	4.0413
	150.7560	22.2963	11.1320	25.6912	12.8456	4.0413
	150.9360	22.3414	11.1372	25.7460	12.8730	4.0413
	151.1160	22.3864	11.1452	25.8008	12.9004	4.0413
	151.2960	22.4313	11.1469	25.8555	12.9277	4.0413
	151.4760	22.4763	11.1257	25.9102	12.9551	4.0413
	151.6560	22.5213	11.1431	25.9649	12.9825	4.0413
	151.8360	22.5663	11.1403	26.0196	13.0098	4.0413
	152.0160	22.6114	11.1249	26.0745	13.0373	4.0413
	152.1960	22.6564	11.1208	26.1292	13.0646	4.0413
	152.3760	22.7014	11.1270	26.1840	13.0920	4.0413
	152.5560	22.7464	11.1335	26.2388	13.1194	4.0413
	152.7360	22.7912	11.1379	26.2933	13.1466	4.0413
	152.9160	22.8366	11.1373	26.3485	13.1743	4.0413
	153.0960	22.8813	11.1352	26.4029	13.2015	4.0413
	153.2760	22.9265	11.1351	26.4579	13.2289	4.0413
	153.4560	22.9713	11.1428	26.5123	13.2562	4.0413
	153.6360	23.0164	11.1391	26.5672	13.2836	4.0413
	153.8160	23.0614	11.1462	26.6219	13.3110	4.0413
	153.9960	23.1063	11.1522	26.6766	13.3383	4.0413
	154.1760	23.1513	11.1695	26.7314	13.3657	4.0413
	154.3560	23.1964	11.1800	26.7862	13.3931	4.0413
	154.5360	23.2412	11.1866	26.8408	13.4204	4.0413
	154.7160	23.2864	11.1868	26.8957	13.4478	4.0413
	154.8960	23.3313	11.1821	26.9503	13.4751	4.0413
	155.0760	23.3764	11.1815	27.0052	13.5026	4.0413
	155.2560	23.4214	11.1839	27.0600	13.5300	4.0413
	155.4360	23.4663	11.1854	27.1146	13.5573	4.0413
	155.6160	23.5116	11.1869	27.1696	13.5848	4.0413
	155.7960	23.5563	11.1877	27.2241	13.6120	4.0413
	155.9760	23.6015	11.1888	27.2790	13.6395	4.0413
	156.1560	23.6463	11.1879	27.3336	13.6668	4.0413
	156.3360	23.6914	11.1865	27.3884	13.6942	4.0413
	156.5160	23.7363	11.1901	27.4431	13.7215	4.0413
	156.6960	23.7813	11.2005	27.4978	13.7489	4.0413
	156.8760	23.8263	11.2171	27.5525	13.7763	4.0413
	157.0560	23.8713	11.2354	27.6073	13.8037	4.0413
	157.2360	23.9162	11.2541	27.6619	13.8310	4.0413
	157.4160	23.9614	11.2683	27.7168	13.8584	4.0413
	157.5960	24.0064	11.2575	27.7716	13.8858	4.0413
	157.7760	24.0514	11.2455	27.8263	13.9132	4.0413
	157.9560	24.0964	11.2359	27.8811	13.9406	4.0413
	158.1360	24.1413	11.2262	27.9357	13.9679	4.0413
	158.3160	24.1866	11.2178	27.9908	13.9954	4.0413
	158.4960	24.2313	11.2123	28.0452	14.0226	4.0413
	158.6760	24.2765	11.2062	28.1002	14.0501	4.0413
	158.8560	24.3213	11.1958	28.1548	14.0774	4.0413
	159.0360	24.3663	11.1965	28.2094	14.1047	4.0413
	159.2160	24.4113	11.1902	28.2642	14.1321	4.0413
	159.3960	24.4563	11.1852	28.3189	14.1595	4.0413
	159.5760	24.5014	11.1800	28.3738	14.1869	4.0413
	159.7560	24.5463	11.1660	28.4285	14.2142	4.0413
	159.9360	24.5913	11.1685	28.4832	14.2416	4.0413
	160.1160	24.6364	11.1525	28.5381	14.2690	4.0413
	160.2960	24.6814	11.1539	28.5927	14.2964	4.0413
	160.4760	24.7263	11.1527	28.6475	14.3237	4.0413
	160.6560	24.7714	11.1491	28.7023	14.3511	4.0413
	160.8360	24.8163	11.1488	28.7569	14.3785	4.0413
	161.0160	24.8616	11.1512	28.8120	14.4060	4.0413
	161.1960	24.9063	11.1492	28.8664	14.4332	4.0413
	161.3760	24.9515	11.1477	28.9214	14.4607	4.0413
	161.5560	24.9963	11.1437	28.9759	14.4880	4.0413
	161.7360	25.0413	11.1425	29.0306	14.5153	4.0413
	161.9160	25.0864	11.1407	29.0855	14.5427	4.0413
	162.0960	25.1313	11.1429	29.1402	14.5701	4.0413
	162.2760	25.1763	11.1480	29.1948	14.5974	4.0413
	162.4560	25.2213	11.1458	29.2496	14.6248	4.0413
	162.6360	25.2663	11.1444	29.3043	14.6522	4.0413
	162.8160	25.3114	11.1463	29.3592	14.6796	4.0413
	162.9960	25.3563	11.1475	29.4139	14.7069	4.0413
	163.1760	25.4014	11.1461	29.4687	14.7343	4.0413
	163.3560	25.4465	11.1466	29.5236	14.7618	4.0413
	163.5360	25.4913	11.1472	29.5780	14.7890	4.0413
	163.7160	25.5366	11.1482	29.6331	14.8166	4.0413
	163.8960	25.5813	11.1466	29.6876	14.8438	4.0413
	164.0760	25.6265	11.1473	29.7426	14.8713	4.0413
	164.2560	25.6713	11.1446	29.7970	14.8985	4.0413
	164.4360	25.7164	11.1410	29.8519	14.9259	4.0413
	164.6160	25.7614	11.1451	29.9066	14.9533	4.0413
	164.7960	25.8063	11.1443	29.9613	14.9806	4.0413
	164.9760	25.8513	11.1487	30.0160	15.0080	4.0413
	165.1560	25.8964	11.1451	30.0708	15.0354	4.0413
	165.3360	25.9413	11.1459	30.1255	15.0628	4.0413
	165.5160	25.9864	11.1449	30.1803	15.0902	4.0413
	165.6960	26.0313	11.1449	30.2351	15.1175	4.0413
	165.8760	26.0764	11.1455	30.2898	15.1449	4.0413
	166.0560	26.1214	11.1435	30.3447	15.1723	4.0413
	166.2360	26.1663	11.1423	30.3992	15.1996	4.0413
	166.4160	26.2116	11.1390	30.4543	15.2272	4.0413
	166.5960	26.2564	11.1369	30.5088	15.2544	4.0413
	166.7760	26.3015	11.1352	30.5637	15.2819	4.0413
	166.9560	26.3463	11.1313	30.6182	15.3091	4.0413
	167.1360	26.3914	11.1272	30.6731	15.3365	4.0413
	167.3160	26.4364	11.1242	30.7278	15.3639	4.0413
	167.4960	26.4813	11.1208	30.7825	15.3912	4.0413
	167.6760	26.5263	11.1201	30.8372	15.4186	4.0413
	167.8560	26.5714	11.1171	30.8920	15.4460	4.0413
	168.0360	26.6162	11.1159	30.9465	15.4733	4.0413
	168.2160	26.6613	11.1137	31.0014	15.5007	4.0413
	168.3960	26.7063	11.1111	31.0562	15.5281	4.0413
	168.5760	26.7514	11.1105	31.1110	15.5555	4.0413
	168.7560	26.7964	11.1072	31.1658	15.5829	4.0413
	168.9360	26.8413	11.1052	31.2204	15.6102	4.0413
	169.1160	26.8866	11.1024	31.2755	15.6377	4.0413
	169.2960	26.9313	11.0989	31.3299	15.6650	4.0413
	169.4760	26.9765	11.0923	31.3849	15.6924	4.0413
	169.6560	27.0213	11.0687	31.4394	15.7197	4.0413
	169.8360	27.0664	11.0592	31.4942	15.7471	4.0413
	170.0160	27.1113	11.0539	31.5489	15.7745	4.0413
	170.1960	27.1563	11.0452	31.6036	15.8018	4.0413
	170.3760	27.2014	11.0419	31.6584	15.8292	4.0413
	170.5560	27.2464	11.0359	31.7132	15.8566	4.0413
	170.7360	27.2912	11.0300	31.7677	15.8839	4.0413
	170.9160	27.3364	11.0171	31.8227	15.9114	4.0413
	171.0960	27.3814	11.0041	31.8774	15.9387	4.0413
	171.2760	27.4264	10.9975	31.9322	15.9661	4.0413
	171.4560	27.4714	10.9880	31.9869	15.9935	4.0413
	171.6360	27.5163	10.9753	32.0416	16.0208	4.0413
	171.8160	27.5616	10.9651	32.0967	16.0483	4.0413
	171.9960	27.6063	10.9506	32.1511	16.0755	4.0413
	172.1760	27.6515	10.9349	32.2061	16.1030	4.0413
	172.3560	27.6964	10.9226	32.2607	16.1303	4.0413
	172.5360	27.7414	10.9021	32.3154	16.1577	4.0413
	172.7160	27.7864	10.8856	32.3701	16.1851	4.0413
	172.8960	27.8313	10.8660	32.4248	16.2124	4.0413
	173.0760	27.8764	10.8426	32.4797	16.2399	4.0413
	173.2560	27.9213	10.8215	32.5343	16.2672	4.0413
	173.4360	27.9663	10.7931	32.5890	16.2945	4.0413
	173.6160	28.0114	10.7641	32.6439	16.3219	4.0413
	173.7960	28.0564	10.7305	32.6986	16.3493	4.0413
	173.9760	28.1013	10.6909	32.7533	16.3766	4.0413
	174.1560	28.1465	10.6453	32.8082	16.4041	4.0413
	174.3360	28.1914	10.5932	32.8628	16.4314	4.0413
	174.5160	28.2366	10.5317	32.9178	16.4589	4.0413
	174.6960	28.2814	10.4598	32.9723	16.4862	4.0413
	174.8760	28.3266	10.3760	33.0273	16.5137	4.0413
	175.0560	28.3713	10.2758	33.0818	16.5409	4.0413
	175.2360	28.4164	10.1557	33.1366	16.5683	4.0413
	175.4160	28.4615	10.0109	33.1914	16.5957	4.0413
	175.5960	28.5065	9.8264	33.2461	16.6231	4.0413
	175.7310	28.5462	5.7781	33.2945	16.6472	4.0413