File: P2_Plasticity/S_comp.csv
True Plastic Strain (-)	 True Stress (MPa)
0.0	145.625
0.002	165.3046850069680
0.004	184.45447069906900
0.006	203.0886252560930
0.008	221.2210326698380
0.01	238.86520308883300
0.012	256.03428288452200
0.014	272.74106444640200
0.016	288.9979957134160
0.018000000000000000	304.81718944869700
0.02	320.21043226458500
0.022	335.18919340463200
0.024	349.7646332891380
0.026000000000000000	363.9476118305910
0.028	377.7486965252060
0.03	391.1781703265820
0.032	404.24603930735900
0.034	416.9620401145750
0.036000000000000000	429.3356472242690
0.038	441.3760800007590
0.04	453.0923095658310
0.042	464.4930654829680
0.044	475.58684226160100
0.046	486.3819056862260
0.048	496.88629897509100
0.05	507.1078487730740
0.052000000000000000	517.0541709831700
0.054	526.73267644098
0.056	536.1505764363950
0.058	545.3148880866060
0.06	554.2324395644390
0.062	562.9098751859090
0.064	571.3536603607890
0.066	579.5700864098780
0.068	587.5652752525510
0.07	595.3451839681050
0.07200000000000000	602.915609234273
0.074	610.2821916462300
0.076	617.4504199193060
0.078	624.4256349785330
0.08	631.2130339380810
0.082	637.817673973535
0.084	644.2444760899120
0.08600000000000000	650.4982287882180
0.088	656.5835916332830
0.09	662.5050987255150
0.092	668.2671620791890
0.094	673.8740749097610
0.096	679.3300148326670
0.098	684.6390469759980
0.1	689.8051270093570
0.10200000000000000	694.8321040911550
0.10400000000000000	699.7237237365650
0.106	704.4836306082290
0.108	709.1153712318450
0.11	713.6223966386150
0.112	718.0080649365560
0.114	722.275643812562
0.116	726.42831296711
0.11800000000000000	730.4691664833950
0.12	734.4012151326820
0.122	738.2273886175780
0.124	741.9505377549040
0.126	745.5734365997940
0.128	749.0987845125890
0.13	752.5292081700940
0.132	755.8672635226600
0.134	759.1154376985870
0.136	762.2761508572370
0.138	765.3517579922560
0.14	768.3445506862370
0.14200000000000000	771.2567588181430
0.14400000000000000	774.0905522247470
0.146	776.848042317344
0.148	779.5312836549280
0.15	782.1422754750070
0.152	784.6829631832020
0.154	787.1552398027340
0.156	789.5609473848860
0.158	791.9018783814820
0.16	794.179776980416
0.162	796.3963404052100
0.164	798.5532201795930
0.166	800.65202335802
0.168	802.6943137230610
0.17	804.6816129505500
0.17200000000000000	806.6154017433600
0.17400000000000000	808.4971209346470
0.176	810.3281725613930
0.178	812.1099209090390
0.18	813.8436935279900
0.182	815.5307822227530
0.184	817.1724440144360
0.186	818.7699020773310
0.188	820.3243466502880
0.19	821.8369359235320
0.192	823.3087969016180
0.194	824.7410262431420
0.196	826.134691077839
0.198	827.490829801686
0.2	828.8104528505930
0.202	830.0945434532620
0.20400000000000000	831.3440583637720
0.20600000000000000	832.5599285744430
0.20800000000000000	833.7430600095000
0.21	834.8943342000620
0.212	836.0146089409590
0.214	837.1047189298570
0.216	838.1654763891770
0.218	839.1976716712700
0.22	840.2020738472950
0.222	841.1794312802390
0.224	842.1304721825110
0.226	843.0559051585210
0.228	843.9564197326470
0.23	844.8326868629920
0.232	845.6853594412970
0.234	846.5150727794060
0.23600000000000000	847.322445082624
0.23800000000000000	848.1080779103290
0.24	848.8725566241850
0.242	849.6164508242870
0.244	850.3403147735580
0.246	851.0446878107210
0.248	851.7300947521530
0.25	852.3970462829140
0.252	853.0460393372530
0.254	853.6775574688620
0.256	854.2920712111660
0.258	854.8900384279070
0.26	855.4719046542950
0.262	856.0381034289630
0.264	856.5890566169930
0.266	857.1251747242400
0.268	857.6468572031930
0.27	858.1544927505980
0.272	858.6484595970720
0.274	859.1291257889150
0.276	859.5968494623370
0.278	860.0519791102950
0.28	860.4948538421540
0.28200000000000000	860.9258036363470
0.28400000000000000	861.34514958624
0.28600000000000000	861.7532041393730
0.28800000000000000	862.1502713302560
0.29	862.536647006903
0.292	862.9126190512630
0.294	863.2784675937160
0.296	863.6344652217900
0.298	863.9808771832670
0.3	864.3179615838110
0.302	864.6459695792790
0.304	864.9651455628520
0.306	865.2757273471290
0.308	865.5779463413190
0.31	865.8720277236570
0.312	866.1581906091820
0.314	866.4366482129940
0.316	866.7076080091220
0.318	866.9712718851030
0.32	867.2278362924100
0.322	867.4774923928200
0.324	867.7204262008500
0.326	867.9568187223510
0.328	868.1868460893720
0.33	868.4106796913940
0.332	868.6284863030300
0.334	868.8404282082820
0.336	869.0466633214620
0.338	869.247345304846
0.34	869.4426236831700
0.342	869.6326439550320
0.34400000000000000	869.8175477013090
0.34600000000000000	869.9974726906370
0.34800000000000000	870.1725529820670
0.35000000000000000	870.3429190249500
0.352	870.508697756126
0.354	870.6700126945110
0.356	870.8269840331240
0.358	870.9797287286390
0.36	871.1283605885330
0.362	871.2729903558790
0.364	871.4137257918580
0.366	871.5506717560490
0.368	871.6839302845640
0.37	871.8136006660670
0.372	871.9397795157550
0.374	872.0625608473430
0.376	872.182036143115
0.378	872.2982944220830
0.38	872.411422306313
0.382	872.5215040854700
0.384	872.6286217796160
0.386	872.7328552003230
0.388	872.8342820101420
0.39	872.932977780465
0.392	873.0290160478320
0.394	873.1224683687240
0.396	873.2134043728760
0.398	873.3018918151590
0.4	873.3879966260620
0.402	873.4717829608170
0.404	873.553313247197
0.406	873.6326482320320
0.40800000000000000	873.7098470264710
0.41000000000000000	873.7849671500240
0.41200000000000000	873.8580645734170
0.41400000000000000	873.9291937602980
0.41600000000000000	873.9984077078150
0.418	874.0657579861030
0.42	874.1312947767110
0.422	874.1950669099870
0.424	874.2571219014630
0.426	874.3175059872590
0.428	874.3762641585300
0.43	874.4334401949920
0.432	874.4890766975350
0.434	874.5432151199750
0.436	874.595895799927
0.438	874.6471579888720
0.44	874.6970398813950
0.442	874.745578643646
0.444	874.792810441032
0.446	874.8387704651620
0.448	874.8834929600690
0.45	874.927011247724
0.452	874.9693577528630
0.454	875.0105640271460
0.456	875.0506607726700
0.458	875.089677864836
0.46	875.1276443746180
0.462	875.1645885902150
0.464	875.2005380381360
0.466	875.2355195037030
0.468	875.269559051011
0.47000000000000000	875.3026820423480
0.47200000000000000	875.3349131570920
0.47400000000000000	875.366276410099
0.47600000000000000	875.3967951695950
0.47800000000000000	875.4264921745900
0.48	875.4553895518160
0.482	875.4835088322180
0.484	875.5108709669950
0.486	875.5374963432080
0.488	875.563404798971
0.49	875.5886156382350
0.492	875.6131476451680
0.494	875.6370190981510
0.496	875.6602477833980
0.498	875.6828510082070
0.5	875.7048456138570
0.502	875.7262479881550
0.504	875.7470740776450
0.506	875.7673393994940
0.508	875.7870590530480
0.51	875.8062477310860
0.512	875.8249197307650
0.514	875.843088964275
0.516	875.8607689692030
0.518	875.8779729186210
0.52	875.8947136308980
0.522	875.911003579254
0.524	875.9268549010540
0.526	875.9422794068470
0.528	875.9572885891710
0.53	875.9718936311120
0.532	875.9861054146400
0.534	875.9999345287110
0.536	876.0133912771640
0.538	876.0264856863930
0.54	876.0392275128210
0.542	876.051626250165
0.544	876.0636911365140
0.546	876.0754311612090
0.548	876.0868550715440
0.55	876.0979713792800
0.552	876.1087883669880
0.554	876.1193140942230
0.556	876.1295564035250
0.558	876.1395229262640
0.56	876.149221088327
0.562	876.1586581156500
0.5640000000000000	876.167841039601
0.5660000000000000	876.176776702221
0.5680000000000000	876.1854717613200
0.5700000000000000	876.1939326954400
0.5720000000000000	876.2021658086770
0.5740000000000000	876.2101772353860
0.5760000000000000	876.2179729447420
0.578	876.2255587451990
0.58	876.2329402888050
0.582	876.2401230754240
0.584	876.2471124568290
0.586	876.2539136406880
0.588	876.2605316944470
0.59	876.2669715491070
0.592	876.273238002893
0.594	876.2793357248340
0.596	876.2852692582380
0.598	876.291043024081
0.6	876.296661324297
0.602	876.3021283449860
0.604	876.3074481595330
0.606	876.3126247316400
0.608	876.3176619182840
0.61	876.3225634725870
0.612	876.3273330466140
0.614	876.3319741940920
0.616	876.336490373063
0.618	876.3408849484540
0.62	876.3451611945890
0.622	876.3493222976260
0.624	876.3533713579330
0.626	876.3573113923940
0.628	876.3611453366640
0.63	876.364876047348
0.632	876.368506304136
0.634	876.3720388118700
0.636	876.3754762025630
0.638	876.3788210373540
0.64	876.3820758084240
0.642	876.3852429408480
0.644	876.3883247944020
0.646	876.3913236653220
0.648	876.3942417880160
0.65	876.3970813367280
0.652	876.3998444271580
0.654	876.4025331180370
0.656	876.405149412663
0.658	876.4076952603930
0.66	876.4101725580940
0.662	876.4125831515590
0.664	876.41492883688
0.666	876.4172113617880
0.668	876.4194324269520
0.67	876.4215936872510
0.672	876.4236967530040
0.674	876.425743191168
0.676	876.42773452651
0.678	876.42967224274
0.68	876.4315577836170
0.682	876.433392554027
0.684	876.4351779210250
0.686	876.4369152148570
0.6880000000000000	876.4386057299520
0.6900000000000000	876.4402507258850
0.6920000000000000	876.4418514283130
0.6940000000000000	876.4434090298920
0.6960000000000000	876.444924691165
0.6980000000000000	876.4463995414260
0.7000000000000000	876.4478346795600
0.7020000000000000	876.4492311748650
0.704	876.4505900678450
0.706	876.4519123709890
0.708	876.4531990695210
0.71	876.4544511221400
0.712	876.4556694617270
0.714	876.4568549960490
0.716	876.4580086084250
0.718	876.4591311583930
0.72	876.4602234823460
0.722	876.4612863941550
0.724	876.4623206857790
0.726	876.4633271278500
0.728	876.4643064702520
0.73	876.4652594426750
0.732	876.4661867551630
0.734	876.4670890986420
0.736	876.4679671454310
0.738	876.4688215497490
0.74	876.4696529481970
0.742	876.4704619602360
0.744	876.4712491886490
0.746	876.4720152199840
0.748	876.4727606250000
0.75	876.4734859590840
0.752	876.4741917626710
0.754	876.4748785616420
0.756	876.4755468677220
0.758	876.4761971788510
0.76	876.4768299795680
0.762	876.4774457413590
0.764	876.4780449230200
0.766	876.4786279709910
0.768	876.4791953196890
0.77	876.4797473918380
0.772	876.4802845987770
0.774	876.4808073407700
0.776	876.4813160073020
0.778	876.4818109773720
0.78	876.4822926197750
0.782	876.4827612933740
0.784	876.48321734737
0.786	876.4836611215600
0.788	876.4840929465940
0.79	876.4845131442170
0.792	876.4849220275100
0.794	876.4853199011260
0.796	876.4857070615140
0.798	876.4860837971410
0.8	876.4864503887050
0.802	876.4868071093480
0.804	876.4871542248570
0.806	876.4874919938600
0.808	876.487820668025
0.81	876.4881404922410
0.812	876.4884517048020
0.8140000000000000	876.4887545375900
0.8160000000000000	876.4890492162380
0.8180000000000000	876.4893359603070
0.8200000000000000	876.4896149834460
0.8220000000000000	876.489886493549
0.8240000000000000	876.4901506929140
0.8260000000000000	876.4904077783920
0.8280000000000000	876.490657941533
0.8300000000000000	876.4909013687290
0.8320000000000000	876.4911382413530
0.834	876.4913687358950
0.836	876.4915930240930
0.838	876.4918112730600
0.84	876.4920236454090
0.842	876.4922302993760
0.844	876.4924313889360
0.846	876.4926270639160
0.848	876.4928174701100
0.85	876.4930027493880
0.852	876.4931830397960
0.854	876.4933584756680
0.856	876.4935291877170
0.858	876.4936953031370
0.86	876.4938569456980
0.862	876.4940142358390
0.864	876.4941672907520
0.866	876.4943162244760
0.868	876.4944611479800
0.87	876.4946021692430
0.872	876.4947393933390
0.874	876.4948729225090
0.876	876.4950028562450
0.878	876.4951292913590
0.88	876.4952523220530
0.882	876.495372039998
0.884	876.4954885343920
0.886	876.4956018920340
0.888	876.4957121973840
0.89	876.4958195326300
0.892	876.4959239777440
0.894	876.4960256105470
0.896	876.4961245067640
0.898	876.4962207400800
0.9	876.4963143821990
0.902	876.4964055028900
0.904	876.4964941700460
0.906	876.4965804497320
0.908	876.496664406233
0.91	876.4967461021040
0.912	876.4968255982140
0.914	876.4969029537960
0.916	876.496978226485
0.918	876.497051472366
0.92	876.497122746013
0.922	876.4971921005310
0.924	876.4972595875950
0.926	876.4973252574870
0.928	876.497389159139
0.93	876.4974513401610
0.932	876.4975118468840
0.934	876.4975707243910
0.936	876.4976280165490
0.9380000000000000	876.4976837660470
0.9400000000000000	876.4977380144220
0.9420000000000000	876.4977908020940
0.9440000000000000	876.4978421683940
0.9460000000000000	876.4978921515950
0.9480000000000000	876.4979407889370
0.9500000000000000	876.49798811666
0.9520000000000000	876.4980341700270
0.9540000000000000	876.4980789833510
0.9560000000000000	876.4981225900230
0.9580000000000000	876.4981650225320
0.96	876.4982063124940
0.962	876.498246490674
0.964	876.4982855870080
0.966	876.4983236306260
0.968	876.4983606498740
0.97	876.4983966723330
0.972	876.4984317248450
0.974	876.4984658335250
0.976	876.4984990237870
0.978	876.4985313203620
0.98	876.4985627473130
0.982	876.4985933280540
0.984	876.4986230853720
0.986	876.4986520414390
0.988	876.4986802178280
0.99	876.4987076355340
0.992	876.4987343149850
0.994	876.4987602760600
0.996	876.4987855381010
0.998	876.4988101199320
1.0	876.4988340398670
1.002	876.4988573157280
1.004	876.4988799648590
1.006	876.498902004135
1.008	876.4989234499760
1.01	876.4989443183630
1.012	876.4989646248430
1.014	876.4989843845460
1.016	876.4990036121950
1.018	876.4990223221170
1.02	876.4990405282510
1.022	876.4990582441640
1.024	876.4990754830530
1.026	876.4990922577650
1.028	876.4991085807980
1.03	876.4991244643130
1.032	876.4991399201450
1.034	876.4991549598100
1.036	876.4991695945150
1.038	876.4991838351620
1.04	876.4991976923620
1.042	876.4992111764400
1.044	876.4992242974440
1.046	876.4992370651480
1.048	876.499249489067
1.05	876.4992615784570
1.052	876.4992733423250
1.054	876.4992847894360
1.056	876.4992959283210
1.058	876.4993067672770
1.06	876.499317314382
1.062	876.4993275774930
1.064	876.4993375642570
1.066	876.4993472821160
1.068	876.4993567383090
1.07	876.4993659398830
1.072	876.4993748936940
1.074	876.4993836064120
1.076	876.4993920845300
1.078	876.4994003343640
1.08	876.499408362062
1.082	876.4994161736040
1.084	876.4994237748110
1.086	876.4994311713460
1.088	876.4994383687210
1.09	876.4994453722970
1.092	876.499452187294
1.094	876.4994588187890
1.096	876.4994652717220
1.098	876.4994715509030
1.1	876.4994776610090
1.102	876.4994836065930
1.104	876.4994893920850
1.106	876.4994950217960
1.108	876.4995004999200
1.11	876.499505830539
1.112	876.4995110176250
1.114	876.4995160650420
1.116	876.4995209765510
1.118	876.4995257558110
1.12	876.4995304063850
1.122	876.4995349317360
1.124	876.4995393352370
1.1260000000000000	876.4995436201680
1.1280000000000000	876.4995477897220
1.1300000000000000	876.4995518470050
1.1320000000000000	876.4995557950420
1.1340000000000000	876.4995596367730
1.1360000000000000	876.4995633750600
1.1380000000000000	876.4995670126900
1.1400000000000000	876.499570552372
1.1420000000000000	876.4995739967440
1.1440000000000000	876.4995773483720
1.1460000000000000	876.4995806097530
1.1480000000000000	876.499583783318
1.1500000000000000	876.4995868714310
1.1520000000000000	876.4995898763920
1.154	876.4995928004410
1.156	876.499595645757
1.158	876.4995984144590
1.16	876.4996011086110
1.162	876.4996037302190
1.164	876.4996062812370
1.166	876.4996087635660
1.168	876.4996111790550
1.17	876.4996135295050
1.172	876.4996158166650
1.174	876.4996180422410
1.176	876.4996202078910
1.178	876.4996223152280
1.18	876.4996243658230
1.182	876.4996263612020
1.184	876.4996283028540
1.186	876.499630192224
1.188	876.4996320307210
1.19	876.4996338197140
1.192	876.499635560536
1.194	876.4996372544850
1.196	876.4996389028210
1.198	876.4996405067750
1.2	876.4996420675400
1.202	876.4996435862790
1.204	876.4996450641250
1.206	876.4996465021780
1.208	876.4996479015090
1.21	876.499649263162
1.212	876.4996505881510
1.214	876.4996518774620
1.216	876.4996531320580
1.218	876.4996543528720
1.22	876.499655540814
1.222	876.4996566967690
1.224	876.4996578215990
1.226	876.4996589161420
1.228	876.4996599812120
1.23	876.4996610176040
1.232	876.4996620260900
1.234	876.4996630074220
1.236	876.4996639623300
1.238	876.4996648915260
1.24	876.4996657957020
1.242	876.4996666755320
1.244	876.4996675316710
1.246	876.4996683647580
1.248	876.4996691754130
1.25	876.4996699642410
1.252	876.4996707318280
1.254	876.4996714787470
1.256	876.4996722055540
1.258	876.4996729127910
1.26	876.4996736009850
1.262	876.499674270648
1.264	876.49967492228
1.266	876.4996755563660
1.268	876.4996761733780
1.27	876.4996767737770
1.272	876.4996773580090
1.274	876.4996779265100
1.276	876.4996784797030
1.278	876.4996790180010
1.28	876.4996795418050
1.282	876.4996800515050
1.284	876.4996805474800
1.286	876.4996810301000
1.288	876.4996814997260
1.29	876.499681956706
1.292	876.4996824013820
1.294	876.4996828340840
1.296	876.4996832551350
1.298	876.4996836648480
1.3	876.49968406353
1.302	876.4996844514770
1.304	876.4996848289780
1.306	876.4996851963140
1.308	876.4996855537590
1.31	876.4996859015790
1.312	876.4996862400340
1.314	876.4996865693760
1.316	876.4996868898500
1.318	876.4996872016940
1.32	876.499687505142
1.322	876.4996878004190
1.324	876.4996880877460
1.326	876.4996883673360
1.328	876.4996886393970
1.33	876.4996889041330
1.332	876.4996891617410
1.334	876.4996894124120
1.336	876.4996896563330
1.338	876.499689893687
1.34	876.4996901246500
1.342	876.4996903493930
1.344	876.4996905680860
1.346	876.4996907808890
1.348	876.4996909879630
1.35	876.4996911894610
1.352	876.4996913855330
1.354	876.4996915763260
1.356	876.4996917619820
1.358	876.4996919426380
1.36	876.4996921184310
1.362	876.4996922894890
1.364	876.4996924559420
1.366	876.499692617913
1.368	876.4996927755230
1.37	876.4996929288880
1.372	876.4996930781240
1.374	876.4996932233420
1.3760000000000000	876.4996933646500
1.3780000000000000	876.4996935021530
1.3800000000000000	876.4996936359530
1.3820000000000000	876.4996937661510
1.3840000000000000	876.4996938928430
1.3860000000000000	876.4996940161230
1.3880000000000000	876.4996941360840
1.3900000000000000	876.4996942528150
1.3920000000000000	876.4996943664030
1.3940000000000000	876.4996944769330
1.3960000000000000	876.4996945844860
1.3980000000000000	876.499694689143
1.4000000000000000	876.4996947909820
1.4020000000000000	876.4996948900790
1.4040000000000000	876.4996949865080
1.4060000000000000	876.4996950803400
1.408	876.4996951716460
1.41	876.4996952604930
1.412	876.4996953469480
1.414	876.4996954310750
1.416	876.4996955129370
1.418	876.4996955925950
1.42	876.4996956701070
1.422	876.4996957455330
1.424	876.4996958189280
1.426	876.4996958903460
1.428	876.4996959598410
1.43	876.4996960274650
1.432	876.4996960932690
1.434	876.4996961573000
1.436	876.4996962196080
1.438	876.499696280237
1.44	876.4996963392340
1.442	876.4996963966430
1.444	876.4996964525050
1.446	876.4996965068640
1.448	876.4996965597590
1.45	876.4996966112290
1.452	876.4996966613140
1.454	876.4996967100500
1.456	876.4996967574740
1.458	876.499696803621
1.46	876.4996968485250
1.462	876.4996968922210
1.464	876.4996969347390
1.466	876.4996969761130
1.468	876.4996970163730
1.47	876.4996970555490
1.472	876.4996970936690
1.474	876.4996971307640
1.476	876.4996971668600
1.478	876.4996972019830
1.48	876.4996972361610
1.482	876.4996972694190
1.484	876.499697301781
1.486	876.4996973332720
1.488	876.4996973639150
1.49	876.4996973937320
1.492	876.4996974227470
1.494	876.4996974509810
1.496	876.4996974784540
1.498	876.4996975051880
1.5	876.4996975312020
1.502	876.4996975565150
1.504	876.4996975811470
1.506	876.4996976051150
1.508	876.4996976284390
1.51	876.4996976511340
1.512	876.4996976732180
1.514	876.499697694707
1.516	876.4996977156180
1.518	876.4996977359660
1.52	876.4996977557650
1.522	876.499697775032
1.524	876.49969779378
1.526	876.4996978120230
1.528	876.499697829775
1.53	876.4996978470490
1.532	876.4996978638580
1.534	876.4996978802140
1.536	876.4996978961300
1.538	876.4996979116170
1.54	876.499697926687
1.542	876.4996979413520
1.544	876.4996979556210
1.546	876.4996979695060
1.548	876.4996979830180
1.55	876.4996979961650
1.552	876.4996980089590
1.554	876.4996980214080
1.556	876.4996980335220
1.558	876.49969804531
1.56	876.4996980567800
1.562	876.4996980679420
1.564	876.4996980788030
1.566	876.4996980893710
1.568	876.4996980996550
1.57	876.4996981096620
1.572	876.4996981194
1.574	876.4996981288750
1.576	876.4996981380960
1.578	876.4996981470680
1.58	876.4996981557980
1.582	876.4996981642930
1.584	876.49969817256
1.586	876.4996981806040
1.588	876.4996981884310
1.59	876.499698196048
1.592	876.4996982034600
1.594	876.4996982106720
1.596	876.4996982176890
1.598	876.4996982245180
1.6	876.4996982311630
1.602	876.4996982376290
1.604	876.4996982439210
1.606	876.4996982500440
1.608	876.4996982560010
1.61	876.4996982617990
1.612	876.4996982674400
1.614	876.499698272929
1.616	876.4996982782700
1.618	876.499698283468
1.62	876.4996982885260
1.622	876.4996982934470
1.624	876.4996982982360
1.6260000000000000	876.4996983028960
1.6280000000000000	876.4996983074310
1.6300000000000000	876.4996983118430
1.6320000000000000	876.4996983161370
1.6340000000000000	876.4996983203150
1.6360000000000000	876.4996983243800
1.6380000000000000	876.4996983283360
1.6400000000000000	876.4996983321860
1.6420000000000000	876.4996983359320
1.6440000000000000	876.4996983395770
1.6460000000000000	876.4996983431240
1.6480000000000000	876.499698346575
1.6500000000000000	876.4996983499340
1.6520000000000000	876.4996983532010
1.6540000000000000	876.4996983563820
1.6560000000000000	876.4996983594760
1.6580000000000000	876.4996983624870
1.6600000000000000	876.499698365417
1.6620000000000000	876.499698368268
1.6640000000000000	876.4996983710420
1.666	876.499698373742
1.668	876.4996983763690
1.67	876.4996983789250
1.672	876.4996983814130
1.674	876.4996983838330
1.676	876.4996983861880
1.678	876.4996983884800
1.68	876.49969839071
1.682	876.4996983928800
1.684	876.4996983949920
1.686	876.4996983970460
1.688	876.4996983990460
1.69	876.4996984009910
1.692	876.4996984028850
1.694	876.4996984047270
1.696	876.4996984065200
1.698	876.4996984082640
1.7	876.4996984099610
1.702	876.4996984116130
1.704	876.4996984132200
1.706	876.4996984147840
1.708	876.4996984163060
1.71	876.4996984177870
1.712	876.4996984192280
1.714	876.4996984206300
1.716	876.4996984219940
1.718	876.499698423322
1.72	876.4996984246140
1.722	876.4996984258710
1.724	876.4996984270940
1.726	876.4996984282850
1.728	876.499698429443
1.73	876.4996984305700
1.732	876.499698431667
1.734	876.4996984327340
1.736	876.4996984337730
1.738	876.4996984347830
1.74	876.4996984357670
1.742	876.4996984367230
1.744	876.4996984376540
1.746	876.4996984385610
1.748	876.499698439442
1.75	876.4996984403
1.752	876.4996984411350
1.754	876.499698441947
1.756	876.4996984427370
1.758	876.4996984435070
1.76	876.499698444255
1.762	876.4996984449830
1.764	876.499698445692
1.766	876.4996984463820
1.768	876.4996984470530
1.77	876.4996984477060
1.772	876.499698448341
1.774	876.4996984489590
1.776	876.4996984495610
1.778	876.4996984501460
1.78	876.4996984507160
1.782	876.4996984512700
1.784	876.4996984518100
1.786	876.4996984523340
1.788	876.4996984528450
1.79	876.4996984533420
1.792	876.4996984538260
1.794	876.4996984542960
1.796	876.4996984547540
1.798	876.4996984552000
1.8	876.4996984556330
1.802	876.4996984560550
1.804	876.4996984564660
1.806	876.4996984568650
1.808	876.4996984572540
1.81	876.4996984576320
1.812	876.4996984580010
1.814	876.4996984583590
1.816	876.4996984587070
1.818	876.4996984590460
1.82	876.4996984593760
1.822	876.4996984596980
1.824	876.4996984600100
1.826	876.499698460314
1.828	876.4996984606100
1.83	876.4996984608980
1.832	876.4996984611780
1.834	876.4996984614510
1.836	876.4996984617160
1.838	876.4996984619740
1.84	876.4996984622250
1.842	876.4996984624700
1.844	876.4996984627070
1.846	876.4996984629390
1.848	876.499698463164
1.85	876.4996984633830
1.852	876.4996984635960
1.854	876.4996984638040
1.856	876.4996984640060
1.858	876.4996984642020
1.86	876.4996984643930
1.862	876.4996984645790
1.864	876.4996984647600
1.866	876.4996984649370
1.868	876.4996984651080
1.87	876.4996984652750
1.872	876.4996984654370
1.874	876.499698465595
1.8760000000000000	876.4996984657490
1.8780000000000000	876.4996984658980
1.8800000000000000	876.4996984660440
1.8820000000000000	876.4996984661860
1.8840000000000000	876.4996984663230
1.8860000000000000	876.4996984664570
1.8880000000000000	876.4996984665880
1.8900000000000000	876.4996984667150
1.8920000000000000	876.4996984668380
1.8940000000000000	876.4996984669580
1.8960000000000000	876.4996984670750
1.8980000000000000	876.4996984671890
1.9000000000000000	876.4996984673000
1.9020000000000000	876.4996984674080
1.9040000000000000	876.4996984675130
1.9060000000000000	876.4996984676150
1.9080000000000000	876.4996984677140
1.9100000000000000	876.4996984678110
1.9120000000000000	876.4996984679050
1.9140000000000000	876.499698467996
1.9160000000000000	876.4996984680850
1.9180000000000000	876.4996984681720
1.92	876.499698468256
1.922	876.499698468338
1.924	876.4996984684180
1.926	876.4996984684960
1.928	876.4996984685710
1.93	876.4996984686450
1.932	876.4996984687160
1.934	876.4996984687860
1.936	876.4996984688540
1.938	876.4996984689200
1.94	876.4996984689840
1.942	876.4996984690460
1.944	876.4996984691070
1.946	876.499698469166
1.948	876.4996984692240
1.95	876.4996984692800
1.952	876.4996984693340
1.954	876.499698469387
1.956	876.4996984694390
1.958	876.4996984694890
1.96	876.4996984695380
1.962	876.499698469585
1.964	876.4996984696310
1.966	876.4996984696760
1.968	876.4996984697200
1.97	876.4996984697630
1.972	876.4996984698040
1.974	876.4996984698450
1.976	876.4996984698840
1.978	876.499698469922
1.98	876.4996984699590
1.982	876.4996984699950
1.984	876.4996984700310
1.986	876.4996984700650
1.988	876.4996984700980
1.99	876.4996984701310
1.992	876.4996984701620
1.994	876.4996984701930
1.996	876.4996984702230
1.998	876.4996984702520
2.0	876.49969847028