File: P2_Plasticity/Steel.csv
Tensile strain (Strain 1) : Primary source		Strain 1

Results Table 1
	Tensile strain (Strain 1) gauge length	Strain 1 gauge length	Time at removal
	(mm)	(mm)	(s)
1	50.00	50.00	54.04
2	50.00	50.00	54.04
3	50.00	50.00	54.04

Results Table 2


1	Time	Displacement	Force	Tensile strain (Strain 1)	Tensile displacement	Strain 1
	(s)	(mm)	(kN)	(%)	(mm)	(%)
	0.0000	0.0000	0.0186	0.0000	0.0000	0.0000
	0.2200	0.0145	0.0617	0.0012	0.0006	0.0012
	0.4400	0.0329	0.1871	0.0041	0.0020	0.0041
	0.6600	0.0511	0.3511	0.0076	0.0038	0.0076
	0.8800	0.0694	0.5227	0.0113	0.0057	0.0113
	1.1000	0.0877	0.6834	0.0149	0.0074	0.0149
	1.3200	0.1060	0.8277	0.0181	0.0090	0.0181
	1.5400	0.1244	0.9669	0.0212	0.0106	0.0212
	1.7600	0.1430	1.0977	0.0242	0.0121	0.0242
	1.9800	0.1610	1.2131	0.0269	0.0134	0.0269
	2.2000	0.1793	1.3284	0.0296	0.0148	0.0296
	2.4200	0.1978	1.4477	0.0324	0.0162	0.0324
	2.6400	0.2160	1.5701	0.0352	0.0176	0.0352
	2.8600	0.2344	1.6973	0.0382	0.0191	0.0382
	3.0800	0.2528	1.8274	0.0412	0.0206	0.0412
	3.3000	0.2711	1.9642	0.0444	0.0222	0.0444
	3.5200	0.2894	2.1010	0.0476	0.0238	0.0476
	3.7400	0.3079	2.2434	0.0509	0.0255	0.0509
	3.9600	0.3261	2.3881	0.0543	0.0271	0.0543
	4.1800	0.3443	2.5328	0.0577	0.0289	0.0577
	4.4000	0.3625	2.6814	0.0611	0.0306	0.0611
	4.6200	0.3812	2.8330	0.0647	0.0324	0.0647
	4.8400	0.3994	2.9799	0.0683	0.0342	0.0683
	5.0600	0.4176	3.1274	0.0719	0.0360	0.0719
	5.2800	0.4362	3.2793	0.0758	0.0379	0.0758
	5.5000	0.4543	3.4283	0.0796	0.0398	0.0796
	5.7200	0.4728	3.5819	0.0837	0.0418	0.0837
	5.9400	0.4912	3.7311	0.0877	0.0439	0.0877
	6.1600	0.5094	3.8850	0.0920	0.0460	0.0920
	6.3800	0.5277	4.0353	0.0964	0.0482	0.0964
	6.6000	0.5460	4.1835	0.1010	0.0505	0.1010
	6.8200	0.5645	4.3375	0.1058	0.0529	0.1058
	7.0400	0.5828	4.4855	0.1107	0.0553	0.1107
	7.2600	0.6008	4.6327	0.1158	0.0579	0.1158
	7.4800	0.6195	4.7852	0.1213	0.0606	0.1213
	7.7000	0.6378	4.9321	0.1269	0.0634	0.1269
	7.9200	0.6560	5.0753	0.1327	0.0664	0.1327
	8.1400	0.6746	5.2211	0.1388	0.0694	0.1388
	8.3600	0.6928	5.3620	0.1453	0.0726	0.1453
	8.5800	0.7110	5.5008	0.1519	0.0759	0.1519
	8.8000	0.7297	5.6381	0.1589	0.0794	0.1589
	9.0200	0.7477	5.7701	0.1661	0.0831	0.1661
	9.2400	0.7660	5.8990	0.1738	0.0869	0.1738
	9.4600	0.7844	6.0227	0.1817	0.0908	0.1817
	9.6800	0.8028	6.1457	0.1901	0.0951	0.1901
	9.9000	0.8212	6.2635	0.1991	0.0995	0.1991
	10.1200	0.8393	6.3727	0.2083	0.1041	0.2083
	10.3400	0.8578	6.4800	0.2182	0.1091	0.2182
	10.5600	0.8762	6.5820	0.2286	0.1143	0.2286
	10.7800	0.8945	6.6743	0.2397	0.1198	0.2397
	11.0000	0.9128	6.7617	0.2513	0.1257	0.2513
	11.2200	0.9312	6.8463	0.2637	0.1318	0.2637
	11.4400	0.9493	6.9189	0.2766	0.1383	0.2766
	11.6600	0.9677	6.9888	0.2902	0.1451	0.2902
	11.8800	0.9864	7.0559	0.3047	0.1523	0.3047
	12.1000	1.0043	7.1079	0.3194	0.1597	0.3194
	12.3200	1.0226	7.1607	0.3348	0.1674	0.3348
	12.5400	1.0411	7.2086	0.3507	0.1754	0.3507
	12.7600	1.0595	7.2531	0.3674	0.1837	0.3674
	12.9800	1.0778	7.2897	0.3843	0.1922	0.3843
	13.2000	1.0963	7.3257	0.4015	0.2008	0.4015
	13.4200	1.1145	7.3607	0.4193	0.2097	0.4193
	13.6400	1.1329	7.3895	0.4373	0.2186	0.4373
	13.8600	1.1513	7.4165	0.4555	0.2278	0.4555
	14.0800	1.1694	7.4439	0.4740	0.2370	0.4740
	14.3000	1.1878	7.4671	0.4925	0.2463	0.4925
	14.5200	1.2059	7.4894	0.5112	0.2556	0.5112
	14.7400	1.2246	7.5158	0.5300	0.2650	0.5300
	14.9600	1.2429	7.5333	0.5490	0.2745	0.5490
	15.1800	1.2611	7.5540	0.5679	0.2840	0.5679
	15.4000	1.2796	7.5726	0.5869	0.2935	0.5869
	15.6200	1.2978	7.5920	0.6061	0.3031	0.6061
	15.8400	1.3162	7.6104	0.6254	0.3127	0.6254
	16.0600	1.3345	7.6238	0.6445	0.3223	0.6445
	16.2800	1.3527	7.6448	0.6638	0.3319	0.6638
	16.5000	1.3712	7.6620	0.6831	0.3416	0.6831
	16.7200	1.3894	7.6751	0.7024	0.3512	0.7024
	16.9400	1.4080	7.6958	0.7220	0.3610	0.7220
	17.1600	1.4261	7.7077	0.7413	0.3706	0.7413
	17.3800	1.4443	7.7205	0.7607	0.3803	0.7607
	17.6000	1.4629	7.7407	0.7802	0.3901	0.7802
	17.8200	1.4812	7.7527	0.7997	0.3998	0.7997
	18.0400	1.4995	7.7662	0.8193	0.4096	0.8193
	18.2600	1.5180	7.7821	0.8387	0.4193	0.8387
	18.4800	1.5362	7.7956	0.8582	0.4291	0.8582
	18.7000	1.5544	7.8089	0.8776	0.4388	0.8776
	18.9200	1.5731	7.8225	0.8971	0.4485	0.8971
	19.1400	1.5910	7.8346	0.9164	0.4582	0.9164
	19.3600	1.6094	7.8488	0.9359	0.4680	0.9359
	19.5800	1.6277	7.8614	0.9553	0.4776	0.9553
	19.8000	1.6461	7.8753	0.9748	0.4874	0.9748
	20.0200	1.6646	7.8899	0.9943	0.4972	0.9943
	20.2400	1.6827	7.8987	1.0135	0.5068	1.0135
	20.4600	1.7012	7.9121	1.0330	0.5165	1.0330
	20.6800	1.7195	7.9265	1.0525	0.5262	1.0525
	20.9000	1.7379	7.9376	1.0720	0.5360	1.0720
	21.1200	1.7561	7.9474	1.0915	0.5457	1.0915
	21.3400	1.7746	7.9645	1.1110	0.5555	1.1110
	21.5600	1.7926	7.9731	1.1304	0.5652	1.1304
	21.7800	1.8112	7.9872	1.1499	0.5750	1.1499
	22.0000	1.8297	8.0009	1.1695	0.5848	1.1695
	22.2200	1.8477	8.0086	1.1888	0.5944	1.1888
	22.4400	1.8659	8.0205	1.2082	0.6041	1.2082
	22.6600	1.8846	8.0337	1.2276	0.6138	1.2276
	22.8800	1.9029	8.0457	1.2472	0.6236	1.2472
	23.1000	1.9212	8.0540	1.2665	0.6333	1.2665
	23.3200	1.9396	8.0662	1.2858	0.6429	1.2858
	23.5400	1.9578	8.0798	1.3052	0.6526	1.3052
	23.7600	1.9761	8.0892	1.3245	0.6623	1.3245
	23.9800	1.9945	8.0998	1.3439	0.6719	1.3439
	24.2000	2.0128	8.1129	1.3633	0.6816	1.3633
	24.4200	2.0310	8.1214	1.3825	0.6912	1.3825
	24.6400	2.0493	8.1343	1.4018	0.7009	1.4018
	24.8600	2.0680	8.1466	1.4213	0.7106	1.4213
	25.0800	2.0863	8.1562	1.4407	0.7204	1.4407
	25.3000	2.1044	8.1663	1.4599	0.7299	1.4599
	25.5200	2.1230	8.1777	1.4793	0.7396	1.4793
	25.7400	2.1411	8.1868	1.4986	0.7493	1.4986
	25.9600	2.1596	8.1998	1.5180	0.7590	1.5180
	26.1800	2.1778	8.2061	1.5373	0.7686	1.5373
	26.4000	2.1961	8.2210	1.5567	0.7783	1.5567
	26.6200	2.2145	8.2301	1.5759	0.7879	1.5759
	26.8400	2.2327	8.2386	1.5951	0.7976	1.5951
	27.0600	2.2513	8.2542	1.6146	0.8073	1.6146
	27.2800	2.2694	8.2596	1.6337	0.8168	1.6337
	27.5000	2.2876	8.2701	1.6529	0.8264	1.6529
	27.7200	2.3062	8.2820	1.6721	0.8361	1.6721
	27.9400	2.3246	8.2931	1.6914	0.8457	1.6914
	28.1600	2.3427	8.2995	1.7107	0.8553	1.7107
	28.3800	2.3613	8.3133	1.7298	0.8649	1.7298
	28.6000	2.3794	8.3218	1.7490	0.8745	1.7490
	28.8200	2.3978	8.3329	1.7683	0.8842	1.7683
	29.0400	2.4163	8.3424	1.7876	0.8938	1.7876
	29.2600	2.4344	8.3516	1.8068	0.9034	1.8068
	29.4800	2.4528	8.3623	1.8261	0.9130	1.8261
	29.7000	2.4710	8.3706	1.8451	0.9226	1.8451
	29.9200	2.4895	8.3833	1.8644	0.9322	1.8644
	30.1400	2.5080	8.3936	1.8838	0.9419	1.8838
	30.3600	2.5260	8.3991	1.9027	0.9514	1.9027
	30.5800	2.5445	8.4112	1.9219	0.9610	1.9219
	30.8000	2.5629	8.4226	1.9412	0.9706	1.9412
	31.0200	2.5812	8.4302	1.9603	0.9802	1.9603
	31.2400	2.5994	8.4379	1.9795	0.9897	1.9795
	31.4600	2.6179	8.4515	1.9986	0.9993	1.9986
	31.6800	2.6360	8.4588	2.0177	1.0088	2.0177
	31.9000	2.6544	8.4684	2.0367	1.0184	2.0367
	32.1200	2.6730	8.4815	2.0560	1.0280	2.0560
	32.3400	2.6910	8.4875	2.0750	1.0375	2.0750
	32.5600	2.7094	8.4973	2.0941	1.0470	2.0941
	32.7800	2.7278	8.5063	2.1132	1.0566	2.1132
	33.0000	2.7463	8.5193	2.1324	1.0662	2.1324
	33.2200	2.7646	8.5254	2.1516	1.0758	2.1516
	33.4400	2.7829	8.5337	2.1706	1.0853	2.1706
	33.6600	2.8012	8.5472	2.1897	1.0949	2.1897
	33.8800	2.8195	8.5541	2.2088	1.1044	2.2088
	34.1000	2.8378	8.5632	2.2280	1.1140	2.2280
	34.3200	2.8561	8.5732	2.2470	1.1235	2.2470
	34.5400	2.8745	8.5821	2.2661	1.1330	2.2661
	34.7600	2.8926	8.5900	2.2850	1.1425	2.2850
	34.9800	2.9113	8.6029	2.3041	1.1520	2.3041
	35.2000	2.9296	8.6093	2.3232	1.1616	2.3232
	35.4200	2.9479	8.6194	2.3422	1.1711	2.3422
	35.6400	2.9662	8.6261	2.3611	1.1805	2.3611
	35.8600	2.9845	8.6381	2.3802	1.1901	2.3802
	36.0800	3.0029	8.6475	2.3992	1.1996	2.3992
	36.3000	3.0210	8.6513	2.4181	1.2090	2.4181
	36.5200	3.0394	8.6666	2.4372	1.2186	2.4372
	36.7400	3.0578	8.6745	2.4561	1.2280	2.4561
	36.9600	3.0760	8.6806	2.4751	1.2375	2.4751
	37.1800	3.0946	8.6950	2.4942	1.2471	2.4942
	37.4000	3.1128	8.7008	2.5131	1.2565	2.5131
	37.6200	3.1310	8.7076	2.5321	1.2661	2.5321
	37.8400	3.1496	8.7198	2.5511	1.2755	2.5511
	38.0600	3.1679	8.7275	2.5701	1.2850	2.5701
	38.2800	3.1862	8.7358	2.5892	1.2946	2.5892
	38.5000	3.2046	8.7445	2.6080	1.3040	2.6080
	38.7200	3.2228	8.7542	2.6269	1.3135	2.6269
	38.9400	3.2411	8.7635	2.6459	1.3229	2.6459
	39.1600	3.2596	8.7716	2.6649	1.3324	2.6649
	39.3800	3.2777	8.7793	2.6837	1.3418	2.6837
	39.6000	3.2961	8.7901	2.7026	1.3513	2.7026
	39.8200	3.3144	8.7964	2.7214	1.3607	2.7214
	40.0400	3.3329	8.8070	2.7404	1.3702	2.7404
	40.2600	3.3513	8.8173	2.7594	1.3797	2.7594
	40.4800	3.3694	8.8220	2.7781	1.3891	2.7781
	40.7000	3.3878	8.8315	2.7970	1.3985	2.7970
	40.9200	3.4062	8.8427	2.8159	1.4080	2.8159
	41.1400	3.4245	8.8510	2.8349	1.4175	2.8349
	41.3600	3.4427	8.8564	2.8538	1.4269	2.8538
	41.5800	3.4612	8.8700	2.8727	1.4364	2.8727
	41.8000	3.4793	8.8752	2.8915	1.4458	2.8915
	42.0200	3.4978	8.8866	2.9105	1.4553	2.9105
	42.2400	3.5164	8.8952	2.9295	1.4647	2.9295
	42.4600	3.5344	8.9009	2.9482	1.4741	2.9482
	42.6800	3.5528	8.9098	2.9670	1.4835	2.9670
	42.9000	3.5712	8.9174	2.9858	1.4929	2.9858
	43.1200	3.5895	8.9287	3.0048	1.5024	3.0048
	43.3400	3.6078	8.9341	3.0235	1.5118	3.0235
	43.5600	3.6262	8.9437	3.0423	1.5211	3.0423
	43.7800	3.6445	8.9547	3.0612	1.5306	3.0612
	44.0000	3.6628	8.9605	3.0799	1.5400	3.0799
	44.2200	3.6811	8.9700	3.0988	1.5494	3.0988
	44.4400	3.6995	8.9782	3.1176	1.5588	3.1176
	44.6600	3.7177	8.9855	3.1364	1.5682	3.1364
	44.8800	3.7361	8.9958	3.1552	1.5776	3.1552
	45.1000	3.7547	9.0041	3.1739	1.5870	3.1739
	45.3200	3.7730	9.0127	3.1929	1.5965	3.1929
	45.5400	3.7911	9.0200	3.2116	1.6058	3.2116
	45.7600	3.8096	9.0270	3.2304	1.6152	3.2304
	45.9800	3.8278	9.0382	3.2493	1.6247	3.2493
	46.2000	3.8462	9.0454	3.2681	1.6341	3.2681
	46.4200	3.8644	9.0504	3.2868	1.6434	3.2868
	46.6400	3.8828	9.0635	3.3055	1.6528	3.3055
	46.8600	3.9011	9.0703	3.3242	1.6621	3.3242
	47.0800	3.9193	9.0767	3.3429	1.6714	3.3429
	47.3000	3.9381	9.0906	3.3618	1.6809	3.3618
	47.5200	3.9561	9.0932	3.3804	1.6902	3.3804
	47.7400	3.9744	9.1014	3.3990	1.6995	3.3990
	47.9600	3.9930	9.1116	3.4177	1.7089	3.4177
	48.1800	4.0112	9.1198	3.4365	1.7183	3.4365
	48.4000	4.0294	9.1262	3.4553	1.7277	3.4553
	48.6200	4.0479	9.1355	3.4738	1.7369	3.4738
	48.8400	4.0661	9.1443	3.4926	1.7463	3.4926
	49.0600	4.0845	9.1532	3.5114	1.7557	3.5114
	49.2800	4.1028	9.1609	3.5302	1.7651	3.5302
	49.5000	4.1210	9.1671	3.5488	1.7744	3.5488
	49.7200	4.1395	9.1787	3.5677	1.7839	3.5677
	49.9400	4.1577	9.1828	3.5863	1.7931	3.5863
	50.1600	4.1762	9.1933	3.6051	1.8025	3.6051
	50.3800	4.1947	9.2029	3.6239	1.8120	3.6239
	50.6000	4.2128	9.2071	3.6424	1.8212	3.6424
	50.8200	4.2311	9.2150	3.6610	1.8305	3.6610
	51.0400	4.2496	9.2265	3.6798	1.8399	3.6798
	51.2600	4.2678	9.2309	3.6984	1.8492	3.6984
	51.4800	4.2860	9.2383	3.7169	1.8585	3.7169
	51.7000	4.3045	9.2505	3.7355	1.8678	3.7355
	51.9200	4.3227	9.2565	3.7541	1.8771	3.7541
	52.1400	4.3411	9.2649	3.7727	1.8864	3.7727
	52.3600	4.3597	9.2735	3.7914	1.8957	3.7914
	52.5800	4.3778	9.2812	3.8101	1.9050	3.8101
	52.8000	4.3961	9.2870	3.8286	1.9143	3.8286
	53.0200	4.4145	9.2950	3.8472	1.9236	3.8472
	53.2400	4.4329	9.3066	3.8660	1.9330	3.8660
	53.4600	4.4512	9.3116	3.8847	1.9423	3.8847
	53.6800	4.4694	9.3190	3.9032	1.9516	3.9032
	53.9000	4.4878	9.3318	3.9220	1.9610	3.9220
	54.0860	4.5059	9.3510	3.9411	1.9706	3.9342
	54.3060	4.5062	9.1812	3.9415	1.9707	3.9342
	54.5260	4.5059	9.0872	3.9411	1.9705	3.9342
	54.7460	4.5055	9.0285	3.9406	1.9703	3.9342
	54.9660	4.5052	8.9858	3.9403	1.9702	3.9342
	55.1860	4.5050	8.9527	3.9400	1.9700	3.9342
	55.4060	4.5048	8.9265	3.9399	1.9699	3.9342
	55.6260	4.5047	8.9050	3.9398	1.9699	3.9342
	55.8460	4.5047	8.8870	3.9397	1.9699	3.9342
	56.0660	4.5047	8.8711	3.9397	1.9698	3.9342
	56.2860	4.5047	8.8573	3.9397	1.9698	3.9342
	56.5060	4.5047	8.8448	3.9397	1.9698	3.9342
	56.7260	4.5047	8.8334	3.9397	1.9698	3.9342
	56.9460	4.5046	8.8229	3.9396	1.9698	3.9342
	57.1660	4.5046	8.8133	3.9396	1.9698	3.9342
	57.3860	4.5046	8.8045	3.9396	1.9698	3.9342
	57.6060	4.5046	8.7962	3.9396	1.9698	3.9342
	57.8260	4.5046	8.7884	3.9396	1.9698	3.9342
	58.0460	4.5046	8.7811	3.9396	1.9698	3.9342
	58.2660	4.5046	8.7743	3.9396	1.9698	3.9342
	58.4860	4.5046	8.7677	3.9396	1.9698	3.9342
	58.7060	4.5046	8.7615	3.9396	1.9698	3.9342
	58.9260	4.5046	8.7557	3.9396	1.9698	3.9342
	59.1460	4.5046	8.7502	3.9396	1.9698	3.9342
	59.3660	4.5046	8.7449	3.9396	1.9698	3.9342
	59.5860	4.5046	8.7397	3.9396	1.9698	3.9342
	59.8060	4.5046	8.7348	3.9396	1.9698	3.9342
	60.0260	4.5046	8.7301	3.9396	1.9698	3.9342
	60.2460	4.5046	8.7264	3.9396	1.9698	3.9342
	60.4660	4.5046	8.7206	3.9396	1.9698	3.9342
	60.6860	4.5046	8.7202	3.9396	1.9698	3.9342
	60.9060	4.5046	8.7161	3.9396	1.9698	3.9342
	61.1260	4.5046	8.7140	3.9396	1.9698	3.9342
	61.3460	4.5046	8.7099	3.9396	1.9698	3.9342
	61.5660	4.5046	8.7048	3.9396	1.9698	3.9342
	61.7860	4.5046	8.7010	3.9396	1.9698	3.9342
	62.0060	4.5046	8.6977	3.9396	1.9698	3.9342
	62.2260	4.5046	8.6942	3.9396	1.9698	3.9342
	62.4460	4.5046	8.6910	3.9396	1.9698	3.9342
	62.6660	4.5046	8.6879	3.9396	1.9698	3.9342
	62.8860	4.5046	8.6845	3.9396	1.9698	3.9342
	63.1060	4.5046	8.6811	3.9396	1.9698	3.9342
	63.3260	4.5046	8.6778	3.9396	1.9698	3.9342
	63.5460	4.5046	8.6745	3.9396	1.9698	3.9342
	63.7660	4.5046	8.6718	3.9396	1.9698	3.9342
	63.9860	4.5046	8.6691	3.9396	1.9698	3.9342
	64.2060	4.5046	8.6662	3.9396	1.9698	3.9342
	64.4260	4.5046	8.6636	3.9396	1.9698	3.9342
	64.6460	4.5046	8.6611	3.9396	1.9698	3.9342
	64.8660	4.5046	8.6587	3.9396	1.9698	3.9342
	65.0860	4.5046	8.6561	3.9396	1.9698	3.9342
	65.3060	4.5046	8.6535	3.9396	1.9698	3.9342
	65.5260	4.5046	8.6514	3.9396	1.9698	3.9342
	65.7460	4.5046	8.6490	3.9396	1.9698	3.9342
	65.9660	4.5046	8.6468	3.9396	1.9698	3.9342
	66.1860	4.5046	8.6445	3.9396	1.9698	3.9342
	66.4060	4.5046	8.6425	3.9396	1.9698	3.9342
	66.6260	4.5046	8.6404	3.9396	1.9698	3.9342
	66.8460	4.5046	8.6383	3.9396	1.9698	3.9342
	67.0660	4.5046	8.6367	3.9396	1.9698	3.9342
	67.2860	4.5046	8.6358	3.9396	1.9698	3.9342
	67.5060	4.5046	8.6321	3.9396	1.9698	3.9342
	67.7260	4.5046	8.6296	3.9396	1.9698	3.9342
	67.9460	4.5046	8.6273	3.9396	1.9698	3.9342
	68.1660	4.5046	8.6247	3.9396	1.9698	3.9342
	68.3860	4.5046	8.6233	3.9396	1.9698	3.9342
	68.6060	4.5046	8.6204	3.9396	1.9698	3.9342
	68.8260	4.5046	8.6198	3.9396	1.9698	3.9342
	69.0460	4.5046	8.6201	3.9396	1.9698	3.9342
	69.2660	4.5046	8.6157	3.9396	1.9698	3.9342
	69.4860	4.5046	8.6126	3.9396	1.9698	3.9342
	69.7060	4.5046	8.6119	3.9396	1.9698	3.9342
	69.9260	4.5046	8.6116	3.9396	1.9698	3.9342
	70.1460	4.5046	8.6090	3.9396	1.9698	3.9342
	70.3660	4.5046	8.6071	3.9396	1.9698	3.9342
	70.5860	4.5046	8.6054	3.9396	1.9698	3.9342
	70.8060	4.5046	8.6035	3.9396	1.9698	3.9342
	71.0260	4.5046	8.6023	3.9396	1.9698	3.9342
	71.2460	4.5046	8.6008	3.9396	1.9698	3.9342
	71.4660	4.5046	8.5996	3.9396	1.9698	3.9342
	71.6860	4.5046	8.5980	3.9396	1.9698	3.9342
	71.9060	4.5046	8.5966	3.9396	1.9698	3.9342
	72.1260	4.5046	8.5952	3.9396	1.9698	3.9342
	72.3300	4.5046	8.5942	3.9396	1.9698	3.9342
	72.4970	4.5282	8.9189	3.9671	1.9836	3.9342
	72.7170	4.5825	9.5179	4.0307	2.0153	3.9342
	72.9370	4.6377	9.5706	4.0951	2.0476	3.9342
	73.1570	4.6927	9.5865	4.1594	2.0797	3.9342
	73.3770	4.7476	9.6019	4.2236	2.1118	3.9342
	73.5970	4.8026	9.6198	4.2879	2.1439	3.9342
	73.8170	4.8576	9.6404	4.3521	2.1761	3.9342
	74.0370	4.9126	9.6604	4.4164	2.2082	3.9342
	74.2570	4.9675	9.6810	4.4806	2.2403	3.9342
	74.4770	5.0225	9.7039	4.5449	2.2725	3.9342
	74.6970	5.0775	9.7261	4.6092	2.3046	3.9342
	74.9170	5.1326	9.7487	4.6736	2.3368	3.9342
	75.1370	5.1876	9.7701	4.7379	2.3689	3.9342
	75.3570	5.2426	9.7915	4.8021	2.4010	3.9342
	75.5770	5.2977	9.8141	4.8665	2.4332	3.9342
	75.7970	5.3525	9.8349	4.9306	2.4653	3.9342
	76.0170	5.4075	9.8575	4.9949	2.4974	3.9342
	76.2370	5.4628	9.8818	5.0595	2.5297	3.9342
	76.4570	5.5175	9.9011	5.1234	2.5617	3.9342
	76.6770	5.5726	9.9230	5.1879	2.5939	3.9342
	76.8970	5.6278	9.9459	5.2524	2.6262	3.9342
	77.1170	5.6826	9.9651	5.3164	2.6582	3.9342
	77.3370	5.7376	9.9858	5.3807	2.6904	3.9342
	77.5570	5.7927	10.0099	5.4450	2.7225	3.9342
	77.7770	5.8475	10.0302	5.5092	2.7546	3.9342
	77.9970	5.9026	10.0504	5.5735	2.7868	3.9342
	78.2170	5.9576	10.0726	5.6378	2.8189	3.9342
	78.4370	6.0126	10.0934	5.7021	2.8510	3.9342
	78.6570	6.0675	10.1142	5.7663	2.8831	3.9342
	78.8770	6.1226	10.1367	5.8307	2.9153	3.9342
	79.0970	6.1776	10.1570	5.8950	2.9475	3.9342
	79.3170	6.2326	10.1774	5.9592	2.9796	3.9342
	79.5370	6.2877	10.1984	6.0236	3.0118	3.9342
	79.7570	6.3426	10.2185	6.0878	3.0439	3.9342
	79.9770	6.3975	10.2407	6.1520	3.0760	3.9342
	80.1970	6.4525	10.2613	6.2162	3.1081	3.9342
	80.4170	6.5076	10.2822	6.2806	3.1403	3.9342
	80.6370	6.5627	10.3038	6.3451	3.1725	3.9342
	80.8570	6.6176	10.3219	6.4092	3.2046	3.9342
	81.0770	6.6726	10.3418	6.4735	3.2367	3.9342
	81.2970	6.7278	10.3639	6.5379	3.2690	3.9342
	81.5170	6.7825	10.3822	6.6019	3.3009	3.9342
	81.7370	6.8376	10.4030	6.6664	3.3332	3.9342
	81.9570	6.8927	10.4243	6.7308	3.3654	3.9342
	82.1770	6.9476	10.4425	6.7949	3.3974	3.9342
	82.3970	7.0026	10.4618	6.8592	3.4296	3.9342
	82.6170	7.0576	10.4831	6.9234	3.4617	3.9342
	82.8370	7.1125	10.5018	6.9876	3.4938	3.9342
	83.0570	7.1676	10.5208	7.0520	3.5260	3.9342
	83.2770	7.2227	10.5417	7.1164	3.5582	3.9342
	83.4970	7.2776	10.5609	7.1806	3.5903	3.9342
	83.7170	7.3326	10.5787	7.2449	3.6225	3.9342
	83.9370	7.3876	10.5999	7.3092	3.6546	3.9342
	84.1570	7.4425	10.6189	7.3734	3.6867	3.9342
	84.3770	7.4976	10.6380	7.4377	3.7188	3.9342
	84.5970	7.5525	10.6576	7.5019	3.7510	3.9342
	84.8170	7.6075	10.6767	7.5662	3.7831	3.9342
	85.0370	7.6626	10.6961	7.6305	3.8153	3.9342
	85.2570	7.7175	10.7146	7.6948	3.8474	3.9342
	85.4770	7.7725	10.7340	7.7590	3.8795	3.9342
	85.6970	7.8277	10.7553	7.8235	3.9118	3.9342
	85.9170	7.8826	10.7726	7.8876	3.9438	3.9342
	86.1370	7.9377	10.7920	7.9520	3.9760	3.9342
	86.3570	7.9928	10.8112	8.0164	4.0082	3.9342
	86.5770	8.0475	10.8272	8.0804	4.0402	3.9342
	86.7970	8.1026	10.8464	8.1448	4.0724	3.9342
	87.0170	8.1578	10.8668	8.2094	4.1047	3.9342
	87.2370	8.2126	10.8835	8.2734	4.1367	3.9342
	87.4570	8.2677	10.9020	8.3378	4.1689	3.9342
	87.6770	8.3227	10.9215	8.4021	4.2010	3.9342
	87.8970	8.3776	10.9382	8.4662	4.2331	3.9342
	88.1170	8.4325	10.9557	8.5304	4.2652	3.9342
	88.3370	8.4876	10.9761	8.5948	4.2974	3.9342
	88.5570	8.5425	10.9939	8.6590	4.3295	3.9342
	88.7770	8.5975	11.0103	8.7233	4.3616	3.9342
	88.9970	8.6526	11.0305	8.7876	4.3938	3.9342
	89.2170	8.7076	11.0472	8.8519	4.4260	3.9342
	89.4370	8.7627	11.0656	8.9163	4.4581	3.9342
	89.6570	8.8176	11.0840	8.9805	4.4903	3.9342
	89.8770	8.8726	11.1019	9.0448	4.5224	3.9342
	90.0970	8.9276	11.1203	9.1090	4.5545	3.9342
	90.3170	8.9825	11.1366	9.1732	4.5866	3.9342
	90.5370	9.0375	11.1539	9.2375	4.6188	3.9342
	90.7570	9.0927	11.1731	9.3020	4.6510	3.9342
	90.9770	9.1476	11.1896	9.3662	4.6831	3.9342
	91.1970	9.2027	11.2073	9.4306	4.7153	3.9342
	91.4170	9.2578	11.2257	9.4950	4.7475	3.9342
	91.6370	9.3126	11.2413	9.5590	4.7795	3.9342
	91.8570	9.3676	11.2583	9.6233	4.8117	3.9342
	92.0770	9.4227	11.2763	9.6877	4.8438	3.9342
	92.2970	9.4775	11.2933	9.7517	4.8759	3.9342
	92.5170	9.5325	11.3098	9.8161	4.9080	3.9342
	92.7370	9.5877	11.3281	9.8806	4.9403	3.9342
	92.9570	9.6426	11.3439	9.9447	4.9724	3.9342
	93.1770	9.6977	11.3599	10.0091	5.0046	3.9342
	93.3970	9.7527	11.3779	10.0734	5.0367	3.9342
	93.6170	9.8075	11.3939	10.1375	5.0687	3.9342
	93.8370	9.8625	11.4105	10.2018	5.1009	3.9342
	94.0570	9.9175	11.4278	10.2660	5.1330	3.9342
	94.2770	9.9726	11.4440	10.3304	5.1652	3.9342
	94.4970	10.0276	11.4608	10.3947	5.1973	3.9342
	94.7170	10.0825	11.4774	10.4589	5.2295	3.9342
	94.9370	10.1375	11.4944	10.5232	5.2616	3.9342
	95.1570	10.1927	11.5124	10.5877	5.2938	3.9342
	95.3770	10.2476	11.5268	10.6519	5.3259	3.9342
	95.5970	10.3026	11.5429	10.7161	5.3581	3.9342
	95.8170	10.3577	11.5603	10.7805	5.3902	3.9342
	96.0370	10.4125	11.5745	10.8446	5.4223	3.9342
	96.2570	10.4675	11.5907	10.9089	5.4544	3.9342
	96.4770	10.5228	11.6091	10.9735	5.4867	3.9342
	96.6970	10.5776	11.6234	11.0375	5.5188	3.9342
	96.9170	10.6327	11.6388	11.1019	5.5510	3.9342
	97.1370	10.6878	11.6555	11.1664	5.5832	3.9342
	97.3570	10.7425	11.6702	11.2303	5.6151	3.9342
	97.5770	10.7975	11.6851	11.2946	5.6473	3.9342
	97.7970	10.8526	11.7027	11.3590	5.6795	3.9342
	98.0170	10.9075	11.7181	11.4231	5.7115	3.9342
	98.2370	10.9626	11.7318	11.4875	5.7438	3.9342
	98.4570	11.0177	11.7492	11.5519	5.7759	3.9342
	98.6770	11.0726	11.7633	11.6161	5.8080	3.9342
	98.8970	11.1276	11.7792	11.6804	5.8402	3.9342
	99.1170	11.1826	11.7951	11.7446	5.8723	3.9342
	99.3370	11.2376	11.8098	11.8090	5.9045	3.9342
	99.5570	11.2926	11.8260	11.8732	5.9366	3.9342
	99.7770	11.3476	11.8399	11.9375	5.9687	3.9342
	99.9970	11.4025	11.8551	12.0017	6.0009	3.9342
	100.2170	11.4576	11.8719	12.0660	6.0330	3.9342
	100.4370	11.5126	11.8862	12.1303	6.0651	3.9342
	100.6570	11.5676	11.9015	12.1946	6.0973	3.9342
	100.8770	11.6228	11.9175	12.2592	6.1296	3.9342
	101.0970	11.6776	11.9296	12.3232	6.1616	3.9342
	101.3170	11.7326	11.9439	12.3874	6.1937	3.9342
	101.5370	11.7878	11.9604	12.4519	6.2260	3.9342
	101.7570	11.8425	11.9742	12.5159	6.2580	3.9342
	101.9770	11.8977	11.9884	12.5804	6.2902	3.9342
	102.1970	11.9527	12.0041	12.6447	6.3224	3.9342
	102.4170	12.0075	12.0174	12.7088	6.3544	3.9342
	102.6370	12.0626	12.0305	12.7732	6.3866	3.9342
	102.8570	12.1176	12.0460	12.8375	6.4187	3.9342
	103.0770	12.1726	12.0599	12.9017	6.4508	3.9342
	103.2970	12.2276	12.0738	12.9661	6.4830	3.9342
	103.5170	12.2826	12.0891	13.0303	6.5151	3.9342
	103.7370	12.3376	12.1026	13.0946	6.5473	3.9342
	103.9570	12.3925	12.1162	13.1588	6.5794	3.9342
	104.1770	12.4476	12.1316	13.2231	6.6116	3.9342
	104.3970	12.5025	12.1450	13.2873	6.6437	3.9342
	104.6170	12.5576	12.1600	13.3517	6.6758	3.9342
	104.8370	12.6126	12.1728	13.4160	6.7080	3.9342
	105.0570	12.6675	12.1862	13.4802	6.7401	3.9342
	105.2770	12.7227	12.2009	13.5446	6.7723	3.9342
	105.4970	12.7776	12.2134	13.6088	6.8044	3.9342
	105.7170	12.8325	12.2279	13.6730	6.8365	3.9342
	105.9370	12.8878	12.2436	13.7376	6.8688	3.9342
	106.1570	12.9425	12.2548	13.8015	6.9008	3.9342
	106.3770	12.9976	12.2682	13.8660	6.9330	3.9342
	106.5970	13.0528	12.2828	13.9305	6.9653	3.9342
	106.8170	13.1075	12.2938	13.9944	6.9972	3.9342
	107.0370	13.1626	12.3071	14.0588	7.0294	3.9342
	107.2570	13.2177	12.3224	14.1232	7.0616	3.9342
	107.4770	13.2726	12.3350	14.1874	7.0937	3.9342
	107.6970	13.3276	12.3464	14.2517	7.1258	3.9342
	107.9170	13.3827	12.3618	14.3160	7.1580	3.9342
	108.1370	13.4376	12.3738	14.3802	7.1901	3.9342
	108.3570	13.4925	12.3854	14.4444	7.2222	3.9342
	108.5770	13.5476	12.4004	14.5087	7.2544	3.9342
	108.7970	13.6026	12.4130	14.5731	7.2865	3.9342
	109.0170	13.6576	12.4254	14.6373	7.3187	3.9342
	109.2370	13.7127	12.4381	14.7017	7.3509	3.9342
	109.4570	13.7676	12.4507	14.7659	7.3830	3.9342
	109.6770	13.8226	12.4642	14.8302	7.4151	3.9342
	109.8970	13.8776	12.4772	14.8944	7.4472	3.9342
	110.1170	13.9325	12.4892	14.9587	7.4793	3.9342
	110.3370	13.9877	12.5036	15.0232	7.5116	3.9342
	110.5570	14.0425	12.5132	15.0873	7.5436	3.9342
	110.7770	14.0976	12.5255	15.1516	7.5758	3.9342
	110.9970	14.1528	12.5401	15.2161	7.6081	3.9342
	111.2170	14.2076	12.5506	15.2801	7.6401	3.9342
	111.4370	14.2626	12.5627	15.3445	7.6722	3.9342
	111.6570	14.3178	12.5774	15.4089	7.7045	3.9342
	111.8770	14.3725	12.5873	15.4730	7.7365	3.9342
	112.0970	14.4276	12.5989	15.5373	7.7686	3.9342
	112.3170	14.4826	12.6117	15.6016	7.8008	3.9342
	112.5370	14.5375	12.6231	15.6658	7.8329	3.9342
	112.7570	14.5926	12.6342	15.7301	7.8651	3.9342
	112.9770	14.6477	12.6479	15.7946	7.8973	3.9342
	113.1970	14.7027	12.6591	15.8588	7.9294	3.9342
	113.4170	14.7576	12.6695	15.9230	7.9615	3.9342
	113.6370	14.8126	12.6826	15.9872	7.9936	3.9342
	113.8570	14.8675	12.6934	16.0514	8.0257	3.9342
	114.0770	14.9225	12.7064	16.1158	8.0579	3.9342
	114.2970	14.9776	12.7176	16.1801	8.0900	3.9342
	114.5170	15.0325	12.7286	16.2443	8.1222	3.9342
	114.7370	15.0877	12.7415	16.3088	8.1544	3.9342
	114.9570	15.1426	12.7517	16.3729	8.1865	3.9342
	115.1770	15.1975	12.7638	16.4372	8.2186	3.9342
	115.3970	15.2528	12.7772	16.5017	8.2509	3.9342
	115.6170	15.3076	12.7862	16.5658	8.2829	3.9342
	115.8370	15.3626	12.7978	16.6300	8.3150	3.9342
	116.0570	15.4177	12.8106	16.6945	8.3473	3.9342
	116.2770	15.4725	12.8192	16.7585	8.3793	3.9342
	116.4970	15.5276	12.8302	16.8230	8.4115	3.9342
	116.7170	15.5828	12.8433	16.8875	8.4437	3.9342
	116.9370	15.6377	12.8530	16.9516	8.4758	3.9342
	117.1570	15.6926	12.8634	17.0158	8.5079	3.9342
	117.3770	15.7477	12.8756	17.0802	8.5401	3.9342
	117.5970	15.8025	12.8854	17.1442	8.5721	3.9342
	117.8170	15.8575	12.8953	17.2085	8.6043	3.9342
	118.0370	15.9126	12.9079	17.2730	8.6365	3.9342
	118.2570	15.9675	12.9180	17.3371	8.6686	3.9342
	118.4770	16.0226	12.9279	17.4015	8.7007	3.9342
	118.6970	16.0777	12.9398	17.4659	8.7329	3.9342
	118.9170	16.1326	12.9495	17.5301	8.7650	3.9342
	119.1370	16.1876	12.9603	17.5943	8.7972	3.9342
	119.3570	16.2425	12.9711	17.6585	8.8293	3.9342
	119.5770	16.2976	12.9815	17.7228	8.8614	3.9342
	119.7970	16.3526	12.9933	17.7872	8.8936	3.9342
	120.0170	16.4075	13.0020	17.8514	8.9257	3.9342
	120.2370	16.4626	13.0127	17.9157	8.9579	3.9342
	120.4570	16.5177	13.0249	17.9802	8.9901	3.9342
	120.6770	16.5726	13.0337	18.0443	9.0221	3.9342
	120.8970	16.6277	13.0440	18.1087	9.0543	3.9342
	121.1170	16.6829	13.0555	18.1732	9.0866	3.9342
	121.3370	16.7376	13.0625	18.2371	9.1186	3.9342
	121.5570	16.7926	13.0726	18.3014	9.1507	3.9342
	121.7770	16.8477	13.0846	18.3658	9.1829	3.9342
	121.9970	16.9025	13.0943	18.4299	9.2149	3.9342
	122.2170	16.9576	13.1031	18.4943	9.2471	3.9342
	122.4370	17.0127	13.1147	18.5587	9.2794	3.9342
	122.6570	17.0676	13.1235	18.6228	9.3114	3.9342
	122.8770	17.1227	13.1314	18.6872	9.3436	3.9342
	123.0970	17.1777	13.1427	18.7515	9.3757	3.9342
	123.3170	17.2325	13.1516	18.8156	9.4078	3.9342
	123.5370	17.2876	13.1617	18.8800	9.4400	3.9342
	123.7570	17.3425	13.1728	18.9442	9.4721	3.9342
	123.9770	17.3975	13.1811	19.0085	9.5042	3.9342
	124.1970	17.4526	13.1916	19.0729	9.5364	3.9342
	124.4170	17.5076	13.2008	19.1371	9.5685	3.9342
	124.6370	17.5626	13.2111	19.2013	9.6007	3.9342
	124.8570	17.6175	13.2209	19.2655	9.6328	3.9342
	125.0770	17.6725	13.2292	19.3298	9.6649	3.9342
	125.2970	17.7276	13.2384	19.3942	9.6971	3.9342
	125.5170	17.7827	13.2488	19.4587	9.7293	3.9342
	125.7370	17.8375	13.2561	19.5227	9.7614	3.9342
	125.9570	17.8926	13.2666	19.5870	9.7935	3.9342
	126.1770	17.9478	13.2781	19.6516	9.8258	3.9342
	126.3970	18.0026	13.2850	19.7156	9.8578	3.9342
	126.6170	18.0577	13.2934	19.7800	9.8900	3.9342
	126.8370	18.1129	13.3038	19.8446	9.9223	3.9342
	127.0570	18.1675	13.3105	19.9084	9.9542	3.9342
	127.2770	18.2225	13.3193	19.9727	9.9863	3.9342
	127.4970	18.2776	13.3310	20.0371	10.0185	3.9342
	127.7170	18.3326	13.3397	20.1014	10.0507	3.9342
	127.9370	18.3877	13.3467	20.1657	10.0829	3.9342
	128.1570	18.4426	13.3568	20.2299	10.1150	3.9342
	128.3770	18.4976	13.3649	20.2942	10.1471	3.9342
	128.5970	18.5525	13.3732	20.3584	10.1792	3.9342
	128.8170	18.6076	13.3831	20.4227	10.2114	3.9342
	129.0370	18.6627	13.3918	20.4871	10.2436	3.9342
	129.2570	18.7177	13.4005	20.5514	10.2757	3.9342
	129.4770	18.7726	13.4085	20.6156	10.3078	3.9342
	129.6970	18.8275	13.4173	20.6798	10.3399	3.9342
	129.9170	18.8826	13.4276	20.7442	10.3721	3.9342
	130.1370	18.9376	13.4351	20.8084	10.4042	3.9342
	130.3570	18.9926	13.4437	20.8728	10.4364	3.9342
	130.5770	19.0478	13.4526	20.9372	10.4686	3.9342
	130.7970	19.1025	13.4585	21.0012	10.5006	3.9342
	131.0170	19.1576	13.4674	21.0656	10.5328	3.9342
	131.2370	19.2128	13.4769	21.1301	10.5650	3.9342
	131.4570	19.2675	13.4848	21.1941	10.5970	3.9342
	131.6770	19.3226	13.4926	21.2585	10.6292	3.9342
	131.8970	19.3778	13.5027	21.3229	10.6614	3.9342
	132.1170	19.4325	13.5091	21.3869	10.6935	3.9342
	132.3370	19.4876	13.5155	21.4513	10.7256	3.9342
	132.5570	19.5426	13.5253	21.5155	10.7578	3.9342
	132.7770	19.5976	13.5327	21.5798	10.7899	3.9342
	132.9970	19.6526	13.5402	21.6441	10.8220	3.9342
	133.2170	19.7076	13.5504	21.7084	10.8542	3.9342
	133.4370	19.7627	13.5573	21.7728	10.8864	3.9342
	133.6570	19.8176	13.5646	21.8369	10.9185	3.9342
	133.8770	19.8724	13.5727	21.9010	10.9505	3.9342
	134.0970	19.9275	13.5806	21.9654	10.9827	3.9342
	134.3170	19.9825	13.5898	22.0297	11.0149	3.9342
	134.5370	20.0376	13.5968	22.0941	11.0471	3.9342
	134.7570	20.0926	13.6041	22.1584	11.0792	3.9342
	134.9770	20.1477	13.6117	22.2228	11.1114	3.9342
	135.1970	20.2025	13.6187	22.2869	11.1434	3.9342
	135.4170	20.2575	13.6274	22.3511	11.1756	3.9342
	135.6370	20.3127	13.6372	22.4157	11.2078	3.9342
	135.8570	20.3675	13.6422	22.4797	11.2398	3.9342
	136.0770	20.4227	13.6501	22.5441	11.2721	3.9342
	136.2970	20.4777	13.6578	22.6085	11.3043	3.9342
	136.5170	20.5325	13.6635	22.6725	11.3363	3.9342
	136.7370	20.5877	13.6716	22.7370	11.3685	3.9342
	136.9570	20.6428	13.6808	22.8014	11.4007	3.9342
	137.1770	20.6975	13.6865	22.8654	11.4327	3.9342
	137.3970	20.7526	13.6939	22.9298	11.4649	3.9342
	137.6170	20.8077	13.7022	22.9941	11.4971	3.9342
	137.8370	20.8626	13.7078	23.0583	11.5291	3.9342
	138.0570	20.9175	13.7148	23.1225	11.5612	3.9342
	138.2770	20.9726	13.7232	23.1869	11.5935	3.9342
	138.4970	21.0276	13.7302	23.2512	11.6256	3.9342
	138.7170	21.0825	13.7376	23.3154	11.6577	3.9342
	138.9370	21.1377	13.7449	23.3798	11.6899	3.9342
	139.1570	21.1926	13.7518	23.4441	11.7220	3.9342
	139.3770	21.2476	13.7594	23.5083	11.7541	3.9342
	139.5970	21.3025	13.7659	23.5724	11.7862	3.9342
	139.8170	21.3575	13.7728	23.6367	11.8184	3.9342
	140.0370	21.4127	13.7814	23.7013	11.8506	3.9342
	140.2570	21.4676	13.7858	23.7654	11.8827	3.9342
	140.4770	21.5227	13.7927	23.8298	11.9149	3.9342
	140.6970	21.5778	13.8016	23.8942	11.9471	3.9342
	140.9170	21.6326	13.8077	23.9583	11.9791	3.9342
	141.1370	21.6877	13.8137	24.0227	12.0114	3.9342
	141.3570	21.7428	13.8219	24.0871	12.0435	3.9342
	141.5770	21.7975	13.8259	24.1510	12.0755	3.9342
	141.7970	21.8526	13.8326	24.2154	12.1077	3.9342
	142.0170	21.9075	13.8404	24.2796	12.1398	3.9342
	142.2370	21.9626	13.8472	24.3439	12.1720	3.9342
	142.4570	22.0177	13.8527	24.4083	12.2042	3.9342
	142.6770	22.0727	13.8607	24.4727	12.2364	3.9342
	142.8970	22.1275	13.8653	24.5367	12.2684	3.9342
	143.1170	22.1825	13.8716	24.6010	12.3005	3.9342
	143.3370	22.2376	13.8788	24.6654	12.3327	3.9342
	143.5570	22.2925	13.8854	24.7295	12.3648	3.9342
	143.7770	22.3475	13.8920	24.7939	12.3969	3.9342
	143.9970	22.4025	13.8979	24.8582	12.4291	3.9342
	144.2170	22.4576	13.9047	24.9225	12.4613	3.9342
	144.4370	22.5126	13.9113	24.9868	12.4934	3.9342
	144.6570	22.5676	13.9172	25.0510	12.5255	3.9342
	144.8770	22.6226	13.9235	25.1154	12.5577	3.9342
	145.0970	22.6778	13.9316	25.1799	12.5899	3.9342
	145.3170	22.7325	13.9354	25.2439	12.6219	3.9342
	145.5370	22.7875	13.9418	25.3081	12.6541	3.9342
	145.7570	22.8427	13.9497	25.3726	12.6863	3.9342
	145.9770	22.8975	13.9540	25.4367	12.7183	3.9342
	146.1970	22.9526	13.9603	25.5010	12.7505	3.9342
	146.4170	23.0078	13.9683	25.5656	12.7828	3.9342
	146.6370	23.0627	13.9727	25.6297	12.8148	3.9342
	146.8570	23.1176	13.9773	25.6939	12.8470	3.9342
	147.0770	23.1727	13.9848	25.7583	12.8792	3.9342
	147.2970	23.2275	13.9899	25.8223	12.9112	3.9342
	147.5170	23.2825	13.9952	25.8867	12.9433	3.9342
	147.7370	23.3376	14.0030	25.9511	12.9755	3.9342
	147.9570	23.3925	14.0083	26.0153	13.0076	3.9342
	148.1770	23.4476	14.0134	26.0796	13.0398	3.9342
	148.3970	23.5027	14.0203	26.1440	13.0720	3.9342
	148.6170	23.5576	14.0248	26.2081	13.1041	3.9342
	148.8370	23.6125	14.0310	26.2724	13.1362	3.9342
	149.0570	23.6675	14.0378	26.3367	13.1683	3.9342
	149.2770	23.7226	14.0431	26.4010	13.2005	3.9342
	149.4970	23.7776	14.0499	26.4653	13.2327	3.9342
	149.7170	23.8325	14.0537	26.5295	13.2648	3.9342
	149.9370	23.8877	14.0599	26.5939	13.2970	3.9342
	150.1570	23.9427	14.0673	26.6583	13.3291	3.9342
	150.3770	23.9976	14.0709	26.7224	13.3612	3.9342
	150.5970	24.0527	14.0765	26.7868	13.3934	3.9342
	150.8170	24.1077	14.0829	26.8512	13.4256	3.9342
	151.0370	24.1625	14.0863	26.9152	13.4576	3.9342
	151.2570	24.2176	14.0922	26.9796	13.4898	3.9342
	151.4770	24.2728	14.0987	27.0440	13.5220	3.9342
	151.6970	24.3276	14.1041	27.1081	13.5541	3.9342
	151.9170	24.3825	14.1084	27.1722	13.5861	3.9342
	152.1370	24.4377	14.1153	27.2368	13.6184	3.9342
	152.3570	24.4926	14.1191	27.3010	13.6505	3.9342
	152.5770	24.5477	14.1230	27.3653	13.6827	3.9342
	152.7970	24.6026	14.1292	27.4296	13.7148	3.9342
	153.0170	24.6575	14.1342	27.4937	13.7468	3.9342
	153.2370	24.7126	14.1398	27.5581	13.7790	3.9342
	153.4570	24.7675	14.1462	27.6223	13.8111	3.9342
	153.6770	24.8226	14.1506	27.6867	13.8433	3.9342
	153.8970	24.8776	14.1556	27.7510	13.8755	3.9342
	154.1170	24.9326	14.1607	27.8152	13.9076	3.9342
	154.3370	24.9875	14.1656	27.8794	13.9397	3.9342
	154.5570	25.0426	14.1725	27.9438	13.9719	3.9342
	154.7770	25.0976	14.1755	28.0081	14.0040	3.9342
	154.9970	25.1526	14.1810	28.0724	14.0362	3.9342
	155.2170	25.2077	14.1869	28.1368	14.0684	3.9342
	155.4370	25.2625	14.1896	28.2008	14.1004	3.9342
	155.6570	25.3176	14.1959	28.2652	14.1326	3.9342
	155.8770	25.3728	14.2028	28.3297	14.1649	3.9342
	156.0970	25.4275	14.2053	28.3937	14.1968	3.9342
	156.3170	25.4827	14.2097	28.4582	14.2291	3.9342
	156.5370	25.5378	14.2156	28.5226	14.2613	3.9342
	156.7570	25.5925	14.2185	28.5865	14.2932	3.9342
	156.9770	25.6475	14.2229	28.6508	14.3254	3.9342
	157.1970	25.7027	14.2303	28.7153	14.3577	3.9342
	157.4170	25.7576	14.2345	28.7794	14.3897	3.9342
	157.6370	25.8126	14.2376	28.8437	14.4219	3.9342
	157.8570	25.8676	14.2432	28.9080	14.4540	3.9342
	158.0770	25.9226	14.2465	28.9723	14.4861	3.9342
	158.2970	25.9775	14.2510	29.0365	14.5182	3.9342
	158.5170	26.0326	14.2574	29.1009	14.5505	3.9342
	158.7370	26.0877	14.2615	29.1652	14.5826	3.9342
	158.9570	26.1427	14.2663	29.2295	14.6147	3.9342
	159.1770	26.1976	14.2702	29.2937	14.6469	3.9342
	159.3970	26.2526	14.2749	29.3580	14.6790	3.9342
	159.6170	26.3075	14.2798	29.4222	14.7111	3.9342
	159.8370	26.3626	14.2849	29.4866	14.7433	3.9342
	160.0570	26.4176	14.2882	29.5508	14.7754	3.9342
	160.2770	26.4728	14.2940	29.6153	14.8077	3.9342
	160.4970	26.5276	14.2964	29.6794	14.8397	3.9342
	160.7170	26.5827	14.3008	29.7438	14.8719	3.9342
	160.9370	26.6377	14.3066	29.8081	14.9041	3.9342
	161.1570	26.6925	14.3099	29.8722	14.9361	3.9342
	161.3770	26.7477	14.3139	29.9366	14.9683	3.9342
	161.5970	26.8028	14.3189	30.0010	15.0005	3.9342
	161.8170	26.8575	14.3218	30.0649	15.0325	3.9342
	162.0370	26.9126	14.3251	30.1294	15.0647	3.9342
	162.2570	26.9676	14.3313	30.1937	15.0968	3.9342
	162.4770	27.0226	14.3341	30.2580	15.1290	3.9342
	162.6970	27.0777	14.3387	30.3223	15.1612	3.9342
	162.9170	27.1327	14.3437	30.3866	15.1933	3.9342
	163.1370	27.1877	14.3468	30.4509	15.2254	3.9342
	163.3570	27.2425	14.3506	30.5150	15.2575	3.9342
	163.5770	27.2975	14.3549	30.5793	15.2896	3.9342
	163.7970	27.3525	14.3586	30.6435	15.3217	3.9342
	164.0170	27.4076	14.3638	30.7079	15.3539	3.9342
	164.2370	27.4626	14.3671	30.7722	15.3861	3.9342
	164.4570	27.5176	14.3715	30.8365	15.4183	3.9342
	164.6770	27.5728	14.3760	30.9010	15.4505	3.9342
	164.8970	27.6276	14.3780	30.9650	15.4825	3.9342
	165.1170	27.6826	14.3826	31.0293	15.5147	3.9342
	165.3370	27.7377	14.3893	31.0938	15.5469	3.9342
	165.5570	27.7925	14.3906	31.1578	15.5789	3.9342
	165.7770	27.8476	14.3945	31.2222	15.6111	3.9342
	165.9970	27.9028	14.3991	31.2867	15.6433	3.9342
	166.2170	27.9576	14.4010	31.3507	15.6754	3.9342
	166.4370	28.0127	14.4050	31.4152	15.7076	3.9342
	166.6570	28.0677	14.4109	31.4795	15.7397	3.9342
	166.8770	28.1225	14.4133	31.5435	15.7718	3.9342
	167.0970	28.1776	14.4154	31.6079	15.8040	3.9342
	167.3170	28.2326	14.4201	31.6721	15.8361	3.9342
	167.5370	28.2875	14.4235	31.7364	15.8682	3.9342
	167.7570	28.3425	14.4262	31.8006	15.9003	3.9342
	167.9770	28.3976	14.4314	31.8650	15.9325	3.9342
	168.1970	28.4527	14.4354	31.9294	15.9647	3.9342
	168.4170	28.5076	14.4377	31.9936	15.9968	3.9342
	168.6370	28.5627	14.4418	32.0579	16.0290	3.9342
	168.8570	28.6176	14.4453	32.1221	16.0611	3.9342
	169.0770	28.6725	14.4494	32.1863	16.0931	3.9342
	169.2970	28.7275	14.4524	32.2506	16.1253	3.9342
	169.5170	28.7825	14.4563	32.3149	16.1574	3.9342
	169.7370	28.8378	14.4607	32.3795	16.1897	3.9342
	169.9570	28.8925	14.4624	32.4435	16.2217	3.9342
	170.1770	28.9477	14.4664	32.5079	16.2540	3.9342
	170.3970	29.0028	14.4709	32.5724	16.2862	3.9342
	170.6170	29.0576	14.4731	32.6364	16.3182	3.9342
	170.8370	29.1126	14.4757	32.7007	16.3504	3.9342
	171.0570	29.1677	14.4802	32.7651	16.3826	3.9342
	171.2770	29.2225	14.4817	32.8292	16.4146	3.9342
	171.4970	29.2775	14.4847	32.8934	16.4467	3.9342
	171.7170	29.3327	14.4901	32.9579	16.4790	3.9342
	171.9370	29.3876	14.4928	33.0221	16.5111	3.9342
	172.1570	29.4426	14.4944	33.0864	16.5432	3.9342
	172.3770	29.4977	14.4990	33.1508	16.5754	3.9342
	172.5970	29.5526	14.5014	33.2150	16.6075	3.9342
	172.8170	29.6075	14.5032	33.2791	16.6396	3.9342
	173.0370	29.6626	14.5075	33.3435	16.6717	3.9342
	173.2570	29.7174	14.5107	33.4075	16.7038	3.9342
	173.4770	29.7726	14.5143	33.4720	16.7360	3.9342
	173.6970	29.8276	14.5172	33.5364	16.7682	3.9342
	173.9170	29.8826	14.5201	33.6007	16.8003	3.9342
	174.1370	29.9377	14.5237	33.6650	16.8325	3.9342
	174.3570	29.9925	14.5257	33.7291	16.8646	3.9342
	174.5770	30.0475	14.5290	33.7934	16.8967	3.9342
	174.7970	30.1027	14.5341	33.8579	16.9289	3.9342
	175.0170	30.1575	14.5344	33.9219	16.9610	3.9342
	175.2370	30.2127	14.5382	33.9864	16.9932	3.9342
	175.4570	30.2678	14.5422	34.0508	17.0254	3.9342
	175.6770	30.3225	14.5433	34.1148	17.0574	3.9342
	175.8970	30.3776	14.5471	34.1792	17.0896	3.9342
	176.1170	30.4329	14.5513	34.2438	17.1219	3.9342
	176.3370	30.4876	14.5518	34.3078	17.1539	3.9342
	176.5570	30.5426	14.5538	34.3720	17.1860	3.9342
	176.7770	30.5977	14.5581	34.4364	17.2182	3.9342
	176.9970	30.6526	14.5601	34.5005	17.2503	3.9342
	177.2170	30.7075	14.5621	34.5648	17.2824	3.9342
	177.4370	30.7627	14.5672	34.6293	17.3146	3.9342
	177.6570	30.8176	14.5696	34.6934	17.3467	3.9342
	177.8770	30.8726	14.5705	34.7577	17.3788	3.9342
	178.0970	30.9276	14.5739	34.8221	17.4110	3.9342
	178.3170	30.9826	14.5761	34.8863	17.4431	3.9342
	178.5370	31.0375	14.5784	34.9505	17.4752	3.9342
	178.7570	31.0926	14.5825	35.0148	17.5074	3.9342
	178.9770	31.1475	14.5852	35.0791	17.5395	3.9342
	179.1970	31.2026	14.5885	35.1434	17.5717	3.9342
	179.4170	31.2576	14.5898	35.2077	17.6038	3.9342
	179.6370	31.3127	14.5918	35.2721	17.6360	3.9342
	179.8570	31.3677	14.5958	35.3364	17.6682	3.9342
	180.0770	31.4225	14.5966	35.4005	17.7002	3.9342
	180.2970	31.4776	14.6000	35.4649	17.7324	3.9342
	180.5170	31.5327	14.6030	35.5293	17.7646	3.9342
	180.7370	31.5876	14.6034	35.5934	17.7967	3.9342
	180.9570	31.6427	14.6061	35.6578	17.8289	3.9342
	181.1770	31.6978	14.6100	35.7222	17.8611	3.9342
	181.3970	31.7525	14.6114	35.7861	17.8931	3.9342
	181.6170	31.8075	14.6136	35.8505	17.9252	3.9342
	181.8370	31.8627	14.6161	35.9149	17.9575	3.9342
	182.0570	31.9175	14.6178	35.9790	17.9895	3.9342
	182.2770	31.9726	14.6185	36.0434	18.0217	3.9342
	182.4970	32.0276	14.6225	36.1077	18.0538	3.9342
	182.7170	32.0826	14.6245	36.1719	18.0860	3.9342
	182.9370	32.1376	14.6265	36.2362	18.1181	3.9342
	183.1570	32.1926	14.6301	36.3005	18.1502	3.9342
	183.3770	32.2476	14.6307	36.3648	18.1824	3.9342
	183.5970	32.3026	14.6334	36.4290	18.2145	3.9342
	183.8170	32.3575	14.6351	36.4932	18.2466	3.9342
	184.0370	32.4125	14.6373	36.5575	18.2787	3.9342
	184.2570	32.4677	14.6413	36.6220	18.3110	3.9342
	184.4770	32.5226	14.6417	36.6862	18.3431	3.9342
	184.6970	32.5777	14.6443	36.7505	18.3753	3.9342
	184.9170	32.6328	14.6474	36.8150	18.4075	3.9342
	185.1370	32.6876	14.6473	36.8791	18.4395	3.9342
	185.3570	32.7426	14.6495	36.9433	18.4716	3.9342
	185.5770	32.7977	14.6532	37.0077	18.5039	3.9342
	185.7970	32.8525	14.6534	37.0718	18.5359	3.9342
	186.0170	32.9077	14.6550	37.1362	18.5681	3.9342
	186.2370	32.9628	14.6578	37.2007	18.6004	3.9342
	186.4570	33.0176	14.6587	37.2647	18.6324	3.9342
	186.6770	33.0726	14.6603	37.3290	18.6645	3.9342
	186.8970	33.1277	14.6640	37.3934	18.6967	3.9342
	187.1170	33.1825	14.6651	37.4575	18.7287	3.9342
	187.3370	33.2376	14.6653	37.5218	18.7609	3.9342
	187.5570	33.2926	14.6681	37.5861	18.7931	3.9342
	187.7770	33.3476	14.6696	37.6504	18.8252	3.9342
[...]
	140.2800	21.2226	13.8849	23.5953	11.7976	4.0505
	140.5000	21.2775	13.8920	23.6595	11.8298	4.0505
	140.7200	21.3327	13.9004	23.7240	11.8620	4.0505
	140.9400	21.3877	13.9062	23.7883	11.8941	4.0505
	141.1600	21.4427	13.9126	23.8525	11.9263	4.0505
	141.3800	21.4978	13.9204	23.9169	11.9585	4.0505
	141.6000	21.5525	13.9245	23.9809	11.9904	4.0505
	141.8200	21.6075	13.9320	24.0452	12.0226	4.0505
	142.0400	21.6628	13.9401	24.1098	12.0549	4.0505
	142.2600	21.7176	13.9447	24.1739	12.0869	4.0505
	142.4800	21.7727	13.9515	24.2383	12.1191	4.0505
	142.7000	21.8279	13.9588	24.3027	12.1514	4.0505
	142.9200	21.8826	13.9639	24.3667	12.1833	4.0505
	143.1400	21.9375	13.9698	24.4309	12.2155	4.0505
	143.3600	21.9927	13.9781	24.4954	12.2477	4.0505
	143.5800	22.0475	13.9834	24.5595	12.2797	4.0505
	143.8000	22.1026	13.9882	24.6238	12.3119	4.0505
	144.0200	22.1576	13.9969	24.6881	12.3440	4.0505
	144.2400	22.2126	14.0018	24.7524	12.3762	4.0505
	144.4600	22.2676	14.0073	24.8167	12.4083	4.0505
	144.6800	22.3227	14.0157	24.8810	12.4405	4.0505
	144.9000	22.3777	14.0215	24.9454	12.4727	4.0505
	145.1200	22.4326	14.0274	25.0095	12.5048	4.0505
	145.3400	22.4875	14.0327	25.0737	12.5369	4.0505
	145.5600	22.5425	14.0390	25.1380	12.5690	4.0505
	145.7800	22.5976	14.0465	25.2024	12.6012	4.0505
	146.0000	22.6527	14.0514	25.2667	12.6334	4.0505
	146.2200	22.7077	14.0577	25.3310	12.6655	4.0505
	146.4400	22.7628	14.0652	25.3955	12.6977	4.0505
	146.6600	22.8176	14.0693	25.4596	12.7298	4.0505
	146.8800	22.8727	14.0743	25.5239	12.7619	4.0505
	147.1000	22.9277	14.0818	25.5882	12.7941	4.0505
	147.3200	22.9825	14.0873	25.6522	12.8261	4.0505
	147.5400	23.0377	14.0924	25.7167	12.8584	4.0505
	147.7600	23.0928	14.0997	25.7811	12.8906	4.0505
	147.9800	23.1476	14.1041	25.8451	12.9226	4.0505
	148.2000	23.2027	14.1087	25.9095	12.9548	4.0505
	148.4200	23.2577	14.1155	25.9738	12.9869	4.0505
	148.6400	23.3126	14.1208	26.0380	13.0190	4.0505
	148.8600	23.3676	14.1261	26.1023	13.0512	4.0505
	149.0800	23.4226	14.1330	26.1666	13.0833	4.0505
	149.3000	23.4776	14.1377	26.2309	13.1155	4.0505
	149.5200	23.5325	14.1429	26.2951	13.1475	4.0505
	149.7400	23.5875	14.1491	26.3594	13.1797	4.0505
	149.9600	23.6425	14.1552	26.4237	13.2118	4.0505
	150.1800	23.6976	14.1619	26.4881	13.2440	4.0505
	150.4000	23.7527	14.1667	26.5524	13.2762	4.0505
	150.6200	23.8076	14.1716	26.6166	13.3083	4.0505
	150.8400	23.8627	14.1778	26.6810	13.3405	4.0505
	151.0600	23.9176	14.1816	26.7451	13.3726	4.0505
	151.2800	23.9726	14.1880	26.8094	13.4047	4.0505
	151.5000	24.0278	14.1956	26.8740	13.4370	4.0505
	151.7200	24.0826	14.1988	26.9380	13.4690	4.0505
	151.9400	24.1376	14.2040	27.0023	13.5012	4.0505
	152.1600	24.1928	14.2106	27.0668	13.5334	4.0505
	152.3800	24.2476	14.2144	27.1309	13.5654	4.0505
	152.6000	24.3026	14.2184	27.1952	13.5976	4.0505
	152.8200	24.3577	14.2259	27.2595	13.6298	4.0505
	153.0400	24.4125	14.2304	27.3235	13.6618	4.0505
	153.2600	24.4676	14.2341	27.3879	13.6940	4.0505
	153.4800	24.5227	14.2406	27.4524	13.7262	4.0505
	153.7000	24.5776	14.2454	27.5166	13.7583	4.0505
	153.9200	24.6326	14.2497	27.5808	13.7904	4.0505
	154.1400	24.6877	14.2564	27.6452	13.8226	4.0505
	154.3600	24.7426	14.2607	27.7094	13.8547	4.0505
	154.5800	24.7976	14.2656	27.7736	13.8868	4.0505
	154.8000	24.8527	14.2699	27.8381	13.9190	4.0505
	155.0200	24.9076	14.2747	27.9022	13.9511	4.0505
	155.2400	24.9626	14.2810	27.9665	13.9832	4.0505
	155.4600	25.0175	14.2864	28.0307	14.0154	4.0505
	155.6800	25.0726	14.2917	28.0951	14.0475	4.0505
	155.9000	25.1278	14.2976	28.1596	14.0798	4.0505
	156.1200	25.1826	14.3000	28.2237	14.1118	4.0505
	156.3400	25.2376	14.3054	28.2880	14.1440	4.0505
	156.5600	25.2927	14.3111	28.3524	14.1762	4.0505
	156.7800	25.3475	14.3146	28.4164	14.2082	4.0505
	157.0000	25.4027	14.3199	28.4809	14.2404	4.0505
	157.2200	25.4578	14.3261	28.5453	14.2727	4.0505
	157.4400	25.5126	14.3290	28.6094	14.3047	4.0505
	157.6600	25.5676	14.3334	28.6737	14.3368	4.0505
	157.8800	25.6226	14.3392	28.7379	14.3690	4.0505
	158.1000	25.6776	14.3435	28.8022	14.4011	4.0505
	158.3200	25.7326	14.3475	28.8665	14.4332	4.0505
	158.5400	25.7877	14.3528	28.9308	14.4654	4.0505
	158.7600	25.8426	14.3565	28.9951	14.4975	4.0505
	158.9800	25.8976	14.3602	29.0593	14.5296	4.0505
	159.2000	25.9526	14.3659	29.1236	14.5618	4.0505
	159.4200	26.0076	14.3710	29.1878	14.5939	4.0505
	159.6400	26.0625	14.3755	29.2521	14.6260	4.0505
	159.8600	26.1176	14.3802	29.3165	14.6582	4.0505
	160.0800	26.1726	14.3843	29.3807	14.6904	4.0505
	160.3000	26.2276	14.3886	29.4450	14.7225	4.0505
	160.5200	26.2825	14.3923	29.5092	14.7546	4.0505
	160.7400	26.3376	14.3978	29.5736	14.7868	4.0505
	160.9600	26.3928	14.4033	29.6381	14.8190	4.0505
	161.1800	26.4476	14.4064	29.7021	14.8511	4.0505
	161.4000	26.5026	14.4104	29.7665	14.8832	4.0505
	161.6200	26.5578	14.4156	29.8309	14.9154	4.0505
	161.8400	26.6125	14.4179	29.8948	14.9474	4.0505
	162.0600	26.6676	14.4225	29.9592	14.9796	4.0505
	162.2800	26.7228	14.4277	30.0238	15.0119	4.0505
	162.5000	26.7777	14.4306	30.0879	15.0440	4.0505
	162.7200	26.8326	14.4340	30.1522	15.0761	4.0505
	162.9400	26.8877	14.4397	30.2165	15.1082	4.0505
	163.1600	26.9426	14.4436	30.2806	15.1403	4.0505
	163.3800	26.9975	14.4462	30.3449	15.1724	4.0505
	163.6000	27.0527	14.4525	30.4093	15.2047	4.0505
	163.8200	27.1076	14.4553	30.4735	15.2367	4.0505
	164.0400	27.1626	14.4583	30.5378	15.2689	4.0505
	164.2600	27.2177	14.4631	30.6022	15.3011	4.0505
	164.4800	27.2726	14.4668	30.6664	15.3332	4.0505
	164.7000	27.3276	14.4707	30.7307	15.3653	4.0505
	164.9200	27.3826	14.4757	30.7949	15.3975	4.0505
	165.1400	27.4376	14.4791	30.8592	15.4296	4.0505
	165.3600	27.4926	14.4840	30.9235	15.4617	4.0505
	165.5800	27.5475	14.4861	30.9877	15.4938	4.0505
	165.8000	27.6026	14.4897	31.0521	15.5260	4.0505
	166.0200	27.6577	14.4952	31.1165	15.5582	4.0505
	166.2400	27.7126	14.4981	31.1807	15.5903	4.0505
	166.4600	27.7677	14.5021	31.2450	15.6225	4.0505
	166.6800	27.8228	14.5072	31.3095	15.6547	4.0505
	166.9000	27.8776	14.5087	31.3735	15.6868	4.0505
	167.1200	27.9327	14.5122	31.4378	15.7189	4.0505
	167.3400	27.9877	14.5170	31.5022	15.7511	4.0505
	167.5600	28.0425	14.5204	31.5662	15.7831	4.0505
	167.7800	28.0975	14.5228	31.6305	15.8153	4.0505
	168.0000	28.1527	14.5283	31.6950	15.8475	4.0505
	168.2200	28.2077	14.5306	31.7593	15.8796	4.0505
	168.4400	28.2627	14.5335	31.8236	15.9118	4.0505
	168.6600	28.3177	14.5381	31.8878	15.9439	4.0505
	168.8800	28.3725	14.5410	31.9519	15.9760	4.0505
	169.1000	28.4275	14.5446	32.0162	16.0081	4.0505
	169.3200	28.4825	14.5490	32.0805	16.0403	4.0505
	169.5400	28.5376	14.5513	32.1448	16.0724	4.0505
	169.7600	28.5926	14.5549	32.2092	16.1046	4.0505
	169.9800	28.6475	14.5585	32.2734	16.1367	4.0505
	170.2000	28.7025	14.5621	32.3376	16.1688	4.0505
	170.4200	28.7577	14.5670	32.4021	16.2011	4.0505
	170.6400	28.8127	14.5688	32.4663	16.2332	4.0505
	170.8600	28.8676	14.5719	32.5306	16.2653	4.0505
	171.0800	28.9227	14.5767	32.5949	16.2975	4.0505
	171.3000	28.9775	14.5776	32.6590	16.3295	4.0505
	171.5200	29.0326	14.5821	32.7234	16.3617	4.0505
	171.7400	29.0878	14.5870	32.7879	16.3940	4.0505
	171.9600	29.1426	14.5887	32.8520	16.4260	4.0505
	172.1800	29.1977	14.5915	32.9164	16.4582	4.0505
	172.4000	29.2528	14.5957	32.9808	16.4904	4.0505
	172.6200	29.3075	14.5974	33.0447	16.5224	4.0505
	172.8400	29.3625	14.5999	33.1090	16.5545	4.0505
	173.0600	29.4177	14.6051	33.1735	16.5867	4.0505
	173.2800	29.4726	14.6080	33.2376	16.6188	4.0505
	173.5000	29.5276	14.6095	33.3019	16.6510	4.0505
	173.7200	29.5827	14.6145	33.3664	16.6832	4.0505
	173.9400	29.6376	14.6162	33.4305	16.7153	4.0505
	174.1600	29.6926	14.6191	33.4948	16.7474	4.0505
	174.3800	29.7476	14.6235	33.5591	16.7795	4.0505
	174.6000	29.8027	14.6260	33.6235	16.8117	4.0505
	174.8200	29.8576	14.6291	33.6876	16.8438	4.0505
	175.0400	29.9126	14.6310	33.7519	16.8760	4.0505
	175.2600	29.9675	14.6340	33.8161	16.9081	4.0505
	175.4800	30.0226	14.6385	33.8805	16.9403	4.0505
	175.7000	30.0776	14.6405	33.9448	16.9724	4.0505
	175.9200	30.1327	14.6442	34.0091	17.0046	4.0505
	176.1400	30.1878	14.6481	34.0736	17.0368	4.0505
	176.3600	30.2426	14.6481	34.1377	17.0688	4.0505
	176.5800	30.2976	14.6506	34.2019	17.1009	4.0505
	176.8000	30.3527	14.6548	34.2663	17.1332	4.0505
	177.0200	30.4075	14.6570	34.3304	17.1652	4.0505
	177.2400	30.4627	14.6587	34.3948	17.1974	4.0505
	177.4600	30.5178	14.6636	34.4592	17.2296	4.0505
	177.6800	30.5725	14.6648	34.5233	17.2616	4.0505
	177.9000	30.6276	14.6662	34.5876	17.2938	4.0505
	178.1200	30.6827	14.6703	34.6520	17.3260	4.0505
	178.3400	30.7376	14.6726	34.7161	17.3581	4.0505
	178.5600	30.7926	14.6741	34.7804	17.3902	4.0505
	178.7800	30.8476	14.6789	34.8448	17.4224	4.0505
	179.0000	30.9026	14.6800	34.9090	17.4545	4.0505
	179.2200	30.9575	14.6828	34.9732	17.4866	4.0505
	179.4400	31.0126	14.6852	35.0375	17.5188	4.0505
	179.6600	31.0676	14.6882	35.1018	17.5509	4.0505
	179.8800	31.1225	14.6910	35.1660	17.5830	4.0505
	180.1000	31.1776	14.6931	35.2304	17.6152	4.0505
	180.3200	31.2326	14.6958	35.2947	17.6473	4.0505
	180.5400	31.2877	14.6983	35.3592	17.6796	4.0505
	180.7600	31.3426	14.6992	35.4233	17.7116	4.0505
	180.9800	31.3976	14.7023	35.4875	17.7438	4.0505
	181.2000	31.4528	14.7071	35.5520	17.7760	4.0505
	181.4200	31.5075	14.7073	35.6160	17.8080	4.0505
	181.6400	31.5627	14.7100	35.6805	17.8402	4.0505
	181.8600	31.6178	14.7124	35.7449	17.8725	4.0505
	182.0800	31.6726	14.7130	35.8089	17.9045	4.0505
	182.3000	31.7276	14.7148	35.8733	17.9366	4.0505
	182.5200	31.7826	14.7193	35.9376	17.9688	4.0505
	182.7400	31.8376	14.7207	36.0018	18.0009	4.0505
	182.9600	31.8926	14.7218	36.0661	18.0331	4.0505
	183.1800	31.9477	14.7254	36.1304	18.0652	4.0505
	183.4000	32.0026	14.7269	36.1946	18.0973	4.0505
	183.6200	32.0575	14.7285	36.2589	18.1294	4.0505
	183.8400	32.1126	14.7312	36.3233	18.1616	4.0505
	184.0600	32.1676	14.7336	36.3875	18.1937	4.0505
	184.2800	32.2226	14.7350	36.4518	18.2259	4.0505
	184.5000	32.2777	14.7370	36.5162	18.2581	4.0505
	184.7200	32.3326	14.7393	36.5803	18.2902	4.0505
	184.9400	32.3876	14.7424	36.6446	18.3223	4.0505
	185.1600	32.4426	14.7442	36.7089	18.3544	4.0505
	185.3800	32.4976	14.7463	36.7732	18.3866	4.0505
	185.6000	32.5527	14.7488	36.8376	18.4188	4.0505
	185.8200	32.6076	14.7487	36.9018	18.4509	4.0505
	186.0400	32.6627	14.7508	36.9661	18.4831	4.0505
	186.2600	32.7178	14.7538	37.0305	18.5153	4.0505
	186.4800	32.7726	14.7556	37.0946	18.5473	4.0505
	186.7000	32.8277	14.7571	37.1590	18.5795	4.0505
	186.9200	32.8828	14.7603	37.2234	18.6117	4.0505
	187.1400	32.9376	14.7601	37.2875	18.6437	4.0505
	187.3600	32.9926	14.7612	37.3518	18.6759	4.0505
	187.5800	33.0476	14.7638	37.4160	18.7080	4.0505
	187.8000	33.1025	14.7655	37.4802	18.7401	4.0505
	188.0200	33.1576	14.7663	37.5446	18.7723	4.0505
	188.2400	33.2128	14.7703	37.6091	18.8045	4.0505
	188.4600	33.2677	14.7704	37.6732	18.8366	4.0505
	188.6800	33.3226	14.7713	37.7374	18.8687	4.0505
	188.9000	33.3775	14.7737	37.8016	18.9008	4.0505
	189.1200	33.4324	14.7756	37.8658	18.9329	4.0505
	189.3400	33.4875	14.7776	37.9302	18.9651	4.0505
	189.5600	33.5426	14.7798	37.9946	18.9973	4.0505
	189.7800	33.5976	14.7806	38.0588	19.0294	4.0505
	190.0000	33.6526	14.7825	38.1232	19.0616	4.0505
	190.2200	33.7076	14.7840	38.1874	19.0937	4.0505
	190.4400	33.7626	14.7866	38.2517	19.1258	4.0505
	190.6600	33.8178	14.7895	38.3162	19.1581	4.0505
	190.8800	33.8726	14.7897	38.3802	19.1901	4.0505
	191.1000	33.9277	14.7913	38.4446	19.2223	4.0505
	191.3200	33.9827	14.7935	38.5090	19.2545	4.0505
	191.5400	34.0375	14.7938	38.5730	19.2865	4.0505
	191.7600	34.0926	14.7957	38.6374	19.3187	4.0505
	191.9800	34.1478	14.7983	38.7019	19.3510	4.0505
	192.2000	34.2026	14.7987	38.7660	19.3830	4.0505
	192.4200	34.2577	14.8001	38.8303	19.4151	4.0505
	192.6400	34.3127	14.8024	38.8947	19.4473	4.0505
	192.8600	34.3675	14.8025	38.9587	19.4793	4.0505
	193.0800	34.4225	14.8035	39.0230	19.5115	4.0505
	193.3000	34.4777	14.8070	39.0875	19.5437	4.0505
	193.5200	34.5326	14.8078	39.1516	19.5758	4.0505
	193.7400	34.5875	14.8079	39.2159	19.6079	4.0505
	193.9600	34.6427	14.8103	39.2803	19.6402	4.0505
	194.1800	34.6976	14.8113	39.3445	19.6723	4.0505
	194.4000	34.7526	14.8125	39.4088	19.7044	4.0505
	194.6200	34.8076	14.8145	39.4730	19.7365	4.0505
	194.8400	34.8625	14.8156	39.5372	19.7686	4.0505
	195.0600	34.9176	14.8176	39.6016	19.8008	4.0505
	195.2800	34.9726	14.8172	39.6659	19.8329	4.0505
	195.5000	35.0276	14.8187	39.7302	19.8651	4.0505
	195.7200	35.0827	14.8217	39.7947	19.8973	4.0505
	195.9400	35.1376	14.8216	39.8588	19.9294	4.0505
	196.1600	35.1928	14.8227	39.9232	19.9616	4.0505
	196.3800	35.2478	14.8244	39.9876	19.9938	4.0505
	196.6000	35.3026	14.8231	40.0516	20.0258	4.0505
	196.8200	35.3576	14.8242	40.1159	20.0579	4.0505
	197.0400	35.4127	14.8266	40.1802	20.0901	4.0505
	197.2600	35.4676	14.8277	40.2444	20.1222	4.0505
	197.4800	35.5226	14.8280	40.3087	20.1544	4.0505
	197.7000	35.5778	14.8304	40.3733	20.1866	4.0505
	197.9200	35.6326	14.8298	40.4373	20.2186	4.0505
	198.1400	35.6876	14.8297	40.5016	20.2508	4.0505
	198.3600	35.7426	14.8323	40.5659	20.2830	4.0505
	198.5800	35.7975	14.8323	40.6301	20.3150	4.0505
	198.8000	35.8526	14.8333	40.6944	20.3472	4.0505
	199.0200	35.9076	14.8349	40.7587	20.3793	4.0505
	199.2400	35.9626	14.8353	40.8230	20.4115	4.0505
	199.4600	36.0176	14.8361	40.8873	20.4436	4.0505
	199.6800	36.0726	14.8375	40.9516	20.4758	4.0505
	199.9000	36.1276	14.8382	41.0158	20.5079	4.0505
	200.1200	36.1827	14.8404	41.0802	20.5401	4.0505
	200.3400	36.2377	14.8395	41.1445	20.5722	4.0505
	200.5600	36.2926	14.8401	41.2087	20.6043	4.0505
	200.7800	36.3477	14.8417	41.2731	20.6366	4.0505
	201.0000	36.4025	14.8413	41.3372	20.6686	4.0505
	201.2200	36.4576	14.8426	41.4015	20.7007	4.0505
	201.4400	36.5128	14.8450	41.4661	20.7330	4.0505
	201.6600	36.5676	14.8439	41.5301	20.7650	4.0505
	201.8800	36.6227	14.8435	41.5945	20.7973	4.0505
	202.1000	36.6779	14.8452	41.6590	20.8295	4.0505
	202.3200	36.7325	14.8441	41.7229	20.8614	4.0505
	202.5400	36.7875	14.8442	41.7872	20.8936	4.0505
	202.7600	36.8426	14.8465	41.8515	20.9258	4.0505
	202.9800	36.8976	14.8467	41.9158	20.9579	4.0505
	203.2000	36.9526	14.8461	41.9801	20.9901	4.0505
	203.4200	37.0077	14.8479	42.0445	21.0222	4.0505
	203.6400	37.0626	14.8468	42.1086	21.0543	4.0505
	203.8600	37.1175	14.8471	42.1728	21.0864	4.0505
	204.0800	37.1726	14.8485	42.2372	21.1186	4.0505
	204.3000	37.2277	14.8482	42.3016	21.1508	4.0505
	204.5200	37.2826	14.8496	42.3658	21.1829	4.0505
	204.7400	37.3376	14.8490	42.4300	21.2150	4.0505
	204.9600	37.3926	14.8493	42.4943	21.2471	4.0505
	205.1800	37.4476	14.8514	42.5587	21.2793	4.0505
	205.4000	37.5026	14.8503	42.6230	21.3115	4.0505
	205.6200	37.5577	14.8508	42.6873	21.3436	4.0505
	205.8400	37.6128	14.8516	42.7517	21.3758	4.0505
	206.0600	37.6676	14.8491	42.8157	21.4079	4.0505
	206.2800	37.7226	14.8499	42.8801	21.4400	4.0505
	206.5000	37.7778	14.8510	42.9445	21.4723	4.0505
	206.7200	37.8326	14.8510	43.0086	21.5043	4.0505
	206.9400	37.8876	14.8500	43.0728	21.5364	4.0505
	207.1600	37.9427	14.8515	43.1373	21.5687	4.0505
	207.3800	37.9976	14.8498	43.2014	21.6007	4.0505
	207.6000	38.0526	14.8483	43.2658	21.6329	4.0505
	207.8200	38.1077	14.8499	43.3301	21.6650	4.0505
	208.0400	38.1626	14.8492	43.3943	21.6972	4.0505
	208.2600	38.2176	14.8484	43.4586	21.7293	4.0505
	208.4800	38.2726	14.8494	43.5228	21.7614	4.0505
	208.7000	38.3277	14.8489	43.5872	21.7936	4.0505
	208.9200	38.3826	14.8481	43.6514	21.8257	4.0505
	209.1400	38.4376	14.8483	43.7157	21.8578	4.0505
	209.3600	38.4925	14.8483	43.7799	21.8899	4.0505
	209.5800	38.5476	14.8489	43.8442	21.9221	4.0505
	209.8000	38.6026	14.8470	43.9085	21.9543	4.0505
	210.0200	38.6576	14.8469	43.9728	21.9864	4.0505
	210.2400	38.7127	14.8468	44.0372	22.0186	4.0505
	210.4600	38.7676	14.8456	44.1014	22.0507	4.0505
	210.6800	38.8226	14.8458	44.1657	22.0828	4.0505
	210.9000	38.8778	14.8467	44.2301	22.1151	4.0505
	211.1200	38.9325	14.8440	44.2941	22.1471	4.0505
	211.3400	38.9877	14.8433	44.3586	22.1793	4.0505
	211.5600	39.0428	14.8437	44.4230	22.2115	4.0505
	211.7800	39.0975	14.8409	44.4870	22.2435	4.0505
	212.0000	39.1526	14.8400	44.5514	22.2757	4.0505
	212.2200	39.2077	14.8411	44.6158	22.3079	4.0505
	212.4400	39.2626	14.8394	44.6799	22.3400	4.0505
	212.6600	39.3176	14.8367	44.7442	22.3721	4.0505
	212.8800	39.3727	14.8374	44.8086	22.4043	4.0505
	213.1000	39.4276	14.8349	44.8727	22.4364	4.0505
	213.3200	39.4825	14.8336	44.9369	22.4685	4.0505
	213.5400	39.5376	14.8341	45.0014	22.5007	4.0505
	213.7600	39.5927	14.8329	45.0657	22.5328	4.0505
	213.9800	39.6476	14.8309	45.1299	22.5650	4.0505
	214.2000	39.7027	14.8294	45.1943	22.5972	4.0505
	214.4200	39.7577	14.8278	45.2586	22.6293	4.0505
	214.6400	39.8125	14.8274	45.3227	22.6613	4.0505
	214.8600	39.8675	14.8255	45.3870	22.6935	4.0505
	215.0800	39.9225	14.8241	45.4512	22.7256	4.0505
	215.3000	39.9777	14.8228	45.5157	22.7579	4.0505
	215.5200	40.0326	14.8196	45.5799	22.7900	4.0505
	215.7400	40.0877	14.8178	45.6443	22.8221	4.0505
	215.9600	40.1427	14.8172	45.7086	22.8543	4.0505
	216.1800	40.1976	14.8141	45.7727	22.8864	4.0505
	216.4000	40.2527	14.8115	45.8372	22.9186	4.0505
	216.6200	40.3078	14.8100	45.9016	22.9508	4.0505
	216.8400	40.3626	14.8064	45.9655	22.9828	4.0505
	217.0600	40.4176	14.8027	46.0299	23.0149	4.0505
	217.2800	40.4726	14.8020	46.0942	23.0471	4.0505
	217.5000	40.5275	14.7981	46.1583	23.0792	4.0505
	217.7200	40.5827	14.7951	46.2228	23.1114	4.0505
	217.9400	40.6378	14.7930	46.2872	23.1436	4.0505
	218.1600	40.6927	14.7888	46.3514	23.1757	4.0505
	218.3800	40.7476	14.7843	46.4155	23.2078	4.0505
	218.6000	40.8026	14.7815	46.4798	23.2399	4.0505
	218.8200	40.8575	14.7773	46.5440	23.2720	4.0505
	219.0400	40.9125	14.7737	46.6083	23.3042	4.0505
	219.2600	40.9675	14.7691	46.6726	23.3363	4.0505
	219.4800	41.0226	14.7645	46.7370	23.3685	4.0505
	219.7000	41.0777	14.7601	46.8014	23.4007	4.0505
	219.9200	41.1326	14.7544	46.8655	23.4328	4.0505
	220.1400	41.1876	14.7493	46.9298	23.4649	4.0505
	220.3600	41.2427	14.7452	46.9943	23.4971	4.0505
	220.5800	41.2975	14.7375	47.0583	23.5291	4.0505
	220.8000	41.3526	14.7314	47.1227	23.5613	4.0505
	221.0200	41.4077	14.7256	47.1871	23.5935	4.0505
	221.2400	41.4626	14.7170	47.2512	23.6256	4.0505
	221.4600	41.5177	14.7099	47.3156	23.6578	4.0505
	221.6800	41.5728	14.7032	47.3801	23.6900	4.0505
	221.9000	41.6276	14.6931	47.4441	23.7221	4.0505
	222.1200	41.6827	14.6826	47.5085	23.7542	4.0505
	222.3400	41.7377	14.6733	47.5728	23.7864	4.0505
	222.5600	41.7925	14.6623	47.6368	23.8184	4.0505
	222.7800	41.8475	14.6498	47.7011	23.8505	4.0505
	223.0000	41.9027	14.6390	47.7656	23.8828	4.0505
	223.2200	41.9576	14.6254	47.8298	23.9149	4.0505
	223.4400	42.0126	14.6097	47.8941	23.9470	4.0505
	223.6600	42.0677	14.5945	47.9584	23.9792	4.0505
	223.8800	42.1226	14.5765	48.0226	24.0113	4.0505
	224.1000	42.1776	14.5582	48.0869	24.0434	4.0505
	224.3200	42.2326	14.5391	48.1512	24.0756	4.0505
	224.5400	42.2875	14.5162	48.2154	24.1077	4.0505
	224.7600	42.3426	14.4938	48.2798	24.1399	4.0505
	224.9800	42.3975	14.4671	48.3439	24.1720	4.0505
	225.2000	42.4527	14.4393	48.4084	24.2042	4.0505
	225.4200	42.5078	14.4107	48.4728	24.2364	4.0505
	225.6400	42.5627	14.3763	48.5370	24.2685	4.0505
	225.8600	42.6177	14.3399	48.6013	24.3006	4.0505
	226.0800	42.6728	14.3015	48.6657	24.3328	4.0505
	226.3000	42.7276	14.2576	48.7297	24.3648	4.0505
	226.5200	42.7826	14.2109	48.7940	24.3970	4.0505
	226.7400	42.8378	14.1616	48.8585	24.4293	4.0505
	226.9600	42.8926	14.1045	48.9226	24.4613	4.0505
	227.1800	42.9477	14.0392	48.9869	24.4935	4.0505
	227.4000	43.0028	13.9685	49.0514	24.5257	4.0505
	227.6200	43.0577	13.8849	49.1155	24.5577	4.0505
	227.8400	43.1127	13.7856	49.1798	24.5899	4.0505
	228.0600	43.1677	13.6726	49.2441	24.6220	4.0505
	228.2800	43.2226	13.5334	49.3082	24.6541	4.0505
	228.5000	43.2777	13.3633	49.3727	24.6863	4.0505
	228.7200	43.3327	13.1587	49.4370	24.7185	4.0505
	228.9400	43.3878	12.9040	49.5013	24.7507	4.0505
	229.1600	43.4428	12.5842	49.5656	24.7828	4.0505
	229.3800	43.4978	12.1691	49.6299	24.8150	4.0505
	229.6000	43.5528	11.5630	49.6942	24.8471	4.0505
	229.7660	43.6012	6.6135	49.7508	24.8754	4.0505